Workbook

Sheet DEMANDA
A1: DEMANDA (unidades por año)
A3: Ref. | B3: Línea | C3: Producto | D3: 2026 | E3: 2027 | F3: 2028 | G3: 2029 | H3: 2030 | I3: 2031 | J3: 2032 | K3: 2033 | L3: 2034 | M3: 2035
A4: D01 | B4: RECARGAS | C4: Parte de la planta industrial | D4: =(PROY_INDEXADO!B63+PROY_INDEXADO!B65+PROY_INDEXADO!B66+PROY_INDEXADO!B67)/PROY_INDEXADO!B75 -> 0.28778641 | E4: =(PROY_INDEXADO!C63+PROY_INDEXADO!C65+PROY_INDEXADO!C66+PROY_INDEXADO!C67)/PROY_INDEXADO!C75 -> 0.28783937 | F4: =(PROY_INDEXADO!D63+PROY_INDEXADO!D65+PROY_INDEXADO!D66+PROY_INDEXADO!D67)/PROY_INDEXADO!D75 -> 0.28789154 | G4: =(PROY_INDEXADO!E63+PROY_INDEXADO!E65+PROY_INDEXADO!E66+PROY_INDEXADO!E67)/PROY_INDEXADO!E75 -> 0.28794305 | H4: =(PROY_INDEXADO!F63+PROY_INDEXADO!F65+PROY_INDEXADO!F66+PROY_INDEXADO!F67)/PROY_INDEXADO!F75 -> 0.2879932 | I4: =(PROY_INDEXADO!G63+PROY_INDEXADO!G65+PROY_INDEXADO!G66+PROY_INDEXADO!G67)/PROY_INDEXADO!G75 -> 0.28804275 | J4: =(PROY_INDEXADO!H63+PROY_INDEXADO!H65+PROY_INDEXADO!H66+PROY_INDEXADO!H67)/PROY_INDEXADO!H75 -> 0.28809088 | K4: =(PROY_INDEXADO!I63+PROY_INDEXADO!I65+PROY_INDEXADO!I66+PROY_INDEXADO!I67)/PROY_INDEXADO!I75 -> 0.28814012 | ... M4: =(PROY_INDEXADO!K63+PROY_INDEXADO!K65+PROY_INDEXADO!K66+PROY_INDEXADO!K67)/PROY_INDEXADO!K75 -> 0.28823651
A5: D02 | C5: % de unidades nuevas que van a CABA | D5: =(PROY_INDEXADO!B79+PROY_INDEXADO!B80+PROY_INDEXADO!B81+PROY_INDEXADO!B82)/PROY_INDEXADO!B93 -> 0.23315299 | E5: =(PROY_INDEXADO!C79+PROY_INDEXADO!C80+PROY_INDEXADO!C81+PROY_INDEXADO!C82)/PROY_INDEXADO!C93 -> 0.23306476 | F5: =(PROY_INDEXADO!D79+PROY_INDEXADO!D80+PROY_INDEXADO!D81+PROY_INDEXADO!D82)/PROY_INDEXADO!D93 -> 0.23305972 | G5: =(PROY_INDEXADO!E79+PROY_INDEXADO!E80+PROY_INDEXADO!E81+PROY_INDEXADO!E82)/PROY_INDEXADO!E93 -> 0.23312519 | H5: =(PROY_INDEXADO!F79+PROY_INDEXADO!F80+PROY_INDEXADO!F81+PROY_INDEXADO!F82)/PROY_INDEXADO!F93 -> 0.23328948 | I5: =(PROY_INDEXADO!G79+PROY_INDEXADO!G80+PROY_INDEXADO!G81+PROY_INDEXADO!G82)/PROY_INDEXADO!G93 -> 0.23356853 | J5: =(PROY_INDEXADO!H79+PROY_INDEXADO!H80+PROY_INDEXADO!H81+PROY_INDEXADO!H82)/PROY_INDEXADO!H93 -> 0.23398058 | K5: =(PROY_INDEXADO!I79+PROY_INDEXADO!I80+PROY_INDEXADO!I81+PROY_INDEXADO!I82)/PROY_INDEXADO!I93 -> 0.23454186 | ... M5: =(PROY_INDEXADO!K79+PROY_INDEXADO!K80+PROY_INDEXADO!K81+PROY_INDEXADO!K82)/PROY_INDEXADO!K93 -> 0.23621517
A6: D03 | B6: RECARGAS | C6: % de recargas de la planta industrial en CABA | D6: =PROY_INDEXADO!B63/(PROY_INDEXADO!B63+PROY_INDEXADO!B65+PROY_INDEXADO!B66+PROY_INDEXADO!B67) -> 0.21154491 | E6: =PROY_INDEXADO!C63/(PROY_INDEXADO!C63+PROY_INDEXADO!C65+PROY_INDEXADO!C66+PROY_INDEXADO!C67) -> 0.21080896 | F6: =PROY_INDEXADO!D63/(PROY_INDEXADO!D63+PROY_INDEXADO!D65+PROY_INDEXADO!D66+PROY_INDEXADO!D67) -> 0.21012352 | G6: =PROY_INDEXADO!E63/(PROY_INDEXADO!E63+PROY_INDEXADO!E65+PROY_INDEXADO!E66+PROY_INDEXADO!E67) -> 0.20949374 | H6: =PROY_INDEXADO!F63/(PROY_INDEXADO!F63+PROY_INDEXADO!F65+PROY_INDEXADO!F66+PROY_INDEXADO!F67) -> 0.20893171 | I6: =PROY_INDEXADO!G63/(PROY_INDEXADO!G63+PROY_INDEXADO!G65+PROY_INDEXADO!G66+PROY_INDEXADO!G67) -> 0.208444 | J6: =PROY_INDEXADO!H63/(PROY_INDEXADO!H63+PROY_INDEXADO!H65+PROY_INDEXADO!H66+PROY_INDEXADO!H67) -> 0.20804543 | K6: =PROY_INDEXADO!I63/(PROY_INDEXADO!I63+PROY_INDEXADO!I65+PROY_INDEXADO!I66+PROY_INDEXADO!I67) -> 0.20774816 | ... M6: =PROY_INDEXADO!K63/(PROY_INDEXADO!K63+PROY_INDEXADO!K65+PROY_INDEXADO!K66+PROY_INDEXADO!K67) -> 0.20752849
A7: D04 | B7: RECARGAS | C7: % de recargas de equipos usados | D7: =PROY_USADOS!$L$5 -> 0.047640139 | E7: =PROY_USADOS!$L$6 -> 0.047635883 | F7: =PROY_USADOS!$L$7 -> 0.047636541 | G7: =PROY_USADOS!$L$8 -> 0.047638627 | H7: =PROY_USADOS!$L$9 -> 0.047635501 | I7: =PROY_USADOS!$L$10 -> 0.047637147 | J7: =PROY_USADOS!$L$11 -> 0.047636246 | K7: =PROY_USADOS!$L$12 -> 0.047637525 | L7: =PROY_USADOS!$L$13 -> 0.047635817 | M7: =PROY_USADOS!$L$14 -> 0.047633261
A8: D05 | B8: MANUALES | C8: Matafuego ABC 1 kg | D8: =PROY_INDEXADO!B3 -> 4178.7365 | E8: =PROY_INDEXADO!C3 -> 5997.304 | F8: =PROY_INDEXADO!D3 -> 6851.7478 | G8: =PROY_INDEXADO!E3 -> 8467.1355 | H8: =PROY_INDEXADO!F3 -> 12680.633 | I8: =PROY_INDEXADO!G3 -> 15620.253 | J8: =PROY_INDEXADO!H3 -> 20332.553 | K8: =PROY_INDEXADO!I3 -> 25132.078 | ... M8: =PROY_INDEXADO!K3 -> 32072.639
A9: D06 | B9: MANUALES | C9: Matafuego ABC 2,5 kg | D9: =PROY_INDEXADO!B4 -> 295.03036 | E9: =PROY_INDEXADO!C4 -> 709.72745 | F9: =PROY_INDEXADO!D4 -> 986.86806 | G9: =PROY_INDEXADO!E4 -> 1500.6382 | H9: =PROY_INDEXADO!F4 -> 2312.6277 | I9: =PROY_INDEXADO!G4 -> 3252.8699 | J9: =PROY_INDEXADO!H4 -> 4102.3155 | K9: =PROY_INDEXADO!I4 -> 5104.3066 | ... M9: =PROY_INDEXADO!K4 -> 7424.8584
A10: D07 | B10: MANUALES | C10: Matafuego ABC 5 kg | D10: =PROY_INDEXADO!B5+PROY_RESERVAS!B30+PROY_RESERVAS!B69*$D$4 -> 2727.9036 | E10: =PROY_INDEXADO!C5+PROY_RESERVAS!C30+PROY_RESERVAS!C69*$D$4 -> 5488.9106 | F10: =PROY_INDEXADO!D5+PROY_RESERVAS!D30+PROY_RESERVAS!D69*$D$4 -> 7206.5855 | G10: =PROY_INDEXADO!E5+PROY_RESERVAS!E30+PROY_RESERVAS!E69*$D$4 -> 10420.908 | H10: =PROY_INDEXADO!F5+PROY_RESERVAS!F30+PROY_RESERVAS!F69*$D$4 -> 14495.071 | I10: =PROY_INDEXADO!G5+PROY_RESERVAS!G30+PROY_RESERVAS!G69*$D$4 -> 18737.061 | J10: =PROY_INDEXADO!H5+PROY_RESERVAS!H30+PROY_RESERVAS!H69*$D$4 -> 22634.482 | K10: =PROY_INDEXADO!I5+PROY_RESERVAS!I30+PROY_RESERVAS!I69*$D$4 -> 26002.338 | ... M10: =PROY_INDEXADO!K5+PROY_RESERVAS!K30+PROY_RESERVAS!K69*$D$4 -> 32428.771
A11: D08 | B11: MANUALES | C11: Matafuego ABC 10 kg | D11: =PROY_INDEXADO!B6+PROY_RESERVAS!B70*$D$4 -> 92.408754 | E11: =PROY_INDEXADO!C6+PROY_RESERVAS!C70*$D$4 -> 178.13943 | F11: =PROY_INDEXADO!D6+PROY_RESERVAS!D70*$D$4 -> 255.06523 | G11: =PROY_INDEXADO!E6+PROY_RESERVAS!E70*$D$4 -> 361.07103 | H11: =PROY_INDEXADO!F6+PROY_RESERVAS!F70*$D$4 -> 605.62479 | I11: =PROY_INDEXADO!G6+PROY_RESERVAS!G70*$D$4 -> 876.21675 | J11: =PROY_INDEXADO!H6+PROY_RESERVAS!H70*$D$4 -> 1130.355 | K11: =PROY_INDEXADO!I6+PROY_RESERVAS!I70*$D$4 -> 1397.6176 | ... M11: =PROY_INDEXADO!K6+PROY_RESERVAS!K70*$D$4 -> 1842.877
A12: D09 | B12: MANUALES | C12: Cilindro ABC 1 kg vacío | D12: =PROY_INDEXADO!B15 -> 0 | E12: =PROY_INDEXADO!C15 -> 0 | F12: =PROY_INDEXADO!D15 -> 7662.4 | G12: =PROY_INDEXADO!E15 -> 26694.8 | H12: =PROY_INDEXADO!F15 -> 49434.8 | I12: =PROY_INDEXADO!G15 -> 71680.2 | J12: =PROY_INDEXADO!H15 -> 101340.6 | K12: =PROY_INDEXADO!I15 -> 131001 | ... M12: =PROY_INDEXADO!K15 -> 170548
A13: D10 | B13: MANUALES | C13: Cilindro ABC 2,5 kg vacío | D13: =PROY_INDEXADO!B16 -> 0 | E13: =PROY_INDEXADO!C16 -> 0 | F13: =PROY_INDEXADO!D16 -> 299.6 | G13: =PROY_INDEXADO!E16 -> 1043.8 | H13: =PROY_INDEXADO!F16 -> 1933 | I13: =PROY_INDEXADO!G16 -> 2803 | J13: =PROY_INDEXADO!H16 -> 3963 | K13: =PROY_INDEXADO!I16 -> 5123 | ... M13: =PROY_INDEXADO!K16 -> 6669
A14: D11 | B14: MANUALES | C14: Cilindro ABC 5 kg vacío | D14: =PROY_INDEXADO!B17 -> 0 | E14: =PROY_INDEXADO!C17 -> 0 | F14: =PROY_INDEXADO!D17 -> 1478.8 | G14: =PROY_INDEXADO!E17 -> 5152 | H14: =PROY_INDEXADO!F17 -> 9540.8 | I14: =PROY_INDEXADO!G17 -> 13834.2 | J14: =PROY_INDEXADO!H17 -> 19558.6 | K14: =PROY_INDEXADO!I17 -> 25283 | ... M14: =PROY_INDEXADO!K17 -> 32915
A15: D12 | B15: MANUALES | C15: Cilindro ABC 10 kg vacío | D15: =PROY_INDEXADO!B18 -> 0 | E15: =PROY_INDEXADO!C18 -> 0 | F15: =PROY_INDEXADO!D18 -> 90.4 | G15: =PROY_INDEXADO!E18 -> 315 | H15: =PROY_INDEXADO!F18 -> 583.4 | I15: =PROY_INDEXADO!G18 -> 845.8 | J15: =PROY_INDEXADO!H18 -> 1195.4 | K15: =PROY_INDEXADO!I18 -> 1545 | ... M15: =PROY_INDEXADO!K18 -> 2011
A16: D13 | B16: RODANTES | C16: Matafuego ABC 25 kg | D16: =PROY_INDEXADO!B7 -> 34.051791 | E16: =PROY_INDEXADO!C7 -> 58.462147 | F16: =PROY_INDEXADO!D7 -> 75.20854 | G16: =PROY_INDEXADO!E7 -> 100.52985 | H16: =PROY_INDEXADO!F7 -> 155.876 | I16: =PROY_INDEXADO!G7 -> 211.93448 | J16: =PROY_INDEXADO!H7 -> 272.66823 | K16: =PROY_INDEXADO!I7 -> 337.84867 | ... M16: =PROY_INDEXADO!K7 -> 453.27053
A17: D14 | B17: RODANTES | C17: Matafuego ABC 50 kg | D17: =PROY_INDEXADO!B8+PROY_RESERVAS!B79*$D$4 -> 75.201727 | E17: =PROY_INDEXADO!C8+PROY_RESERVAS!C79*$D$4 -> 129.20669 | F17: =PROY_INDEXADO!D8+PROY_RESERVAS!D79*$D$4 -> 166.6531 | G17: =PROY_INDEXADO!E8+PROY_RESERVAS!E79*$D$4 -> 222.70533 | H17: =PROY_INDEXADO!F8+PROY_RESERVAS!F79*$D$4 -> 344.53881 | I17: =PROY_INDEXADO!G8+PROY_RESERVAS!G79*$D$4 -> 468.2272 | J17: =PROY_INDEXADO!H8+PROY_RESERVAS!H79*$D$4 -> 601.64 | K17: =PROY_INDEXADO!I8+PROY_RESERVAS!I79*$D$4 -> 744.53334 | ... M17: =PROY_INDEXADO!K8+PROY_RESERVAS!K79*$D$4 -> 998.25998
A18: D15 | B18: RODANTES | C18: Matafuego ABC 70 kg | D18: =PROY_INDEXADO!B9 -> 16.34486 | E18: =PROY_INDEXADO!C9 -> 28.061831 | F18: =PROY_INDEXADO!D9 -> 36.100099 | G18: =PROY_INDEXADO!E9 -> 48.254329 | H18: =PROY_INDEXADO!F9 -> 74.820482 | I18: =PROY_INDEXADO!G9 -> 101.72855 | J18: =PROY_INDEXADO!H9 -> 130.88075 | K18: =PROY_INDEXADO!I9 -> 162.16736 | ... M18: =PROY_INDEXADO!K9 -> 217.56986
A19: D16 | B19: RODANTES | C19: Matafuego ABC 100 kg | D19: =PROY_INDEXADO!B10+PROY_RESERVAS!B80*$D$4 -> 11.18436 | E19: =PROY_INDEXADO!C10+PROY_RESERVAS!C80*$D$4 -> 18.722277 | F19: =PROY_INDEXADO!D10+PROY_RESERVAS!D80*$D$4 -> 24.368909 | G19: =PROY_INDEXADO!E10+PROY_RESERVAS!E80*$D$4 -> 32.486118 | H19: =PROY_INDEXADO!F10+PROY_RESERVAS!F80*$D$4 -> 50.499062 | I19: =PROY_INDEXADO!G10+PROY_RESERVAS!G80*$D$4 -> 68.178767 | J19: =PROY_INDEXADO!H10+PROY_RESERVAS!H80*$D$4 -> 87.627957 | K19: =PROY_INDEXADO!I10+PROY_RESERVAS!I80*$D$4 -> 108.50009 | ... M19: =PROY_INDEXADO!K10+PROY_RESERVAS!K80*$D$4 -> 145.17607
A20: D17 | B20: RODANTES | C20: Cilindro ABC 25 kg vacío | D20: =PROY_INDEXADO!B19 -> 0 | E20: =PROY_INDEXADO!C19 -> 0 | F20: =PROY_INDEXADO!D19 -> 14.4 | G20: =PROY_INDEXADO!E19 -> 50.2 | H20: =PROY_INDEXADO!F19 -> 93 | I20: =PROY_INDEXADO!G19 -> 135 | J20: =PROY_INDEXADO!H19 -> 191 | K20: =PROY_INDEXADO!I19 -> 247 | ... M20: =PROY_INDEXADO!K19 -> 322
A21: D18 | B21: RODANTES | C21: Cilindro ABC 50 kg vacío | D21: =PROY_INDEXADO!B20 -> 0 | E21: =PROY_INDEXADO!C20 -> 0 | F21: =PROY_INDEXADO!D20 -> 31.8 | G21: =PROY_INDEXADO!E20 -> 110.8 | H21: =PROY_INDEXADO!F20 -> 205.2 | I21: =PROY_INDEXADO!G20 -> 297.6 | J21: =PROY_INDEXADO!H20 -> 420.8 | K21: =PROY_INDEXADO!I20 -> 544 | ... M21: =PROY_INDEXADO!K20 -> 708
A22: D19 | B22: RODANTES | C22: Cilindro ABC 70 kg vacío | D22: =PROY_INDEXADO!B21 -> 0 | E22: =PROY_INDEXADO!C21 -> 0 | F22: =PROY_INDEXADO!D21 -> 7 | G22: =PROY_INDEXADO!E21 -> 24.4 | H22: =PROY_INDEXADO!F21 -> 45.2 | I22: =PROY_INDEXADO!G21 -> 65.4 | J22: =PROY_INDEXADO!H21 -> 92.2 | K22: =PROY_INDEXADO!I21 -> 119 | ... M22: =PROY_INDEXADO!K21 -> 155
A23: D20 | B23: RODANTES | C23: Cilindro ABC 100 kg vacío | D23: =PROY_INDEXADO!B22 -> 0 | E23: =PROY_INDEXADO!C22 -> 0 | F23: =PROY_INDEXADO!D22 -> 4.6 | G23: =PROY_INDEXADO!E22 -> 16 | H23: =PROY_INDEXADO!F22 -> 29.6 | I23: =PROY_INDEXADO!G22 -> 42.8 | J23: =PROY_INDEXADO!H22 -> 60.4 | K23: =PROY_INDEXADO!I22 -> 78 | ... M23: =PROY_INDEXADO!K22 -> 102
A24: D21 | B24: RECARGAS | C24: Recarga ABC 1 kg | D24: =(PROY_INDEXADO!B27)*$D$4 -> 1000.7721 | E24: =(PROY_INDEXADO!C27)*$D$4 -> 4883.9039 | F24: =(PROY_INDEXADO!D27)*$D$4 -> 8790.7495 | G24: =(PROY_INDEXADO!E27)*$D$4 -> 16129.942 | H24: =(PROY_INDEXADO!F27)*$D$4 -> 24251.826 | I24: =(PROY_INDEXADO!G27)*$D$4 -> 33788.376 | J24: =(PROY_INDEXADO!H27)*$D$4 -> 42480.335 | K24: =(PROY_INDEXADO!I27)*$D$4 -> 49327.846 | ... M24: =(PROY_INDEXADO!K27)*$D$4 -> 56487.491
A25: D22 | B25: RECARGAS | C25: Recarga ABC 2,5 kg | D25: =(PROY_INDEXADO!B28)*$D$4 -> 94.968557 | E25: =(PROY_INDEXADO!C28)*$D$4 -> 370.50026 | F25: =(PROY_INDEXADO!D28)*$D$4 -> 848.15525 | G25: =(PROY_INDEXADO!E28)*$D$4 -> 1561.5415 | H25: =(PROY_INDEXADO!F28)*$D$4 -> 2259.3754 | I25: =(PROY_INDEXADO!G28)*$D$4 -> 2999.8693 | J25: =(PROY_INDEXADO!H28)*$D$4 -> 3686.5139 | K25: =(PROY_INDEXADO!I28)*$D$4 -> 4104.7172 | ... M25: =(PROY_INDEXADO!K28)*$D$4 -> 4783.2292
A26: D23 | B26: RECARGAS | C26: Recarga ABC 5 kg | D26: =(PROY_INDEXADO!B29+PROY_RESERVAS!B54)*$D$4 -> 579.42746 | E26: =(PROY_INDEXADO!C29+PROY_RESERVAS!C54)*$D$4 -> 2341.0327 | F26: =(PROY_INDEXADO!D29+PROY_RESERVAS!D54)*$D$4 -> 5274.796 | G26: =(PROY_INDEXADO!E29+PROY_RESERVAS!E54)*$D$4 -> 9966.207 | H26: =(PROY_INDEXADO!F29+PROY_RESERVAS!F54)*$D$4 -> 14367.038 | I26: =(PROY_INDEXADO!G29+PROY_RESERVAS!G54)*$D$4 -> 19107.591 | J26: =(PROY_INDEXADO!H29+PROY_RESERVAS!H54)*$D$4 -> 23397.064 | K26: =(PROY_INDEXADO!I29+PROY_RESERVAS!I54)*$D$4 -> 25952.927 | ... M26: =(PROY_INDEXADO!K29+PROY_RESERVAS!K54)*$D$4 -> 30068.838
A27: D24 | B27: RECARGAS | C27: Recarga ABC 10 kg | D27: =(PROY_INDEXADO!B30+PROY_RESERVAS!B55)*$D$4 -> 34.633262 | E27: =(PROY_INDEXADO!C30+PROY_RESERVAS!C55)*$D$4 -> 127.40782 | F27: =(PROY_INDEXADO!D30+PROY_RESERVAS!D55)*$D$4 -> 298.42726 | G27: =(PROY_INDEXADO!E30+PROY_RESERVAS!E55)*$D$4 -> 570.51062 | H27: =(PROY_INDEXADO!F30+PROY_RESERVAS!F55)*$D$4 -> 827.66705 | I27: =(PROY_INDEXADO!G30+PROY_RESERVAS!G55)*$D$4 -> 1108.6657 | J27: =(PROY_INDEXADO!H30+PROY_RESERVAS!H55)*$D$4 -> 1356.8203 | K27: =(PROY_INDEXADO!I30+PROY_RESERVAS!I55)*$D$4 -> 1502.3932 | ... M27: =(PROY_INDEXADO!K30+PROY_RESERVAS!K55)*$D$4 -> 1741.3814
A28: D25 | B28: RECARGAS | C28: Recarga Agua 10 l | D28: =(PROY_INDEXADO!B31+PROY_RESERVAS!B56)*$D$4 -> 46.422462 | E28: =(PROY_INDEXADO!C31+PROY_RESERVAS!C56)*$D$4 -> 187.18306 | F28: =(PROY_INDEXADO!D31+PROY_RESERVAS!D56)*$D$4 -> 428.90614 | G28: =(PROY_INDEXADO!E31+PROY_RESERVAS!E56)*$D$4 -> 804.78066 | H28: =(PROY_INDEXADO!F31+PROY_RESERVAS!F56)*$D$4 -> 1161.3521 | I28: =(PROY_INDEXADO!G31+PROY_RESERVAS!G56)*$D$4 -> 1552.2496 | J28: =(PROY_INDEXADO!H31+PROY_RESERVAS!H56)*$D$4 -> 1902.2563 | K28: =(PROY_INDEXADO!I31+PROY_RESERVAS!I56)*$D$4 -> 2114.8904 | ... M28: =(PROY_INDEXADO!K31+PROY_RESERVAS!K56)*$D$4 -> 2458.5058
A29: D26 | B29: RECARGAS | C29: Recarga AFFF 10 l | D29: =(PROY_INDEXADO!B32+PROY_RESERVAS!B57)*$D$4 -> 6.837342 | E29: =(PROY_INDEXADO!C32+PROY_RESERVAS!C57)*$D$4 -> 47.000054 | F29: =(PROY_INDEXADO!D32+PROY_RESERVAS!D57)*$D$4 -> 92.266417 | G29: =(PROY_INDEXADO!E32+PROY_RESERVAS!E57)*$D$4 -> 153.50372 | H29: =(PROY_INDEXADO!F32+PROY_RESERVAS!F57)*$D$4 -> 216.64243 | I29: =(PROY_INDEXADO!G32+PROY_RESERVAS!G57)*$D$4 -> 280.2678 | J29: =(PROY_INDEXADO!H32+PROY_RESERVAS!H57)*$D$4 -> 347.62935 | K29: =(PROY_INDEXADO!I32+PROY_RESERVAS!I57)*$D$4 -> 393.29385 | ... M29: =(PROY_INDEXADO!K32+PROY_RESERVAS!K57)*$D$4 -> 466.91659
A30: D27 | B30: RECARGAS | C30: Recarga AFFF 50 l | D30: =(PROY_INDEXADO!B33+PROY_RESERVAS!B58)*$D$4 -> 3.5625642 | E30: =(PROY_INDEXADO!C33+PROY_RESERVAS!C58)*$D$4 -> 24.238384 | F30: =(PROY_INDEXADO!D33+PROY_RESERVAS!D58)*$D$4 -> 47.906029 | G30: =(PROY_INDEXADO!E33+PROY_RESERVAS!E58)*$D$4 -> 82.117304 | H30: =(PROY_INDEXADO!F33+PROY_RESERVAS!F58)*$D$4 -> 116.23765 | I30: =(PROY_INDEXADO!G33+PROY_RESERVAS!G58)*$D$4 -> 149.80068 | J30: =(PROY_INDEXADO!H33+PROY_RESERVAS!H58)*$D$4 -> 183.05101 | K30: =(PROY_INDEXADO!I33+PROY_RESERVAS!I58)*$D$4 -> 206.96966 | ... M30: =(PROY_INDEXADO!K33+PROY_RESERVAS!K58)*$D$4 -> 243.56826
A31: D28 | B31: RECARGAS | C31: Recarga BC 5 kg | D31: =(PROY_INDEXADO!B34+PROY_RESERVAS!B59)*$D$4 -> 2.2526531 | E31: =(PROY_INDEXADO!C34+PROY_RESERVAS!C59)*$D$4 -> 13.834788 | F31: =(PROY_INDEXADO!D34+PROY_RESERVAS!D59)*$D$4 -> 25.869027 | G31: =(PROY_INDEXADO!E34+PROY_RESERVAS!E59)*$D$4 -> 46.478222 | H31: =(PROY_INDEXADO!F34+PROY_RESERVAS!F59)*$D$4 -> 64.117719 | I31: =(PROY_INDEXADO!G34+PROY_RESERVAS!G59)*$D$4 -> 85.147323 | J31: =(PROY_INDEXADO!H34+PROY_RESERVAS!H59)*$D$4 -> 107.29949 | K31: =(PROY_INDEXADO!I34+PROY_RESERVAS!I59)*$D$4 -> 118.97348 | ... M31: =(PROY_INDEXADO!K34+PROY_RESERVAS!K59)*$D$4 -> 140.86546
A32: D29 | B32: RECARGAS | C32: Recarga Clase K 6 l | D32: =(PROY_INDEXADO!B35+PROY_RESERVAS!B60)*$D$4 -> 23.866187 | E32: =(PROY_INDEXADO!C35+PROY_RESERVAS!C60)*$D$4 -> 97.674378 | F32: =(PROY_INDEXADO!D35+PROY_RESERVAS!D60)*$D$4 -> 217.45094 | G32: =(PROY_INDEXADO!E35+PROY_RESERVAS!E60)*$D$4 -> 395.3897 | H32: =(PROY_INDEXADO!F35+PROY_RESERVAS!F60)*$D$4 -> 570.71658 | I32: =(PROY_INDEXADO!G35+PROY_RESERVAS!G60)*$D$4 -> 756.17071 | J32: =(PROY_INDEXADO!H35+PROY_RESERVAS!H60)*$D$4 -> 930.20151 | K32: =(PROY_INDEXADO!I35+PROY_RESERVAS!I60)*$D$4 -> 1041.0787 | ... M32: =(PROY_INDEXADO!K35+PROY_RESERVAS!K60)*$D$4 -> 1212.3174
A33: D30 | B33: RECARGAS | C33: Recarga CO₂ 2 kg | D33: =(PROY_INDEXADO!B36)*$D$4 -> 129.6812 | E33: =(PROY_INDEXADO!C36)*$D$4 -> 488.42577 | F33: =(PROY_INDEXADO!D36)*$D$4 -> 1138.2519 | G33: =(PROY_INDEXADO!E36)*$D$4 -> 2176.028 | H33: =(PROY_INDEXADO!F36)*$D$4 -> 3142.6693 | I33: =(PROY_INDEXADO!G36)*$D$4 -> 4177.1867 | J33: =(PROY_INDEXADO!H36)*$D$4 -> 5107.2013 | K33: =(PROY_INDEXADO!I36)*$D$4 -> 5645.5652 | ... M33: =(PROY_INDEXADO!K36)*$D$4 -> 6542.6807
A34: D31 | B34: RECARGAS | C34: Recarga CO₂ 5 kg | D34: =(PROY_INDEXADO!B37+PROY_RESERVAS!B61)*$D$4 -> 38.037061 | E34: =(PROY_INDEXADO!C37+PROY_RESERVAS!C61)*$D$4 -> 192.71052 | F34: =(PROY_INDEXADO!D37+PROY_RESERVAS!D61)*$D$4 -> 412.57829 | G34: =(PROY_INDEXADO!E37+PROY_RESERVAS!E61)*$D$4 -> 739.4051 | H34: =(PROY_INDEXADO!F37+PROY_RESERVAS!F61)*$D$4 -> 1065.1717 | I34: =(PROY_INDEXADO!G37+PROY_RESERVAS!G61)*$D$4 -> 1419.2077 | J34: =(PROY_INDEXADO!H37+PROY_RESERVAS!H61)*$D$4 -> 1758.0599 | K34: =(PROY_INDEXADO!I37+PROY_RESERVAS!I61)*$D$4 -> 1983.2685 | ... M34: =(PROY_INDEXADO!K37+PROY_RESERVAS!K61)*$D$4 -> 2330.9482
A35: D32 | B35: RECARGAS | C35: Recarga HCFC 5 kg | D35: =(PROY_INDEXADO!B38+PROY_RESERVAS!B62)*$D$4 -> 5.5274309 | E35: =(PROY_INDEXADO!C38+PROY_RESERVAS!C62)*$D$4 -> 32.82927 | F35: =(PROY_INDEXADO!D38+PROY_RESERVAS!D62)*$D$4 -> 67.300015 | G35: =(PROY_INDEXADO!E38+PROY_RESERVAS!E62)*$D$4 -> 116.75936 | H35: =(PROY_INDEXADO!F38+PROY_RESERVAS!F62)*$D$4 -> 167.35004 | I35: =(PROY_INDEXADO!G38+PROY_RESERVAS!G62)*$D$4 -> 219.6805 | J35: =(PROY_INDEXADO!H38+PROY_RESERVAS!H62)*$D$4 -> 275.08031 | K35: =(PROY_INDEXADO!I38+PROY_RESERVAS!I62)*$D$4 -> 312.028 | ... M35: =(PROY_INDEXADO!K38+PROY_RESERVAS!K62)*$D$4 -> 370.07637
A36: D33 | B36: RECARGAS | C36: Recarga Clase D 9 l | D36: =(PROY_INDEXADO!B39+PROY_RESERVAS!B63)*$D$4 -> 2.2526531 | E36: =(PROY_INDEXADO!C39+PROY_RESERVAS!C63)*$D$4 -> 13.834788 | F36: =(PROY_INDEXADO!D39+PROY_RESERVAS!D63)*$D$4 -> 25.869027 | G36: =(PROY_INDEXADO!E39+PROY_RESERVAS!E63)*$D$4 -> 43.248307 | H36: =(PROY_INDEXADO!F39+PROY_RESERVAS!F63)*$D$4 -> 59.924629 | I36: =(PROY_INDEXADO!G39+PROY_RESERVAS!G63)*$D$4 -> 74.469092 | J36: =(PROY_INDEXADO!H39+PROY_RESERVAS!H63)*$D$4 -> 95.665355 | K36: =(PROY_INDEXADO!I39+PROY_RESERVAS!I63)*$D$4 -> 106.7423 | ... M36: =(PROY_INDEXADO!K39+PROY_RESERVAS!K63)*$D$4 -> 127.11145
A37: D34 | B37: RECARGAS | C37: Recarga ABC 25 kg | D37: =(PROY_INDEXADO!B40)*$D$4 -> 5.0759056 | E37: =(PROY_INDEXADO!C40)*$D$4 -> 24.746126 | F37: =(PROY_INDEXADO!D40)*$D$4 -> 53.778522 | G37: =(PROY_INDEXADO!E40)*$D$4 -> 96.864192 | H37: =(PROY_INDEXADO!F40)*$D$4 -> 139.32678 | I37: =(PROY_INDEXADO!G40)*$D$4 -> 185.11009 | J37: =(PROY_INDEXADO!H40)*$D$4 -> 228.05109 | K37: =(PROY_INDEXADO!I40)*$D$4 -> 256.03715 | ... M37: =(PROY_INDEXADO!K40)*$D$4 -> 299.85609
A38: D35 | B38: RECARGAS | C38: Recarga ABC 50 kg | D38: =(PROY_INDEXADO!B41+PROY_RESERVAS!B64)*$D$4 -> 11.454779 | E38: =(PROY_INDEXADO!C41+PROY_RESERVAS!C64)*$D$4 -> 55.304836 | F38: =(PROY_INDEXADO!D41+PROY_RESERVAS!D64)*$D$4 -> 120.32725 | G38: =(PROY_INDEXADO!E41+PROY_RESERVAS!E64)*$D$4 -> 216.55466 | H38: =(PROY_INDEXADO!F41+PROY_RESERVAS!F64)*$D$4 -> 311.41129 | I38: =(PROY_INDEXADO!G41+PROY_RESERVAS!G64)*$D$4 -> 413.86128 | J38: =(PROY_INDEXADO!H41+PROY_RESERVAS!H64)*$D$4 -> 509.77041 | K38: =(PROY_INDEXADO!I41+PROY_RESERVAS!I64)*$D$4 -> 572.20312 | ... M38: =(PROY_INDEXADO!K41+PROY_RESERVAS!K64)*$D$4 -> 670.0437
A39: D36 | B39: RECARGAS | C39: Recarga ABC 70 kg | D39: =(PROY_INDEXADO!B42)*$D$4 -> 2.4364347 | E39: =(PROY_INDEXADO!C42)*$D$4 -> 11.87814 | F39: =(PROY_INDEXADO!D42)*$D$4 -> 25.813691 | G39: =(PROY_INDEXADO!E42)*$D$4 -> 46.494812 | H39: =(PROY_INDEXADO!F42)*$D$4 -> 66.876856 | I39: =(PROY_INDEXADO!G42)*$D$4 -> 88.852841 | J39: =(PROY_INDEXADO!H42)*$D$4 -> 109.46452 | K39: =(PROY_INDEXADO!I42)*$D$4 -> 122.89783 | ... M39: =(PROY_INDEXADO!K42)*$D$4 -> 143.93092
A40: D37 | B40: RECARGAS | C40: Recarga ABC 100 kg | D40: =(PROY_INDEXADO!B43+PROY_RESERVAS!B65)*$D$4 -> 1.9120762 | E40: =(PROY_INDEXADO!C43+PROY_RESERVAS!C65)*$D$4 -> 8.2065467 | F40: =(PROY_INDEXADO!D43+PROY_RESERVAS!D65)*$D$4 -> 17.7847 | G40: =(PROY_INDEXADO!E43+PROY_RESERVAS!E65)*$D$4 -> 31.859901 | H40: =(PROY_INDEXADO!F43+PROY_RESERVAS!F65)*$D$4 -> 46.023503 | I40: =(PROY_INDEXADO!G43+PROY_RESERVAS!G65)*$D$4 -> 60.961946 | J40: =(PROY_INDEXADO!H43+PROY_RESERVAS!H65)*$D$4 -> 74.990853 | K40: =(PROY_INDEXADO!I43+PROY_RESERVAS!I65)*$D$4 -> 84.234181 | ... M40: =(PROY_INDEXADO!K43+PROY_RESERVAS!K65)*$D$4 -> 98.544026
A41: D38 | B41: RECARGAS | C41: Sustitutos nuevos (kit) | D41: =PROY_RESERVAS!B81*$D$4 -> 23.598486 | E41: =PROY_RESERVAS!C81*$D$4 -> 73.956311 | F41: =PROY_RESERVAS!D81*$D$4 -> 100.52859 | G41: =PROY_RESERVAS!E81*$D$4 -> 172.50877 | H41: =PROY_RESERVAS!F81*$D$4 -> 184.73969 | I41: =PROY_RESERVAS!G81*$D$4 -> 213.60946 | J41: =PROY_RESERVAS!H81*$D$4 -> 205.50348 | K41: =PROY_RESERVAS!I81*$D$4 -> 163.46268 | ... M41: =PROY_RESERVAS!K81*$D$4 -> 129.8924
...

Sheet ESTACIONALIDAD
A1: ESTACIONALIDAD: producción mensual del año 2035
A3: Ref. | B3: Perfil | C3: Ene | D3: Feb | E3: Mar | F3: Abr | G3: May | H3: Jun | I3: Jul | J3: Ago | K3: Sep | L3: Oct | M3: Nov | N3: Dic | O3: Total
A4: E01 | B4: Automovilístico (1 kg) | C4: 0.12 | D4: 0.09 | E4: 0.08 | F4: 0.075 | G4: 0.07 | H4: 0.07 | I4: 0.075 | J4: 0.075 | K4: 0.075 | L4: 0.075 | M4: 0.075 | N4: 0.12 | O4: =SUM(C4:N4) -> 1
A5: E02 | B5: Manual comercial (2,5 / 5 / 10 kg) | C5: 0.1 | D5: 0.08 | E5: 0.085 | F5: 0.085 | G5: 0.08 | H5: 0.075 | I5: 0.08 | J5: 0.08 | K5: 0.08 | L5: 0.075 | M5: 0.07 | N5: 0.11 | O5: =SUM(C5:N5) -> 1
A6: E03 | B6: Industrial s/ruedas (25 – 100 kg) | C6: 0.085 | D6: 0.075 | E6: 0.09 | F6: 0.09 | G6: 0.09 | H6: 0.08 | I6: 0.09 | J6: 0.09 | K6: 0.085 | L6: 0.075 | M6: 0.07 | N6: 0.08 | O6: =SUM(C6:N6) -> 1
A7: E04 | B7: Recargas (sin estacionalidad) | C7: 0.083333333 | D7: 0.083333333 | E7: 0.083333333 | F7: 0.083333333 | G7: 0.083333333 | H7: 0.083333333 | I7: 0.083333333 | J7: 0.083333333 | K7: 0.083333333 | L7: 0.083333333 | M7: 0.083333333 | N7: 0.083333333 | O7: =SUM(C7:N7) -> 1
A9: Línea | B9: Producto | C9: Ene | D9: Feb | E9: Mar | F9: Abr | G9: May | H9: Jun | I9: Jul | J9: Ago | K9: Sep | L9: Oct | M9: Nov | N9: Dic | O9: Total | P9: Mes pico del producto
A10: MANUALES | B10: =DEMANDA!C8 -> Matafuego ABC 1 kg | C10: =DEMANDA!$M$8*C$4 -> 3848.7167 | D10: =DEMANDA!$M$8*D$4 -> 2886.5375 | E10: =DEMANDA!$M$8*E$4 -> 2565.8111 | F10: =DEMANDA!$M$8*F$4 -> 2405.4479 | G10: =DEMANDA!$M$8*G$4 -> 2245.0847 | H10: =DEMANDA!$M$8*H$4 -> 2245.0847 | I10: =DEMANDA!$M$8*I$4 -> 2405.4479 | J10: =DEMANDA!$M$8*J$4 -> 2405.4479 | ... N10: =DEMANDA!$M$8*N$4 -> 3848.7167 | O10: =SUM(C10:N10) -> 32072.639 | P10: =MAX(C10:N10) -> 3848.7167
A11: MANUALES | B11: =DEMANDA!C9 -> Matafuego ABC 2,5 kg | C11: =DEMANDA!$M$9*C$5 -> 742.48584 | D11: =DEMANDA!$M$9*D$5 -> 593.98868 | E11: =DEMANDA!$M$9*E$5 -> 631.11297 | F11: =DEMANDA!$M$9*F$5 -> 631.11297 | G11: =DEMANDA!$M$9*G$5 -> 593.98868 | H11: =DEMANDA!$M$9*H$5 -> 556.86438 | I11: =DEMANDA!$M$9*I$5 -> 593.98868 | J11: =DEMANDA!$M$9*J$5 -> 593.98868 | ... N11: =DEMANDA!$M$9*N$5 -> 816.73443 | O11: =SUM(C11:N11) -> 7424.8584 | P11: =MAX(C11:N11) -> 816.73443
A12: MANUALES | B12: =DEMANDA!C10 -> Matafuego ABC 5 kg | C12: =DEMANDA!$M$10*C$5 -> 3242.8771 | D12: =DEMANDA!$M$10*D$5 -> 2594.3017 | E12: =DEMANDA!$M$10*E$5 -> 2756.4455 | F12: =DEMANDA!$M$10*F$5 -> 2756.4455 | G12: =DEMANDA!$M$10*G$5 -> 2594.3017 | H12: =DEMANDA!$M$10*H$5 -> 2432.1578 | I12: =DEMANDA!$M$10*I$5 -> 2594.3017 | J12: =DEMANDA!$M$10*J$5 -> 2594.3017 | ... N12: =DEMANDA!$M$10*N$5 -> 3567.1648 | O12: =SUM(C12:N12) -> 32428.771 | P12: =MAX(C12:N12) -> 3567.1648
A13: MANUALES | B13: =DEMANDA!C11 -> Matafuego ABC 10 kg | C13: =DEMANDA!$M$11*C$5 -> 184.2877 | D13: =DEMANDA!$M$11*D$5 -> 147.43016 | E13: =DEMANDA!$M$11*E$5 -> 156.64454 | F13: =DEMANDA!$M$11*F$5 -> 156.64454 | G13: =DEMANDA!$M$11*G$5 -> 147.43016 | H13: =DEMANDA!$M$11*H$5 -> 138.21577 | I13: =DEMANDA!$M$11*I$5 -> 147.43016 | J13: =DEMANDA!$M$11*J$5 -> 147.43016 | ... N13: =DEMANDA!$M$11*N$5 -> 202.71647 | O13: =SUM(C13:N13) -> 1842.877 | P13: =MAX(C13:N13) -> 202.71647
A14: MANUALES | B14: =DEMANDA!C12 -> Cilindro ABC 1 kg vacío | C14: =DEMANDA!$M$12*C$4 -> 20465.76 | D14: =DEMANDA!$M$12*D$4 -> 15349.32 | E14: =DEMANDA!$M$12*E$4 -> 13643.84 | F14: =DEMANDA!$M$12*F$4 -> 12791.1 | G14: =DEMANDA!$M$12*G$4 -> 11938.36 | H14: =DEMANDA!$M$12*H$4 -> 11938.36 | I14: =DEMANDA!$M$12*I$4 -> 12791.1 | J14: =DEMANDA!$M$12*J$4 -> 12791.1 | ... N14: =DEMANDA!$M$12*N$4 -> 20465.76 | O14: =SUM(C14:N14) -> 170548 | P14: =MAX(C14:N14) -> 20465.76
A15: MANUALES | B15: =DEMANDA!C13 -> Cilindro ABC 2,5 kg vacío | C15: =DEMANDA!$M$13*C$5 -> 666.9 | D15: =DEMANDA!$M$13*D$5 -> 533.52 | E15: =DEMANDA!$M$13*E$5 -> 566.865 | F15: =DEMANDA!$M$13*F$5 -> 566.865 | G15: =DEMANDA!$M$13*G$5 -> 533.52 | H15: =DEMANDA!$M$13*H$5 -> 500.175 | I15: =DEMANDA!$M$13*I$5 -> 533.52 | J15: =DEMANDA!$M$13*J$5 -> 533.52 | ... N15: =DEMANDA!$M$13*N$5 -> 733.59 | O15: =SUM(C15:N15) -> 6669 | P15: =MAX(C15:N15) -> 733.59
A16: MANUALES | B16: =DEMANDA!C14 -> Cilindro ABC 5 kg vacío | C16: =DEMANDA!$M$14*C$5 -> 3291.5 | D16: =DEMANDA!$M$14*D$5 -> 2633.2 | E16: =DEMANDA!$M$14*E$5 -> 2797.775 | F16: =DEMANDA!$M$14*F$5 -> 2797.775 | G16: =DEMANDA!$M$14*G$5 -> 2633.2 | H16: =DEMANDA!$M$14*H$5 -> 2468.625 | I16: =DEMANDA!$M$14*I$5 -> 2633.2 | J16: =DEMANDA!$M$14*J$5 -> 2633.2 | ... N16: =DEMANDA!$M$14*N$5 -> 3620.65 | O16: =SUM(C16:N16) -> 32915 | P16: =MAX(C16:N16) -> 3620.65
A17: MANUALES | B17: =DEMANDA!C15 -> Cilindro ABC 10 kg vacío | C17: =DEMANDA!$M$15*C$5 -> 201.1 | D17: =DEMANDA!$M$15*D$5 -> 160.88 | E17: =DEMANDA!$M$15*E$5 -> 170.935 | F17: =DEMANDA!$M$15*F$5 -> 170.935 | G17: =DEMANDA!$M$15*G$5 -> 160.88 | H17: =DEMANDA!$M$15*H$5 -> 150.825 | I17: =DEMANDA!$M$15*I$5 -> 160.88 | J17: =DEMANDA!$M$15*J$5 -> 160.88 | ... N17: =DEMANDA!$M$15*N$5 -> 221.21 | O17: =SUM(C17:N17) -> 2011 | P17: =MAX(C17:N17) -> 221.21
A18: MANUALES | B18: Total manuales | C18: =SUM(C10:C17) -> 32643.627 | D18: =SUM(D10:D17) -> 24899.178 | E18: =SUM(E10:E17) -> 23289.429 | F18: =SUM(F10:F17) -> 22276.326 | G18: =SUM(G10:G17) -> 20846.765 | H18: =SUM(H10:H17) -> 20430.308 | I18: =SUM(I10:I17) -> 21859.868 | J18: =SUM(J10:J17) -> 21859.868 | ... O18: =SUM(O10:O17) -> 285912.15
A19: RODANTES | B19: =DEMANDA!C16 -> Matafuego ABC 25 kg | C19: =DEMANDA!$M$16*C$6 -> 38.527995 | D19: =DEMANDA!$M$16*D$6 -> 33.99529 | E19: =DEMANDA!$M$16*E$6 -> 40.794348 | F19: =DEMANDA!$M$16*F$6 -> 40.794348 | G19: =DEMANDA!$M$16*G$6 -> 40.794348 | H19: =DEMANDA!$M$16*H$6 -> 36.261643 | I19: =DEMANDA!$M$16*I$6 -> 40.794348 | J19: =DEMANDA!$M$16*J$6 -> 40.794348 | ... N19: =DEMANDA!$M$16*N$6 -> 36.261643 | O19: =SUM(C19:N19) -> 453.27053 | P19: =MAX(C19:N19) -> 40.794348
A20: RODANTES | B20: =DEMANDA!C17 -> Matafuego ABC 50 kg | C20: =DEMANDA!$M$17*C$6 -> 84.852099 | D20: =DEMANDA!$M$17*D$6 -> 74.869499 | E20: =DEMANDA!$M$17*E$6 -> 89.843398 | F20: =DEMANDA!$M$17*F$6 -> 89.843398 | G20: =DEMANDA!$M$17*G$6 -> 89.843398 | H20: =DEMANDA!$M$17*H$6 -> 79.860799 | I20: =DEMANDA!$M$17*I$6 -> 89.843398 | J20: =DEMANDA!$M$17*J$6 -> 89.843398 | ... N20: =DEMANDA!$M$17*N$6 -> 79.860799 | O20: =SUM(C20:N20) -> 998.25998 | P20: =MAX(C20:N20) -> 89.843398
A21: RODANTES | B21: =DEMANDA!C18 -> Matafuego ABC 70 kg | C21: =DEMANDA!$M$18*C$6 -> 18.493438 | D21: =DEMANDA!$M$18*D$6 -> 16.317739 | E21: =DEMANDA!$M$18*E$6 -> 19.581287 | F21: =DEMANDA!$M$18*F$6 -> 19.581287 | G21: =DEMANDA!$M$18*G$6 -> 19.581287 | H21: =DEMANDA!$M$18*H$6 -> 17.405588 | I21: =DEMANDA!$M$18*I$6 -> 19.581287 | J21: =DEMANDA!$M$18*J$6 -> 19.581287 | ... N21: =DEMANDA!$M$18*N$6 -> 17.405588 | O21: =SUM(C21:N21) -> 217.56986 | P21: =MAX(C21:N21) -> 19.581287
A22: RODANTES | B22: =DEMANDA!C19 -> Matafuego ABC 100 kg | C22: =DEMANDA!$M$19*C$6 -> 12.339966 | D22: =DEMANDA!$M$19*D$6 -> 10.888206 | E22: =DEMANDA!$M$19*E$6 -> 13.065847 | F22: =DEMANDA!$M$19*F$6 -> 13.065847 | G22: =DEMANDA!$M$19*G$6 -> 13.065847 | H22: =DEMANDA!$M$19*H$6 -> 11.614086 | I22: =DEMANDA!$M$19*I$6 -> 13.065847 | J22: =DEMANDA!$M$19*J$6 -> 13.065847 | ... N22: =DEMANDA!$M$19*N$6 -> 11.614086 | O22: =SUM(C22:N22) -> 145.17607 | P22: =MAX(C22:N22) -> 13.065847
A23: RODANTES | B23: =DEMANDA!C20 -> Cilindro ABC 25 kg vacío | C23: =DEMANDA!$M$20*C$6 -> 27.37 | D23: =DEMANDA!$M$20*D$6 -> 24.15 | E23: =DEMANDA!$M$20*E$6 -> 28.98 | F23: =DEMANDA!$M$20*F$6 -> 28.98 | G23: =DEMANDA!$M$20*G$6 -> 28.98 | H23: =DEMANDA!$M$20*H$6 -> 25.76 | I23: =DEMANDA!$M$20*I$6 -> 28.98 | J23: =DEMANDA!$M$20*J$6 -> 28.98 | ... N23: =DEMANDA!$M$20*N$6 -> 25.76 | O23: =SUM(C23:N23) -> 322 | P23: =MAX(C23:N23) -> 28.98
A24: RODANTES | B24: =DEMANDA!C21 -> Cilindro ABC 50 kg vacío | C24: =DEMANDA!$M$21*C$6 -> 60.18 | D24: =DEMANDA!$M$21*D$6 -> 53.1 | E24: =DEMANDA!$M$21*E$6 -> 63.72 | F24: =DEMANDA!$M$21*F$6 -> 63.72 | G24: =DEMANDA!$M$21*G$6 -> 63.72 | H24: =DEMANDA!$M$21*H$6 -> 56.64 | I24: =DEMANDA!$M$21*I$6 -> 63.72 | J24: =DEMANDA!$M$21*J$6 -> 63.72 | ... N24: =DEMANDA!$M$21*N$6 -> 56.64 | O24: =SUM(C24:N24) -> 708 | P24: =MAX(C24:N24) -> 63.72
A25: RODANTES | B25: =DEMANDA!C22 -> Cilindro ABC 70 kg vacío | C25: =DEMANDA!$M$22*C$6 -> 13.175 | D25: =DEMANDA!$M$22*D$6 -> 11.625 | E25: =DEMANDA!$M$22*E$6 -> 13.95 | F25: =DEMANDA!$M$22*F$6 -> 13.95 | G25: =DEMANDA!$M$22*G$6 -> 13.95 | H25: =DEMANDA!$M$22*H$6 -> 12.4 | I25: =DEMANDA!$M$22*I$6 -> 13.95 | J25: =DEMANDA!$M$22*J$6 -> 13.95 | ... N25: =DEMANDA!$M$22*N$6 -> 12.4 | O25: =SUM(C25:N25) -> 155 | P25: =MAX(C25:N25) -> 13.95
A26: RODANTES | B26: =DEMANDA!C23 -> Cilindro ABC 100 kg vacío | C26: =DEMANDA!$M$23*C$6 -> 8.67 | D26: =DEMANDA!$M$23*D$6 -> 7.65 | E26: =DEMANDA!$M$23*E$6 -> 9.18 | F26: =DEMANDA!$M$23*F$6 -> 9.18 | G26: =DEMANDA!$M$23*G$6 -> 9.18 | H26: =DEMANDA!$M$23*H$6 -> 8.16 | I26: =DEMANDA!$M$23*I$6 -> 9.18 | J26: =DEMANDA!$M$23*J$6 -> 9.18 | ... N26: =DEMANDA!$M$23*N$6 -> 8.16 | O26: =SUM(C26:N26) -> 102 | P26: =MAX(C26:N26) -> 9.18
A27: RODANTES | B27: Total rodantes | C27: =SUM(C19:C26) -> 263.6085 | D27: =SUM(D19:D26) -> 232.59573 | E27: =SUM(E19:E26) -> 279.11488 | F27: =SUM(F19:F26) -> 279.11488 | G27: =SUM(G19:G26) -> 279.11488 | H27: =SUM(H19:H26) -> 248.10212 | I27: =SUM(I19:I26) -> 279.11488 | J27: =SUM(J19:J26) -> 279.11488 | ... O27: =SUM(O19:O26) -> 3101.2764
A28: RECARGAS | B28: =DEMANDA!C24 -> Recarga ABC 1 kg | C28: =DEMANDA!$M$24*C$7 -> 4707.2909 | D28: =DEMANDA!$M$24*D$7 -> 4707.2909 | E28: =DEMANDA!$M$24*E$7 -> 4707.2909 | F28: =DEMANDA!$M$24*F$7 -> 4707.2909 | G28: =DEMANDA!$M$24*G$7 -> 4707.2909 | H28: =DEMANDA!$M$24*H$7 -> 4707.2909 | I28: =DEMANDA!$M$24*I$7 -> 4707.2909 | J28: =DEMANDA!$M$24*J$7 -> 4707.2909 | ... N28: =DEMANDA!$M$24*N$7 -> 4707.2909 | O28: =SUM(C28:N28) -> 56487.491 | P28: =MAX(C28:N28) -> 4707.2909
A29: RECARGAS | B29: =DEMANDA!C25 -> Recarga ABC 2,5 kg | C29: =DEMANDA!$M$25*C$7 -> 398.60243 | D29: =DEMANDA!$M$25*D$7 -> 398.60243 | E29: =DEMANDA!$M$25*E$7 -> 398.60243 | F29: =DEMANDA!$M$25*F$7 -> 398.60243 | G29: =DEMANDA!$M$25*G$7 -> 398.60243 | H29: =DEMANDA!$M$25*H$7 -> 398.60243 | I29: =DEMANDA!$M$25*I$7 -> 398.60243 | J29: =DEMANDA!$M$25*J$7 -> 398.60243 | ... N29: =DEMANDA!$M$25*N$7 -> 398.60243 | O29: =SUM(C29:N29) -> 4783.2292 | P29: =MAX(C29:N29) -> 398.60243
A30: RECARGAS | B30: =DEMANDA!C26 -> Recarga ABC 5 kg | C30: =DEMANDA!$M$26*C$7 -> 2505.7365 | D30: =DEMANDA!$M$26*D$7 -> 2505.7365 | E30: =DEMANDA!$M$26*E$7 -> 2505.7365 | F30: =DEMANDA!$M$26*F$7 -> 2505.7365 | G30: =DEMANDA!$M$26*G$7 -> 2505.7365 | H30: =DEMANDA!$M$26*H$7 -> 2505.7365 | I30: =DEMANDA!$M$26*I$7 -> 2505.7365 | J30: =DEMANDA!$M$26*J$7 -> 2505.7365 | ... N30: =DEMANDA!$M$26*N$7 -> 2505.7365 | O30: =SUM(C30:N30) -> 30068.838 | P30: =MAX(C30:N30) -> 2505.7365
A31: RECARGAS | B31: =DEMANDA!C27 -> Recarga ABC 10 kg | C31: =DEMANDA!$M$27*C$7 -> 145.11512 | D31: =DEMANDA!$M$27*D$7 -> 145.11512 | E31: =DEMANDA!$M$27*E$7 -> 145.11512 | F31: =DEMANDA!$M$27*F$7 -> 145.11512 | G31: =DEMANDA!$M$27*G$7 -> 145.11512 | H31: =DEMANDA!$M$27*H$7 -> 145.11512 | I31: =DEMANDA!$M$27*I$7 -> 145.11512 | J31: =DEMANDA!$M$27*J$7 -> 145.11512 | ... N31: =DEMANDA!$M$27*N$7 -> 145.11512 | O31: =SUM(C31:N31) -> 1741.3814 | P31: =MAX(C31:N31) -> 145.11512
A32: RECARGAS | B32: =DEMANDA!C28 -> Recarga Agua 10 l | C32: =DEMANDA!$M$28*C$7 -> 204.87548 | D32: =DEMANDA!$M$28*D$7 -> 204.87548 | E32: =DEMANDA!$M$28*E$7 -> 204.87548 | F32: =DEMANDA!$M$28*F$7 -> 204.87548 | G32: =DEMANDA!$M$28*G$7 -> 204.87548 | H32: =DEMANDA!$M$28*H$7 -> 204.87548 | I32: =DEMANDA!$M$28*I$7 -> 204.87548 | J32: =DEMANDA!$M$28*J$7 -> 204.87548 | ... N32: =DEMANDA!$M$28*N$7 -> 204.87548 | O32: =SUM(C32:N32) -> 2458.5058 | P32: =MAX(C32:N32) -> 204.87548
A33: RECARGAS | B33: =DEMANDA!C29 -> Recarga AFFF 10 l | C33: =DEMANDA!$M$29*C$7 -> 38.909716 | D33: =DEMANDA!$M$29*D$7 -> 38.909716 | E33: =DEMANDA!$M$29*E$7 -> 38.909716 | F33: =DEMANDA!$M$29*F$7 -> 38.909716 | G33: =DEMANDA!$M$29*G$7 -> 38.909716 | H33: =DEMANDA!$M$29*H$7 -> 38.909716 | I33: =DEMANDA!$M$29*I$7 -> 38.909716 | J33: =DEMANDA!$M$29*J$7 -> 38.909716 | ... N33: =DEMANDA!$M$29*N$7 -> 38.909716 | O33: =SUM(C33:N33) -> 466.91659 | P33: =MAX(C33:N33) -> 38.909716
A34: RECARGAS | B34: =DEMANDA!C30 -> Recarga AFFF 50 l | C34: =DEMANDA!$M$30*C$7 -> 20.297355 | D34: =DEMANDA!$M$30*D$7 -> 20.297355 | E34: =DEMANDA!$M$30*E$7 -> 20.297355 | F34: =DEMANDA!$M$30*F$7 -> 20.297355 | G34: =DEMANDA!$M$30*G$7 -> 20.297355 | H34: =DEMANDA!$M$30*H$7 -> 20.297355 | I34: =DEMANDA!$M$30*I$7 -> 20.297355 | J34: =DEMANDA!$M$30*J$7 -> 20.297355 | ... N34: =DEMANDA!$M$30*N$7 -> 20.297355 | O34: =SUM(C34:N34) -> 243.56826 | P34: =MAX(C34:N34) -> 20.297355
A35: RECARGAS | B35: =DEMANDA!C31 -> Recarga BC 5 kg | C35: =DEMANDA!$M$31*C$7 -> 11.738789 | D35: =DEMANDA!$M$31*D$7 -> 11.738789 | E35: =DEMANDA!$M$31*E$7 -> 11.738789 | F35: =DEMANDA!$M$31*F$7 -> 11.738789 | G35: =DEMANDA!$M$31*G$7 -> 11.738789 | H35: =DEMANDA!$M$31*H$7 -> 11.738789 | I35: =DEMANDA!$M$31*I$7 -> 11.738789 | J35: =DEMANDA!$M$31*J$7 -> 11.738789 | ... N35: =DEMANDA!$M$31*N$7 -> 11.738789 | O35: =SUM(C35:N35) -> 140.86546 | P35: =MAX(C35:N35) -> 11.738789
A36: RECARGAS | B36: =DEMANDA!C32 -> Recarga Clase K 6 l | C36: =DEMANDA!$M$32*C$7 -> 101.02645 | D36: =DEMANDA!$M$32*D$7 -> 101.02645 | E36: =DEMANDA!$M$32*E$7 -> 101.02645 | F36: =DEMANDA!$M$32*F$7 -> 101.02645 | G36: =DEMANDA!$M$32*G$7 -> 101.02645 | H36: =DEMANDA!$M$32*H$7 -> 101.02645 | I36: =DEMANDA!$M$32*I$7 -> 101.02645 | J36: =DEMANDA!$M$32*J$7 -> 101.02645 | ... N36: =DEMANDA!$M$32*N$7 -> 101.02645 | O36: =SUM(C36:N36) -> 1212.3174 | P36: =MAX(C36:N36) -> 101.02645
A37: RECARGAS | B37: =DEMANDA!C33 -> Recarga CO₂ 2 kg | C37: =DEMANDA!$M$33*C$7 -> 545.22339 | D37: =DEMANDA!$M$33*D$7 -> 545.22339 | E37: =DEMANDA!$M$33*E$7 -> 545.22339 | F37: =DEMANDA!$M$33*F$7 -> 545.22339 | G37: =DEMANDA!$M$33*G$7 -> 545.22339 | H37: =DEMANDA!$M$33*H$7 -> 545.22339 | I37: =DEMANDA!$M$33*I$7 -> 545.22339 | J37: =DEMANDA!$M$33*J$7 -> 545.22339 | ... N37: =DEMANDA!$M$33*N$7 -> 545.22339 | O37: =SUM(C37:N37) -> 6542.6807 | P37: =MAX(C37:N37) -> 545.22339
A38: RECARGAS | B38: =DEMANDA!C34 -> Recarga CO₂ 5 kg | C38: =DEMANDA!$M$34*C$7 -> 194.24569 | D38: =DEMANDA!$M$34*D$7 -> 194.24569 | E38: =DEMANDA!$M$34*E$7 -> 194.24569 | F38: =DEMANDA!$M$34*F$7 -> 194.24569 | G38: =DEMANDA!$M$34*G$7 -> 194.24569 | H38: =DEMANDA!$M$34*H$7 -> 194.24569 | I38: =DEMANDA!$M$34*I$7 -> 194.24569 | J38: =DEMANDA!$M$34*J$7 -> 194.24569 | ... N38: =DEMANDA!$M$34*N$7 -> 194.24569 | O38: =SUM(C38:N38) -> 2330.9482 | P38: =MAX(C38:N38) -> 194.24569
A39: RECARGAS | B39: =DEMANDA!C35 -> Recarga HCFC 5 kg | C39: =DEMANDA!$M$35*C$7 -> 30.839698 | D39: =DEMANDA!$M$35*D$7 -> 30.839698 | E39: =DEMANDA!$M$35*E$7 -> 30.839698 | F39: =DEMANDA!$M$35*F$7 -> 30.839698 | G39: =DEMANDA!$M$35*G$7 -> 30.839698 | H39: =DEMANDA!$M$35*H$7 -> 30.839698 | I39: =DEMANDA!$M$35*I$7 -> 30.839698 | J39: =DEMANDA!$M$35*J$7 -> 30.839698 | ... N39: =DEMANDA!$M$35*N$7 -> 30.839698 | O39: =SUM(C39:N39) -> 370.07637 | P39: =MAX(C39:N39) -> 30.839698
A40: RECARGAS | B40: =DEMANDA!C36 -> Recarga Clase D 9 l | C40: =DEMANDA!$M$36*C$7 -> 10.592621 | D40: =DEMANDA!$M$36*D$7 -> 10.592621 | E40: =DEMANDA!$M$36*E$7 -> 10.592621 | F40: =DEMANDA!$M$36*F$7 -> 10.592621 | G40: =DEMANDA!$M$36*G$7 -> 10.592621 | H40: =DEMANDA!$M$36*H$7 -> 10.592621 | I40: =DEMANDA!$M$36*I$7 -> 10.592621 | J40: =DEMANDA!$M$36*J$7 -> 10.592621 | ... N40: =DEMANDA!$M$36*N$7 -> 10.592621 | O40: =SUM(C40:N40) -> 127.11145 | P40: =MAX(C40:N40) -> 10.592621
A41: RECARGAS | B41: =DEMANDA!C37 -> Recarga ABC 25 kg | C41: =DEMANDA!$M$37*C$7 -> 24.988007 | D41: =DEMANDA!$M$37*D$7 -> 24.988007 | E41: =DEMANDA!$M$37*E$7 -> 24.988007 | F41: =DEMANDA!$M$37*F$7 -> 24.988007 | G41: =DEMANDA!$M$37*G$7 -> 24.988007 | H41: =DEMANDA!$M$37*H$7 -> 24.988007 | I41: =DEMANDA!$M$37*I$7 -> 24.988007 | J41: =DEMANDA!$M$37*J$7 -> 24.988007 | ... N41: =DEMANDA!$M$37*N$7 -> 24.988007 | O41: =SUM(C41:N41) -> 299.85609 | P41: =MAX(C41:N41) -> 24.988007
A42: RECARGAS | B42: =DEMANDA!C38 -> Recarga ABC 50 kg | C42: =DEMANDA!$M$38*C$7 -> 55.836975 | D42: =DEMANDA!$M$38*D$7 -> 55.836975 | E42: =DEMANDA!$M$38*E$7 -> 55.836975 | F42: =DEMANDA!$M$38*F$7 -> 55.836975 | G42: =DEMANDA!$M$38*G$7 -> 55.836975 | H42: =DEMANDA!$M$38*H$7 -> 55.836975 | I42: =DEMANDA!$M$38*I$7 -> 55.836975 | J42: =DEMANDA!$M$38*J$7 -> 55.836975 | ... N42: =DEMANDA!$M$38*N$7 -> 55.836975 | O42: =SUM(C42:N42) -> 670.0437 | P42: =MAX(C42:N42) -> 55.836975
...

Sheet MANUALES
A1: MANUALES: consumo por unidad de producto y lo que hay que comprar
A3: Ref. | B3: Código | C3: Material | D3: UM | E3: Destino | F3: ABC 1 kg | G3: ABC 2,5 kg | H3: ABC 5 kg | I3: ABC 10 kg | J3: Cilindro ABC 1 kg | K3: Cilindro ABC 2,5 kg | L3: Cilindro ABC 5 kg | M3: Cilindro ABC 10 kg | N3: 2026 | O3: 2027 | P3: 2028 | Q3: 2029 | R3: 2030 | S3: 2031 | T3: 2032 | U3: 2033 | V3: 2034 | W3: 2035 | X3: Mes pico 2035
C4: Demanda 2026 | F4: =DEMANDA!D8 -> 4178.7365 | G4: =DEMANDA!D9 -> 295.03036 | H4: =DEMANDA!D10 -> 2727.9036 | I4: =DEMANDA!D11 -> 92.408754 | J4: =DEMANDA!D12 -> 0 | K4: =DEMANDA!D13 -> 0 | L4: =DEMANDA!D14 -> 0 | M4: =DEMANDA!D15 -> 0
C5: Demanda 2027 | F5: =DEMANDA!E8 -> 5997.304 | G5: =DEMANDA!E9 -> 709.72745 | H5: =DEMANDA!E10 -> 5488.9106 | I5: =DEMANDA!E11 -> 178.13943 | J5: =DEMANDA!E12 -> 0 | K5: =DEMANDA!E13 -> 0 | L5: =DEMANDA!E14 -> 0 | M5: =DEMANDA!E15 -> 0
C6: Demanda 2028 | F6: =DEMANDA!F8 -> 6851.7478 | G6: =DEMANDA!F9 -> 986.86806 | H6: =DEMANDA!F10 -> 7206.5855 | I6: =DEMANDA!F11 -> 255.06523 | J6: =DEMANDA!F12 -> 7662.4 | K6: =DEMANDA!F13 -> 299.6 | L6: =DEMANDA!F14 -> 1478.8 | M6: =DEMANDA!F15 -> 90.4
C7: Demanda 2029 | F7: =DEMANDA!G8 -> 8467.1355 | G7: =DEMANDA!G9 -> 1500.6382 | H7: =DEMANDA!G10 -> 10420.908 | I7: =DEMANDA!G11 -> 361.07103 | J7: =DEMANDA!G12 -> 26694.8 | K7: =DEMANDA!G13 -> 1043.8 | L7: =DEMANDA!G14 -> 5152 | M7: =DEMANDA!G15 -> 315
C8: Demanda 2030 | F8: =DEMANDA!H8 -> 12680.633 | G8: =DEMANDA!H9 -> 2312.6277 | H8: =DEMANDA!H10 -> 14495.071 | I8: =DEMANDA!H11 -> 605.62479 | J8: =DEMANDA!H12 -> 49434.8 | K8: =DEMANDA!H13 -> 1933 | L8: =DEMANDA!H14 -> 9540.8 | M8: =DEMANDA!H15 -> 583.4
C9: Demanda 2031 | F9: =DEMANDA!I8 -> 15620.253 | G9: =DEMANDA!I9 -> 3252.8699 | H9: =DEMANDA!I10 -> 18737.061 | I9: =DEMANDA!I11 -> 876.21675 | J9: =DEMANDA!I12 -> 71680.2 | K9: =DEMANDA!I13 -> 2803 | L9: =DEMANDA!I14 -> 13834.2 | M9: =DEMANDA!I15 -> 845.8
C10: Demanda 2032 | F10: =DEMANDA!J8 -> 20332.553 | G10: =DEMANDA!J9 -> 4102.3155 | H10: =DEMANDA!J10 -> 22634.482 | I10: =DEMANDA!J11 -> 1130.355 | J10: =DEMANDA!J12 -> 101340.6 | K10: =DEMANDA!J13 -> 3963 | L10: =DEMANDA!J14 -> 19558.6 | M10: =DEMANDA!J15 -> 1195.4
C11: Demanda 2033 | F11: =DEMANDA!K8 -> 25132.078 | G11: =DEMANDA!K9 -> 5104.3066 | H11: =DEMANDA!K10 -> 26002.338 | I11: =DEMANDA!K11 -> 1397.6176 | J11: =DEMANDA!K12 -> 131001 | K11: =DEMANDA!K13 -> 5123 | L11: =DEMANDA!K14 -> 25283 | M11: =DEMANDA!K15 -> 1545
C12: Demanda 2034 | F12: =DEMANDA!L8 -> 28573.336 | G12: =DEMANDA!L9 -> 6195.1862 | H12: =DEMANDA!L10 -> 28613.4 | I12: =DEMANDA!L11 -> 1614.5948 | J12: =DEMANDA!L12 -> 146819.8 | K12: =DEMANDA!L13 -> 5741.4 | L12: =DEMANDA!L14 -> 28335.8 | M12: =DEMANDA!L15 -> 1731.4
C13: Demanda 2035 | F13: =DEMANDA!M8 -> 32072.639 | G13: =DEMANDA!M9 -> 7424.8584 | H13: =DEMANDA!M10 -> 32428.771 | I13: =DEMANDA!M11 -> 1842.877 | J13: =DEMANDA!M12 -> 170548 | K13: =DEMANDA!M13 -> 6669 | L13: =DEMANDA!M14 -> 32915 | M13: =DEMANDA!M15 -> 2011
C14: Producción del mes pico de cada producto, 2035 | F14: =ESTACIONALIDAD!P10 -> 3848.7167 | G14: =ESTACIONALIDAD!P11 -> 816.73443 | H14: =ESTACIONALIDAD!P12 -> 3567.1648 | I14: =ESTACIONALIDAD!P13 -> 202.71647 | J14: =ESTACIONALIDAD!P14 -> 20465.76 | K14: =ESTACIONALIDAD!P15 -> 733.59 | L14: =ESTACIONALIDAD!P16 -> 3620.65 | M14: =ESTACIONALIDAD!P17 -> 221.21
C15: CONSUMO POR UNIDAD (cantidad del material por cada producto)
A16: M01 | B16: MP-01 | C16: Caño c/costura Ø76,2 × 1,25 × 6 m (cuerpo 1 kg) | D16: barra | F16: =1/23 -> 0.043478261 | J16: =1/23 -> 0.043478261 | N16: =SUMPRODUCT($F16:$M16,$F$4:$M$4) -> 181.6842 | O16: =SUMPRODUCT($F16:$M16,$F$5:$M$5) -> 260.75235 | P16: =SUMPRODUCT($F16:$M16,$F$6:$M$6) -> 631.0499 | Q16: =SUMPRODUCT($F16:$M16,$F$7:$M$7) -> 1528.7798 | R16: =SUMPRODUCT($F16:$M16,$F$8:$M$8) -> 2700.671 | S16: =SUMPRODUCT($F16:$M16,$F$9:$M$9) -> 3795.6719 | T16: =SUMPRODUCT($F16:$M16,$F$10:$M$10) -> 5290.1371 | U16: =SUMPRODUCT($F16:$M16,$F$11:$M$11) -> 6788.3947 | V16: =SUMPRODUCT($F16:$M16,$F$12:$M$12) -> 7625.7885 | W16: =SUMPRODUCT($F16:$M16,$F$13:$M$13) -> 8809.593 | X16: =SUMPRODUCT($F16:$M16,$F$14:$M$14) -> 1057.1512
A17: M02 | B17: MP-02 | C17: Hoja LAF 1,25 × 1220 × 2440 mm | D17: hoja | G17: =1/27 -> 0.037037037 | K17: =1/27 -> 0.037037037 | N17: =SUMPRODUCT($F17:$M17,$F$4:$M$4) -> 10.92705 | O17: =SUMPRODUCT($F17:$M17,$F$5:$M$5) -> 26.286202 | P17: =SUMPRODUCT($F17:$M17,$F$6:$M$6) -> 47.646965 | Q17: =SUMPRODUCT($F17:$M17,$F$7:$M$7) -> 94.238451 | R17: =SUMPRODUCT($F17:$M17,$F$8:$M$8) -> 157.24547 | S17: =SUMPRODUCT($F17:$M17,$F$9:$M$9) -> 224.29148 | T17: =SUMPRODUCT($F17:$M17,$F$10:$M$10) -> 298.71539 | U17: =SUMPRODUCT($F17:$M17,$F$11:$M$11) -> 378.78913 | V17: =SUMPRODUCT($F17:$M17,$F$12:$M$12) -> 442.09579 | W17: =SUMPRODUCT($F17:$M17,$F$13:$M$13) -> 521.99476 | X17: =SUMPRODUCT($F17:$M17,$F$14:$M$14) -> 57.419423
A18: M03 | B18: MP-03 | C18: Hoja LAF 1,6 × 1000 × 2000 mm | D18: hoja | H18: =1/12 -> 0.083333333 | L18: =1/12 -> 0.083333333 | N18: =SUMPRODUCT($F18:$M18,$F$4:$M$4) -> 227.3253 | O18: =SUMPRODUCT($F18:$M18,$F$5:$M$5) -> 457.40922 | P18: =SUMPRODUCT($F18:$M18,$F$6:$M$6) -> 723.78212 | Q18: =SUMPRODUCT($F18:$M18,$F$7:$M$7) -> 1297.7423 | R18: =SUMPRODUCT($F18:$M18,$F$8:$M$8) -> 2002.9893 | S18: =SUMPRODUCT($F18:$M18,$F$9:$M$9) -> 2714.2717 | T18: =SUMPRODUCT($F18:$M18,$F$10:$M$10) -> 3516.0902 | U18: =SUMPRODUCT($F18:$M18,$F$11:$M$11) -> 4273.7782 | V18: =SUMPRODUCT($F18:$M18,$F$12:$M$12) -> 4745.7666 | W18: =SUMPRODUCT($F18:$M18,$F$13:$M$13) -> 5445.3142 | X18: =SUMPRODUCT($F18:$M18,$F$14:$M$14) -> 598.98456
A19: M04 | B19: MP-04 | C19: Hoja LAF 2,0 × 1500 × 3000 mm | D19: hoja | I19: =1/15 -> 0.066666667 | M19: =1/15 -> 0.066666667 | N19: =SUMPRODUCT($F19:$M19,$F$4:$M$4) -> 6.1605836 | O19: =SUMPRODUCT($F19:$M19,$F$5:$M$5) -> 11.875962 | P19: =SUMPRODUCT($F19:$M19,$F$6:$M$6) -> 23.031015 | Q19: =SUMPRODUCT($F19:$M19,$F$7:$M$7) -> 45.071402 | R19: =SUMPRODUCT($F19:$M19,$F$8:$M$8) -> 79.26832 | S19: =SUMPRODUCT($F19:$M19,$F$9:$M$9) -> 114.80112 | T19: =SUMPRODUCT($F19:$M19,$F$10:$M$10) -> 155.05033 | U19: =SUMPRODUCT($F19:$M19,$F$11:$M$11) -> 196.17451 | V19: =SUMPRODUCT($F19:$M19,$F$12:$M$12) -> 223.06632 | W19: =SUMPRODUCT($F19:$M19,$F$13:$M$13) -> 256.92513 | X19: =SUMPRODUCT($F19:$M19,$F$14:$M$14) -> 28.261764
A20: M05 | B20: MP-05 | C20: Fleje LAF 0,9 × 114 mm (cúpula 1 kg) | D20: kg | F20: =114*(95+3)*0.9*7.85/1000000 -> 0.07893018 | J20: =114*(95+3)*0.9*7.85/1000000 -> 0.07893018 | N20: =SUMPRODUCT($F20:$M20,$F$4:$M$4) -> 329.82843 | O20: =SUMPRODUCT($F20:$M20,$F$5:$M$5) -> 473.36828 | P20: =SUMPRODUCT($F20:$M20,$F$6:$M$6) -> 1145.6043 | Q20: =SUMPRODUCT($F20:$M20,$F$7:$M$7) -> 2775.3379 | R20: =SUMPRODUCT($F20:$M20,$F$8:$M$8) -> 4902.7823 | S20: =SUMPRODUCT($F20:$M20,$F$9:$M$9) -> 6890.6405 | T20: =SUMPRODUCT($F20:$M20,$F$10:$M$10) -> 9603.6839 | U20: =SUMPRODUCT($F20:$M20,$F$11:$M$11) -> 12323.612 | V20: =SUMPRODUCT($F20:$M20,$F$12:$M$12) -> 13843.812 | W20: =SUMPRODUCT($F20:$M20,$F$13:$M$13) -> 15992.884 | X20: =SUMPRODUCT($F20:$M20,$F$14:$M$14) -> 1919.146
A21: M06 | B21: MP-13 | C21: Fleje LAF 1,25 × 135 mm (fondo 1 kg) | D21: kg | F21: =135*(112+3)*1.25*7.85/1000000 -> 0.15233906 | J21: =135*(112+3)*1.25*7.85/1000000 -> 0.15233906 | N21: =SUMPRODUCT($F21:$M21,$F$4:$M$4) -> 636.58481 | O21: =SUMPRODUCT($F21:$M21,$F$5:$M$5) -> 913.62367 | P21: =SUMPRODUCT($F21:$M21,$F$6:$M$6) -> 2211.0717 | Q21: =SUMPRODUCT($F21:$M21,$F$7:$M$7) -> 5356.5363 | R21: =SUMPRODUCT($F21:$M21,$F$8:$M$8) -> 9462.6068 | S21: =SUMPRODUCT($F21:$M21,$F$9:$M$9) -> 13299.269 | T21: =SUMPRODUCT($F21:$M21,$F$10:$M$10) -> 18535.574 | U21: =SUMPRODUCT($F21:$M21,$F$11:$M$11) -> 23785.167 | V21: =SUMPRODUCT($F21:$M21,$F$12:$M$12) -> 26719.226 | W21: =SUMPRODUCT($F21:$M21,$F$13:$M$13) -> 30867.038 | X21: =SUMPRODUCT($F21:$M21,$F$14:$M$14) -> 3704.0446
A22: M07 | B22: MP-06 | C22: Fleje LAF 1,25 × 200 mm (cúpula y fondo 2,5 kg) | D22: kg | G22: =200*(179+3)*1.25*7.85/1000000+200*(148+3)*1.25*7.85/1000000 -> 0.6535125 | K22: =200*(179+3)*1.25*7.85/1000000+200*(148+3)*1.25*7.85/1000000 -> 0.6535125 | N22: =SUMPRODUCT($F22:$M22,$F$4:$M$4) -> 192.80603 | O22: =SUMPRODUCT($F22:$M22,$F$5:$M$5) -> 463.81576 | P22: =SUMPRODUCT($F22:$M22,$F$6:$M$6) -> 840.72296 | Q22: =SUMPRODUCT($F22:$M22,$F$7:$M$7) -> 1662.8222 | R22: =SUMPRODUCT($F22:$M22,$F$8:$M$8) -> 2774.5708 | S22: =SUMPRODUCT($F22:$M22,$F$9:$M$9) -> 3957.5867 | T22: =SUMPRODUCT($F22:$M22,$F$10:$M$10) -> 5270.7845 | U22: =SUMPRODUCT($F22:$M22,$F$11:$M$11) -> 6683.6727 | V22: =SUMPRODUCT($F22:$M22,$F$12:$M$12) -> 7800.7083 | W22: =SUMPRODUCT($F22:$M22,$F$13:$M$13) -> 9210.5127 | X22: =SUMPRODUCT($F22:$M22,$F$14:$M$14) -> 1013.1564
A23: M08 | B23: MP-07 | C23: Fleje LAF 1,6 × 250 mm (cúpula 5 kg) | D23: kg | H23: =250*(221+3)*1.6*7.85/1000000 -> 0.70336 | L23: =250*(221+3)*1.6*7.85/1000000 -> 0.70336 | N23: =SUMPRODUCT($F23:$M23,$F$4:$M$4) -> 1918.6983 | O23: =SUMPRODUCT($F23:$M23,$F$5:$M$5) -> 3860.6802 | P23: =SUMPRODUCT($F23:$M23,$F$6:$M$6) -> 6108.9527 | Q23: =SUMPRODUCT($F23:$M23,$F$7:$M$7) -> 10953.36 | R23: =SUMPRODUCT($F23:$M23,$F$8:$M$8) -> 16905.87 | S23: =SUMPRODUCT($F23:$M23,$F$9:$M$9) -> 22909.322 | T23: =SUMPRODUCT($F23:$M23,$F$10:$M$10) -> 29676.926 | U23: =SUMPRODUCT($F23:$M23,$F$11:$M$11) -> 36072.056 | V23: =SUMPRODUCT($F23:$M23,$F$12:$M$12) -> 40055.789 | W23: =SUMPRODUCT($F23:$M23,$F$13:$M$13) -> 45960.195 | X23: =SUMPRODUCT($F23:$M23,$F$14:$M$14) -> 5055.6214
A24: M09 | B24: MP-08 | C24: Fleje LAF 1,6 × 200 mm (fondo 5 kg) | D24: kg | H24: =200*(177+3)*1.6*7.85/1000000 -> 0.45216 | L24: =200*(177+3)*1.6*7.85/1000000 -> 0.45216 | N24: =SUMPRODUCT($F24:$M24,$F$4:$M$4) -> 1233.4489 | O24: =SUMPRODUCT($F24:$M24,$F$5:$M$5) -> 2481.8658 | P24: =SUMPRODUCT($F24:$M24,$F$6:$M$6) -> 3927.1839 | Q24: =SUMPRODUCT($F24:$M24,$F$7:$M$7) -> 7041.446 | R24: =SUMPRODUCT($F24:$M24,$F$8:$M$8) -> 10868.06 | S24: =SUMPRODUCT($F24:$M24,$F$9:$M$9) -> 14727.421 | T24: =SUMPRODUCT($F24:$M24,$F$10:$M$10) -> 19078.024 | U24: =SUMPRODUCT($F24:$M24,$F$11:$M$11) -> 23189.179 | V24: =SUMPRODUCT($F24:$M24,$F$12:$M$12) -> 25750.15 | W24: =SUMPRODUCT($F24:$M24,$F$13:$M$13) -> 29545.839 | X24: =SUMPRODUCT($F24:$M24,$F$14:$M$14) -> 3250.0423
A25: M10 | B25: MP-09 | C25: Fleje LAF 1,6 × 300 mm (cúpula 10 kg) | D25: kg | I25: =300*(258+3)*1.6*7.85/1000000 -> 0.983448 | M25: =300*(258+3)*1.6*7.85/1000000 -> 0.983448 | N25: =SUMPRODUCT($F25:$M25,$F$4:$M$4) -> 90.879205 | O25: =SUMPRODUCT($F25:$M25,$F$5:$M$5) -> 175.19087 | P25: =SUMPRODUCT($F25:$M25,$F$6:$M$6) -> 339.74709 | Q25: =SUMPRODUCT($F25:$M25,$F$7:$M$7) -> 664.8807 | R25: =SUMPRODUCT($F25:$M25,$F$8:$M$8) -> 1169.3441 | S25: =SUMPRODUCT($F25:$M25,$F$9:$M$9) -> 1693.5139 | T25: =SUMPRODUCT($F25:$M25,$F$10:$M$10) -> 2287.2591 | U25: =SUMPRODUCT($F25:$M25,$F$11:$M$11) -> 2893.9114 | V25: =SUMPRODUCT($F25:$M25,$F$12:$M$12) -> 3290.6119 | W25: =SUMPRODUCT($F25:$M25,$F$13:$M$13) -> 3790.0876 | X25: =SUMPRODUCT($F25:$M25,$F$14:$M$14) -> 416.90964
A26: M11 | B26: MP-10 | C26: Fleje LAF 2,0 × 249 mm (fondo 10 kg) | D26: kg | I26: =249*(205+3)*2*7.85/1000000 -> 0.8131344 | M26: =249*(205+3)*2*7.85/1000000 -> 0.8131344 | N26: =SUMPRODUCT($F26:$M26,$F$4:$M$4) -> 75.140737 | O26: =SUMPRODUCT($F26:$M26,$F$5:$M$5) -> 144.8513 | P26: =SUMPRODUCT($F26:$M26,$F$6:$M$6) -> 280.90966 | Q26: =SUMPRODUCT($F26:$M26,$F$7:$M$7) -> 549.73661 | R26: =SUMPRODUCT($F26:$M26,$F$8:$M$8) -> 966.83696 | S26: =SUMPRODUCT($F26:$M26,$F$9:$M$9) -> 1400.2311 | T26: =SUMPRODUCT($F26:$M26,$F$10:$M$10) -> 1891.1514 | U26: =SUMPRODUCT($F26:$M26,$F$11:$M$11) -> 2392.7436 | V26: =SUMPRODUCT($F26:$M26,$F$12:$M$12) -> 2720.7435 | W26: =SUMPRODUCT($F26:$M26,$F$13:$M$13) -> 3133.7199 | X26: =SUMPRODUCT($F26:$M26,$F$14:$M$14) -> 344.70919
A27: M12 | B27: MP-18 | C27: Asiento de válvula M22 × 1,5 (1 kg) | D27: u | F27: 1 | J27: 1 | N27: =SUMPRODUCT($F27:$M27,$F$4:$M$4) -> 4178.7365 | O27: =SUMPRODUCT($F27:$M27,$F$5:$M$5) -> 5997.304 | P27: =SUMPRODUCT($F27:$M27,$F$6:$M$6) -> 14514.148 | Q27: =SUMPRODUCT($F27:$M27,$F$7:$M$7) -> 35161.936 | R27: =SUMPRODUCT($F27:$M27,$F$8:$M$8) -> 62115.433 | S27: =SUMPRODUCT($F27:$M27,$F$9:$M$9) -> 87300.453 | T27: =SUMPRODUCT($F27:$M27,$F$10:$M$10) -> 121673.15 | U27: =SUMPRODUCT($F27:$M27,$F$11:$M$11) -> 156133.08 | V27: =SUMPRODUCT($F27:$M27,$F$12:$M$12) -> 175393.14 | W27: =SUMPRODUCT($F27:$M27,$F$13:$M$13) -> 202620.64 | X27: =SUMPRODUCT($F27:$M27,$F$14:$M$14) -> 24314.477
A28: M13 | B28: MP-19 | C28: Asiento de válvula M30 × 1,5 (2,5 a 10 kg) | D28: u | G28: 1 | H28: 1 | I28: 1 | K28: 1 | L28: 1 | M28: 1 | N28: =SUMPRODUCT($F28:$M28,$F$4:$M$4) -> 3115.3427 | O28: =SUMPRODUCT($F28:$M28,$F$5:$M$5) -> 6376.7775 | P28: =SUMPRODUCT($F28:$M28,$F$6:$M$6) -> 10317.319 | Q28: =SUMPRODUCT($F28:$M28,$F$7:$M$7) -> 18793.417 | R28: =SUMPRODUCT($F28:$M28,$F$8:$M$8) -> 29470.524 | S28: =SUMPRODUCT($F28:$M28,$F$9:$M$9) -> 40349.148 | T28: =SUMPRODUCT($F28:$M28,$F$10:$M$10) -> 52584.153 | U28: =SUMPRODUCT($F28:$M28,$F$11:$M$11) -> 64455.263 | V28: =SUMPRODUCT($F28:$M28,$F$12:$M$12) -> 72231.781 | W28: =SUMPRODUCT($F28:$M28,$F$13:$M$13) -> 83291.506 | X28: =SUMPRODUCT($F28:$M28,$F$14:$M$14) -> 9162.0657
A29: M14 | B29: MP-23 | C29: Alambre MAG ER70S-6 Ø0,9 mm (manuales) | D29: kg | F29: 0.01499 | G29: 0.0304 | H29: 0.03675 | I29: 0.04575 | J29: 0.01499 | K29: 0.0304 | L29: 0.03675 | M29: 0.04575 | N29: =SUMPRODUCT($F29:$M29,$F$4:$M$4) -> 176.08634 | O29: =SUMPRODUCT($F29:$M29,$F$5:$M$5) -> 321.34265 | P29: =SUMPRODUCT($F29:$M29,$F$6:$M$6) -> 591.66866 | Q29: =SUMPRODUCT($F29:$M29,$F$7:$M$7) -> 1207.6629 | R29: =SUMPRODUCT($F29:$M29,$F$8:$M$8) -> 1997.8936 | S29: =SUMPRODUCT($F29:$M29,$F$9:$M$9) -> 2768.5083 | T29: =SUMPRODUCT($F29:$M29,$F$10:$M$10) -> 3726.0652 | U29: =SUMPRODUCT($F29:$M29,$F$11:$M$11) -> 4670.7059 | V29: =SUMPRODUCT($F29:$M29,$F$12:$M$12) -> 5237.9777 | W29: =SUMPRODUCT($F29:$M29,$F$13:$M$13) -> 6043.4351 | X29: =SUMPRODUCT($F29:$M29,$F$14:$M$14) -> 695.1507
A30: M15 | B30: MP-25 | C30: Gas MAG Ar + 8 % CO₂ (Arcal 21) | D30: m³ | F30: =0.01671*48/(1216*0.01671+99*0.03388+446*0.04096+27*0.051) -> 0.018515817 | G30: =0.03388*48/(1216*0.01671+99*0.03388+446*0.04096+27*0.051) -> 0.037541345 | H30: =0.04096*48/(1216*0.01671+99*0.03388+446*0.04096+27*0.051) -> 0.045386466 | I30: =0.051*48/(1216*0.01671+99*0.03388+446*0.04096+27*0.051) -> 0.056511469 | J30: =0.01671*48/(1216*0.01671+99*0.03388+446*0.04096+27*0.051) -> 0.018515817 | K30: =0.03388*48/(1216*0.01671+99*0.03388+446*0.04096+27*0.051) -> 0.037541345 | L30: =0.04096*48/(1216*0.01671+99*0.03388+446*0.04096+27*0.051) -> 0.045386466 | M30: =0.051*48/(1216*0.01671+99*0.03388+446*0.04096+27*0.051) -> 0.056511469 | N30: =SUMPRODUCT($F30:$M30,$F$4:$M$4) -> 217.48061 | O30: =SUMPRODUCT($F30:$M30,$F$5:$M$5) -> 396.87828 | P30: =SUMPRODUCT($F30:$M30,$F$6:$M$6) -> 730.75875 | Q30: =SUMPRODUCT($F30:$M30,$F$7:$M$7) -> 1491.5786 | R30: =SUMPRODUCT($F30:$M30,$F$8:$M$8) -> 2467.6013 | S30: =SUMPRODUCT($F30:$M30,$F$9:$M$9) -> 3419.3928 | T30: =SUMPRODUCT($F30:$M30,$F$10:$M$10) -> 4602.0873 | U30: =SUMPRODUCT($F30:$M30,$F$11:$M$11) -> 5768.8302 | V30: =SUMPRODUCT($F30:$M30,$F$12:$M$12) -> 6469.4727 | W30: =SUMPRODUCT($F30:$M30,$F$13:$M$13) -> 7464.3001 | X30: =SUMPRODUCT($F30:$M30,$F$14:$M$14) -> 858.58988
A31: M16 | B31: MP-28 | C31: Granalla de acero S330 / S390 | D31: kg | F31: 0.08 | G31: 0.08 | H31: 0.08 | I31: 0.08 | J31: 0.08 | K31: 0.08 | L31: 0.08 | M31: 0.08 | N31: =SUMPRODUCT($F31:$M31,$F$4:$M$4) -> 583.52634 | O31: =SUMPRODUCT($F31:$M31,$F$5:$M$5) -> 989.92652 | P31: =SUMPRODUCT($F31:$M31,$F$6:$M$6) -> 1986.5173 | Q31: =SUMPRODUCT($F31:$M31,$F$7:$M$7) -> 4316.4282 | R31: =SUMPRODUCT($F31:$M31,$F$8:$M$8) -> 7326.8765 | S31: =SUMPRODUCT($F31:$M31,$F$9:$M$9) -> 10211.968 | T31: =SUMPRODUCT($F31:$M31,$F$10:$M$10) -> 13940.584 | U31: =SUMPRODUCT($F31:$M31,$F$11:$M$11) -> 17647.067 | V31: =SUMPRODUCT($F31:$M31,$F$12:$M$12) -> 19809.993 | W31: =SUMPRODUCT($F31:$M31,$F$13:$M$13) -> 22872.972 | X31: =SUMPRODUCT($F31:$M31,$F$14:$M$14) -> 2678.1234
A32: M17 | B32: MP-31 | C32: Pintura en polvo poliéster rojo 03-1-050 | D32: kg | F32: =0.0764/9.46/0.95 -> 0.0085011684 | G32: =0.1375/9.46/0.95 -> 0.015299878 | H32: =0.2091/9.46/0.95 -> 0.023266941 | I32: =0.351/9.46/0.95 -> 0.039056415 | J32: =0.0764/9.46/0.95 -> 0.0085011684 | K32: =0.1375/9.46/0.95 -> 0.015299878 | L32: =0.2091/9.46/0.95 -> 0.023266941 | M32: =0.351/9.46/0.95 -> 0.039056415 | N32: =SUMPRODUCT($F32:$M32,$F$4:$M$4) -> 107.1172 | O32: =SUMPRODUCT($F32:$M32,$F$5:$M$5) -> 196.51048 | P32: =SUMPRODUCT($F32:$M32,$F$6:$M$6) -> 358.645 | Q32: =SUMPRODUCT($F32:$M32,$F$7:$M$7) -> 726.58597 | R32: =SUMPRODUCT($F32:$M32,$F$8:$M$8) -> 1198.6916 | S32: =SUMPRODUCT($F32:$M32,$F$9:$M$9) -> 1659.8993 | T32: =SUMPRODUCT($F32:$M32,$F$10:$M$10) -> 2230.3019 | U32: =SUMPRODUCT($F32:$M32,$F$11:$M$11) -> 2791.9712 | V32: =SUMPRODUCT($F32:$M32,$F$12:$M$12) -> 3129.3911 | W32: =SUMPRODUCT($F32:$M32,$F$13:$M$13) -> 3609.0148 | X32: =SUMPRODUCT($F32:$M32,$F$14:$M$14) -> 414.21675
A33: M18 | B33: MP-33 | C33: Polvo ABC 60 (manuales y sus recargas) | D33: kg | F33: 1.05 | G33: 2.55 | H33: 5.15 | I33: 10.15 | N33: =SUMPRODUCT($F33:$M33,$F$4:$M$4) -> 20126.653 | O33: =SUMPRODUCT($F33:$M33,$F$5:$M$5) -> 38182.979 | P33: =SUMPRODUCT($F33:$M33,$F$6:$M$6) -> 49413.676 | Q33: =SUMPRODUCT($F33:$M33,$F$7:$M$7) -> 70049.666 | R33: =SUMPRODUCT($F33:$M33,$F$8:$M$8) -> 100008.57 | S33: =SUMPRODUCT($F33:$M33,$F$9:$M$9) -> 130085.55 | T33: =SUMPRODUCT($F33:$M33,$F$10:$M$10) -> 159850.77 | U33: =SUMPRODUCT($F33:$M33,$F$11:$M$11) -> 187502.53 | V33: =SUMPRODUCT($F33:$M33,$F$12:$M$12) -> 209546.87 | W33: =SUMPRODUCT($F33:$M33,$F$13:$M$13) -> 238323.03 | X33: =SUMPRODUCT($F33:$M33,$F$14:$M$14) -> 26552.296
A34: M19 | B34: MP-34 | C34: Nitrógeno seco | D34: m³ | F34: =1.18/3*14/1000 -> 0.0055066667 | G34: =3.5/3*14/1000 -> 0.016333333 | H34: =6/3*14/1000 -> 0.028 | I34: =12.5/3*14/1000 -> 0.058333333 | N34: =SUMPRODUCT($F34:$M34,$F$4:$M$4) -> 109.60155 | O34: =SUMPRODUCT($F34:$M34,$F$5:$M$5) -> 208.69833 | P34: =SUMPRODUCT($F34:$M34,$F$6:$M$6) -> 270.51233 | Q34: =SUMPRODUCT($F34:$M34,$F$7:$M$7) -> 383.98401 | R34: =SUMPRODUCT($F34:$M34,$F$8:$M$8) -> 548.79105 | S34: =SUMPRODUCT($F34:$M34,$F$9:$M$9) -> 714.89609 | T34: =SUMPRODUCT($F34:$M34,$F$10:$M$10) -> 878.67196 | U34: =SUMPRODUCT($F34:$M34,$F$11:$M$11) -> 1031.3575 | V34: =SUMPRODUCT($F34:$M34,$F$12:$M$12) -> 1153.8918 | W34: =SUMPRODUCT($F34:$M34,$F$13:$M$13) -> 1313.3928 | X34: =SUMPRODUCT($F34:$M34,$F$14:$M$14) -> 146.23934
A35: M20 | B35: MP-42 | C35: Válvula HZ M-22 con tubo de pesca (1 kg) | D35: u | F35: 1 | N35: =SUMPRODUCT($F35:$M35,$F$4:$M$4) -> 4178.7365 | O35: =SUMPRODUCT($F35:$M35,$F$5:$M$5) -> 5997.304 | P35: =SUMPRODUCT($F35:$M35,$F$6:$M$6) -> 6851.7478 | Q35: =SUMPRODUCT($F35:$M35,$F$7:$M$7) -> 8467.1355 | R35: =SUMPRODUCT($F35:$M35,$F$8:$M$8) -> 12680.633 | S35: =SUMPRODUCT($F35:$M35,$F$9:$M$9) -> 15620.253 | T35: =SUMPRODUCT($F35:$M35,$F$10:$M$10) -> 20332.553 | U35: =SUMPRODUCT($F35:$M35,$F$11:$M$11) -> 25132.078 | V35: =SUMPRODUCT($F35:$M35,$F$12:$M$12) -> 28573.336 | W35: =SUMPRODUCT($F35:$M35,$F$13:$M$13) -> 32072.639 | X35: =SUMPRODUCT($F35:$M35,$F$14:$M$14) -> 3848.7167
A36: M21 | B36: MP-43 | C36: Válvula HZ M-30 con resorte, sin tubo pescante (2,5 a 10 kg) | D36: u | G36: 1 | H36: 1 | I36: 1 | N36: =SUMPRODUCT($F36:$M36,$F$4:$M$4) -> 3115.3427 | O36: =SUMPRODUCT($F36:$M36,$F$5:$M$5) -> 6376.7775 | P36: =SUMPRODUCT($F36:$M36,$F$6:$M$6) -> 8448.5188 | Q36: =SUMPRODUCT($F36:$M36,$F$7:$M$7) -> 12282.617 | R36: =SUMPRODUCT($F36:$M36,$F$8:$M$8) -> 17413.324 | S36: =SUMPRODUCT($F36:$M36,$F$9:$M$9) -> 22866.148 | T36: =SUMPRODUCT($F36:$M36,$F$10:$M$10) -> 27867.153 | U36: =SUMPRODUCT($F36:$M36,$F$11:$M$11) -> 32504.263 | V36: =SUMPRODUCT($F36:$M36,$F$12:$M$12) -> 36423.181 | W36: =SUMPRODUCT($F36:$M36,$F$13:$M$13) -> 41696.506 | X36: =SUMPRODUCT($F36:$M36,$F$14:$M$14) -> 4586.6157
A37: M22 | B37: MP-45 | C37: Manómetro 1,4 MPa | D37: u | F37: 1 | G37: 1 | H37: 1 | I37: 1 | N37: =SUMPRODUCT($F37:$M37,$F$4:$M$4) -> 7294.0792 | O37: =SUMPRODUCT($F37:$M37,$F$5:$M$5) -> 12374.081 | P37: =SUMPRODUCT($F37:$M37,$F$6:$M$6) -> 15300.267 | Q37: =SUMPRODUCT($F37:$M37,$F$7:$M$7) -> 20749.753 | R37: =SUMPRODUCT($F37:$M37,$F$8:$M$8) -> 30093.957 | S37: =SUMPRODUCT($F37:$M37,$F$9:$M$9) -> 38486.401 | T37: =SUMPRODUCT($F37:$M37,$F$10:$M$10) -> 48199.706 | U37: =SUMPRODUCT($F37:$M37,$F$11:$M$11) -> 57636.341 | V37: =SUMPRODUCT($F37:$M37,$F$12:$M$12) -> 64996.517 | W37: =SUMPRODUCT($F37:$M37,$F$13:$M$13) -> 73769.145 | X37: =SUMPRODUCT($F37:$M37,$F$14:$M$14) -> 8435.3324
A38: M23 | B38: MP-46/ABC2.5 | C38: Tubo pescante de PVC rígido, ABC 2,5 kg | D38: u | G38: 1 | N38: =SUMPRODUCT($F38:$M38,$F$4:$M$4) -> 295.03036 | O38: =SUMPRODUCT($F38:$M38,$F$5:$M$5) -> 709.72745 | P38: =SUMPRODUCT($F38:$M38,$F$6:$M$6) -> 986.86806 | Q38: =SUMPRODUCT($F38:$M38,$F$7:$M$7) -> 1500.6382 | R38: =SUMPRODUCT($F38:$M38,$F$8:$M$8) -> 2312.6277 | S38: =SUMPRODUCT($F38:$M38,$F$9:$M$9) -> 3252.8699 | T38: =SUMPRODUCT($F38:$M38,$F$10:$M$10) -> 4102.3155 | U38: =SUMPRODUCT($F38:$M38,$F$11:$M$11) -> 5104.3066 | V38: =SUMPRODUCT($F38:$M38,$F$12:$M$12) -> 6195.1862 | W38: =SUMPRODUCT($F38:$M38,$F$13:$M$13) -> 7424.8584 | X38: =SUMPRODUCT($F38:$M38,$F$14:$M$14) -> 816.73443
A39: M24 | B39: MP-46/ABC5 | C39: Tubo pescante de PVC rígido, ABC 5 kg | D39: u | H39: 1 | N39: =SUMPRODUCT($F39:$M39,$F$4:$M$4) -> 2727.9036 | O39: =SUMPRODUCT($F39:$M39,$F$5:$M$5) -> 5488.9106 | P39: =SUMPRODUCT($F39:$M39,$F$6:$M$6) -> 7206.5855 | Q39: =SUMPRODUCT($F39:$M39,$F$7:$M$7) -> 10420.908 | R39: =SUMPRODUCT($F39:$M39,$F$8:$M$8) -> 14495.071 | S39: =SUMPRODUCT($F39:$M39,$F$9:$M$9) -> 18737.061 | T39: =SUMPRODUCT($F39:$M39,$F$10:$M$10) -> 22634.482 | U39: =SUMPRODUCT($F39:$M39,$F$11:$M$11) -> 26002.338 | V39: =SUMPRODUCT($F39:$M39,$F$12:$M$12) -> 28613.4 | W39: =SUMPRODUCT($F39:$M39,$F$13:$M$13) -> 32428.771 | X39: =SUMPRODUCT($F39:$M39,$F$14:$M$14) -> 3567.1648
