Workbook

Sheet Indexado Dim Técnico
A1: PRODUCCION DE MATAFUEGOS TERMINADOS
A2: Demanda | B2: 2026 | C2: 2027 | D2: 2028 | E2: 2029 | F2: 2030 | G2: 2031 | H2: 2032 | I2: 2033 | J2: 2034 | K2: 2035 | L2: %
A3: ABC 1 kg | B3: 4178.7365 | C3: 5997.304 | D3: 6851.7478 | E3: 8467.1355 | F3: 12680.633 | G3: 15620.253 | H3: 20332.553 | I3: 25132.078 | J3: 28573.336 | K3: 32072.639 | L3: 0.43398757
A4: ABC 2,5 kg | B4: 295.03036 | C4: 709.72745 | D4: 986.86806 | E4: 1500.6382 | F4: 2312.6277 | G4: 3252.8699 | H4: 4102.3155 | I4: 5104.3066 | J4: 6195.1862 | K4: 7424.8584 | L4: 0.1004687
A5: ABC 5 kg | B5: 2255.773 | C5: 3846.9789 | D5: 5093.5376 | E5: 6823.1153 | F5: 10819.307 | G5: 14605.964 | H5: 18877.76 | I5: 23368.186 | J5: 26967.725 | K5: 30750.779 | L5: 0.41610096
A6: ABC 10 kg | B6: 91.833182 | C6: 177.2473 | D6: 252.97878 | E6: 358.02049 | F6: 602.71815 | G6: 872.60503 | H6: 1127.1605 | I6: 1395.4448 | J6: 1612.3501 | K6: 1840.8481 | L6: 0.024909244
A7: ABC 25 kg s/ruedas | B7: 34.051791 | C7: 58.462147 | D7: 75.20854 | E7: 100.52985 | F7: 155.876 | G7: 211.93448 | H7: 272.66823 | I7: 337.84867 | J7: 393.62742 | K7: 453.27053 | L7: 0.0061333829
A8: ABC 50 kg s/ruedas | B8: 74.913941 | C8: 128.61672 | D8: 165.45879 | E8: 221.16568 | F8: 342.92721 | G8: 466.25586 | H8: 599.87011 | I8: 743.26708 | J8: 865.98031 | K8: 997.19517 | L8: 0.013493442
A9: ABC 70 kg s/ruedas | B9: 16.34486 | C9: 28.061831 | D9: 36.100099 | E9: 48.254329 | F9: 74.820482 | G9: 101.72855 | H9: 130.88075 | I9: 162.16736 | J9: 188.94116 | K9: 217.56986 | L9: 0.0029440238
A10: ABC 100 kg s/ruedas | B10: 10.896573 | C10: 18.707887 | D10: 24.066733 | E10: 32.169553 | F10: 49.880321 | G10: 67.819034 | H10: 87.253835 | I10: 108.11157 | J10: 125.96077 | K10: 145.04657 | L10: 0.0019626825
A11: TOTAL | B11: 6957.5803 | C11: 10965.106 | D11: 13485.966 | E11: 17551.029 | F11: 27038.79 | G11: 35199.43 | H11: 45530.462 | I11: 56351.411 | J11: 64923.107 | K11: 73902.207 | L11: 1
A13: PRODUCCION DE CILINDROS
A14: Demanda | B14: 2026 | C14: 2027 | D14: 2028 | E14: 2029 | F14: 2030 | G14: 2031 | H14: 2032 | I14: 2033 | J14: 2034 | K14: 2035 | L14: %
A15: Cilindros ABC 1 kg | B15: 0 | C15: 0 | D15: 7662.4 | E15: 26694.8 | F15: 49434.8 | G15: 71680.2 | H15: 101340.6 | I15: 131001 | J15: 146819.8 | K15: 170548 | L15: 0.79908167
A16: Cilindros ABC 2,5 kg | B16: 0 | C16: 0 | D16: 299.6 | E16: 1043.8 | F16: 1933 | G16: 2803 | H16: 3963 | I16: 5123 | J16: 5741.4 | K16: 6669 | L16: 0.031246779
A17: Cilindros ABC 5 kg | B17: 0 | C17: 0 | D17: 1478.8 | E17: 5152 | F17: 9540.8 | G17: 13834.2 | H17: 19558.6 | I17: 25283 | J17: 28335.8 | K17: 32915 | L17: 0.15421918
A18: Cilindros ABC 10 kg | B18: 0 | C18: 0 | D18: 90.4 | E18: 315 | F18: 583.4 | G18: 845.8 | H18: 1195.4 | I18: 1545 | J18: 1731.4 | K18: 2011 | L18: 0.009422293
A19: Cilindros ABC 25 kg | B19: 0 | C19: 0 | D19: 14.4 | E19: 50.2 | F19: 93 | G19: 135 | H19: 191 | I19: 247 | J19: 277 | K19: 322 | L19: 0.0015086914
A20: Cilindros ABC 50 kg | B20: 0 | C20: 0 | D20: 31.8 | E20: 110.8 | F20: 205.2 | G20: 297.6 | H20: 420.8 | I20: 544 | J20: 609.6 | K20: 708 | L20: 0.0033172469
A21: Cilindros ABC 70 kg | B21: 0 | C21: 0 | D21: 7 | E21: 24.4 | F21: 45.2 | G21: 65.4 | H21: 92.2 | I21: 119 | J21: 133.4 | K21: 155 | L21: 0.00072623343
A22: Cilindros ABC 100 kg | B22: 0 | C22: 0 | D22: 4.6 | E22: 16 | F22: 29.6 | G22: 42.8 | H22: 60.4 | I22: 78 | J22: 87.6 | K22: 102 | L22: 0.00047790845
A23: Cilindros Total | B23: 0 | C23: 0 | D23: 9589 | E23: 33407 | F23: 61865 | G23: 89704 | H23: 126822 | I23: 163940 | J23: 183736 | K23: 213430 | L23: 1
A25: RECARGAS
A26: Demanda | B26: 2026 | C26: 2027 | D26: 2028 | E26: 2029 | F26: 2030 | G26: 2031 | H26: 2032 | I26: 2033 | J26: 2034 | K26: 2035 | L26: %
A27: ABC 1 kg | B27: 3477.4821 | C27: 16970.586 | D27: 30546.09 | E27: 56048.311 | F27: 84270.226 | G27: 117407.82 | H27: 147610.64 | I27: 171404.36 | J27: 183690.57 | K27: 196282.69 | L27: 0.52777261
A28: ABC 2,5 kg | B28: 329.99667 | C28: 1287.414 | D28: 2947.1692 | E28: 5426.0433 | F28: 7850.8758 | G28: 10423.944 | H28: 12809.896 | I28: 14263.068 | J28: 15432.87 | K28: 16620.761 | L28: 0.044690555
A29: ABC 5 kg | B29: 1950.3941 | C29: 7852.6185 | D29: 17775.857 | E29: 33605.568 | F29: 48407.572 | G29: 64323.043 | H29: 78721.1 | I29: 87237.212 | J29: 94103.668 | K29: 101095.18 | L29: 0.27182868
A30: ABC 10 kg | B30: 118.34363 | C30: 437.71658 | D30: 1024.9748 | E30: 1960.4099 | F30: 2844.9768 | G30: 3810.3906 | H30: 4663.6781 | I30: 5164.5146 | J30: 5571.5443 | K30: 5985.9509 | L30: 0.01609526
A31: Agua 10 l | B31: 159.30874 | C31: 643.42354 | D31: 1474.3627 | E31: 2766.4512 | F31: 3991.4652 | G31: 5335.7558 | H31: 6538.9589 | I31: 7269.8197 | J31: 7855.4414 | K31: 8450.8141 | L31: 0.022722881
A32: AFFF 10 l | B32: 22.758391 | C32: 161.31575 | D32: 316.60728 | E32: 527.39462 | F32: 743.78895 | G32: 962.87434 | H32: 1194.9422 | I32: 1351.6172 | J32: 1477.5489 | K32: 1604.4414 | L32: 0.0043140851
A33: AFFF 50 l s/ruedas | B33: 11.379195 | C33: 83.22352 | D33: 164.46383 | E33: 281.34115 | F33: 398.90251 | G33: 514.52728 | H33: 629.06551 | I33: 711.17802 | J33: 773.41098 | K33: 836.35081 | L33: 0.0022488129
A34: BC 5 kg | B34: 6.8275173 | C34: 47.073112 | D34: 88.889676 | E34: 159.50249 | F34: 219.7962 | G34: 291.86985 | H34: 368.84417 | I34: 408.40895 | J34: 445.78194 | K34: 483.4792 | L34: 0.0012999979
A35: Sales K 6 l | B35: 81.930207 | C35: 335.39886 | D35: 746.59835 | E35: 1358.8998 | F35: 1961.1255 | G35: 2598.5414 | H35: 3197.2635 | I35: 3578.5395 | J35: 3870.748 | K35: 4167.5596 | L35: 0.011205898
A36: CO₂ 2 kg | B36: 450.61614 | C36: 1697.1815 | D36: 3955.1969 | E36: 7561.2603 | F36: 10920.145 | G36: 14514.885 | H36: 17746.499 | I36: 19617.205 | J36: 21161.806 | K36: 22734.502 | L36: 0.061129421
A37: CO₂ 5 kg | B37: 125.17115 | C37: 643.63037 | D37: 1375.6267 | E37: 2460.2843 | F37: 3545.2577 | G37: 4723.4618 | H37: 5853.9052 | I37: 6608.4599 | J37: 7185.7084 | K37: 7769.5771 | L37: 0.020891144
A38: HCFC/HFC 5 kg | B38: 18.206713 | C38: 112.07512 | D38: 230.85404 | E38: 400.71533 | F38: 574.50779 | G38: 754.34562 | H38: 944.84884 | I38: 1072.2347 | J38: 1171.6958 | K38: 1271.9411 | L38: 0.0034200452
... A44: Recargas Total | B44: 6829.7931 | C44: 30662.681 | D44: 61483.058 | E44: 114050.8 | F44: 167870.4 | G44: 228490.11 | H44: 283777.78 | I44: 322612.24 | J44: 347003.72 | K44: 371907.69 | L44: 1
A46: MATAFUEGOS TERCIARIZADOS VENDIDOS
A47: Demanda | B47: 2026 | C47: 2027 | D47: 2028 | E47: 2029 | F47: 2030 | G47: 2031 | H47: 2032 | I47: 2033 | J47: 2034 | K47: 2035 | L47: %
A48: Agua 10 l | B48: 175.60796 | C48: 320.39061 | D48: 436.58878 | E48: 602.28658 | F48: 974.75938 | G48: 1370.0813 | H48: 1767.1834 | I48: 2188.4667 | J48: 2536.3433 | K48: 2904.8974 | L48: 0.16128875
...

Sheet Reservas y Sustitutos
A1: Reserva del cliente (IRAM 3517-2:2020 5.3) y extintores sustitutos (9.4.5) — FLAMA
A2: 5.3: «Esta dotación no debe ser menor al 10% de la dotación mínima requerida» · «Si fuera heterogénea, la de reserva debe ser de extintores tipo ABC de 5 kg» · «Las propiedades que tengan menos de 5 extintores pueden no tener dotación de reserva».
A3: 9.4.5: «Los extintores fuera de servicio por mantenimiento o recarga deben ser sustituidos por equipos sustitutos que tengan igual clasificación y por lo menos igual capacidad» · se cubre «con extintores de reserva (ver 5.3) o requiriendo al prestador responsable del servicio su provisión temporaria».
A5: PARÁMETROS (celdas amarillas: completar con datos de planta)
A6: Días hábiles por año (DH) | B6: 260 | E6: menor a 5 matafuegos sin reserva obligatoria | L6: Dato de planta
A7: Ciclo de recarga en planta (días: retiro + recarga + devolución) | B7: 3 | L7: Dato de planta (dimensionamiento técnico de la línea de recarga)
A8: Reserva mínima de la norma | B8: 0.1 | L8: IRAM 3517-2:2020 5.3 (10 %)
A9: Vida útil extintor (años) | B9: 20 | L9: Res. 349/07 PBA art. 26
A10: Vida útil CO₂ (años) | B10: 30 | L10: Res. 349/07 PBA art. 26
A12: Año | B12: 2026 | C12: 2027 | D12: 2028 | E12: 2029 | F12: 2030 | G12: 2031 | H12: 2032 | I12: 2033 | J12: 2034 | K12: 2035
A14: A. PARQUE INSTALADO POR SEGMENTO
A15: Supermercados | B15: 39725 | C15: 39940 | D15: 40154 | E15: 40369 | F15: 40593 | G15: 40811 | H15: 41042 | I15: 41258 | J15: 41486 | K15: 41707
A16: Salud | B16: 3393423 | C16: 3525669 | D16: 3663072 | E16: 3805830 | F16: 3954150 | G16: 4108248 | H16: 4268358 | I16: 4434705 | J16: 4607532 | K16: 4787100
A17: Educación | B17: 703633 | C17: 704099 | D17: 704578 | E17: 705077 | F17: 705582 | G17: 706103 | H17: 706636 | I17: 707181 | J17: 707746 | K17: 708321
A18: Automotor | B18: 12094003 | C18: 12355237 | D18: 12622105 | E18: 12894744 | F18: 13173268 | G18: 13457809 | H18: 13748498 | I18: 14045462 | J18: 14348845 | K18: 14658783
A19: Industrias / almacenes | B19: 480202 | C19: 491487 | D19: 503046 | E19: 514886 | F19: 527016 | G19: 539450 | H19: 552192 | I19: 565246 | J19: 578626 | K19: 592334
A20: Edificios | B20: 18972632 | C20: 19153968 | D20: 19337280 | E20: 19522464 | F20: 19709624 | G20: 19898792 | H20: 20089920 | I20: 20283056 | J20: 20478312 | K20: 20675608
A21: Hoteles | B21: 327007 | C21: 330622 | D21: 334864 | E21: 339841 | F21: 345690 | G21: 352567 | H21: 360658 | I21: 370183 | J21: 381402 | K21: 394627
A22: Parque total | B22: 36010625 | C22: 36601022 | D22: 37205099 | E22: 37823211 | F22: 38455923 | G22: 39103780 | H22: 39767304 | I22: 40447091 | J22: 41143949 | K22: 41858480
A23: Parque con reserva obligatoria (sin Automotor) | B23: 23916622 | C23: 24245785 | D23: 24582994 | E23: 24928467 | F23: 25282655 | G23: 25645971 | H23: 26018806 | I23: 26401629 | J23: 26795104 | K23: 27199697
A24: % del parque con reserva obligatoria | B24: 0.66415459 | C24: 0.66243464 | D24: 0.6607426 | E24: 0.65907855 | F24: 0.65744502 | G24: 0.65584378 | H24: 0.65427634 | I24: 0.65274482 | J24: 0.65125261 | K24: 0.64980135 | L24: 5.3: propiedades con < 5 extintores exentas; en el Excel el único segmento así es Automotor
A26: B. RESERVA DEL CLIENTE (5.3)
A27: Recargas del año (mantenimiento anual) | B27: 6829.7931 | C27: 30662.681 | D27: 61483.058 | E27: 114050.8 | F27: 167870.4 | G27: 228490.11 | H27: 283777.78 | I27: 322612.24 | J27: 347003.72 | K27: 371907.69 | L27: Indexado Dim Técnico fila 44
A28: Parque de reserva obligatoria | B28: 4536.0385 | C28: 20312.022 | D28: 40624.476 | E28: 75168.433 | F28: 110365.56 | G28: 149853.82 | H28: 185669.09 | I28: 210583.47 | J28: 225987.07 | K28: 241666.12
A29: Reserva requerida en clientes | B29: 454 | C29: 2032 | D29: 4063 | E29: 7517 | F29: 11037 | G29: 14986 | H29: 18567 | I29: 21059 | J29: 22599 | K29: 24167 | L29: 5.3: ≥ 10 % de la dotación
A30: VENTA de reserva | B30: 454 | C30: 1578 | D30: 2031 | E30: 3454 | F30: 3520 | G30: 3949 | H30: 3581 | I30: 2492 | J30: 1540 | K30: 1568
A32: C. EXTINTORES SUSTITUTOS (9.4.5) — STOCK
A33: Fracción de retiros cubierta por la reserva del cliente | B33: 0.066473463 | C33: 0.066269483 | D33: 0.066083245 | E33: 0.065909229 | F33: 0.065747149 | G33: 0.065587084 | H33: 0.065427955 | I33: 0.065276507 | J33: 0.065126104 | K33: 0.064981179 | L33: La reserva (10 %) cubre como máximo esa fracción de lo que se retira
A34: Necesidad por tipo = recargas / DH × ciclo × (1 − cobertura)
A35: ABC 1 kg | B35: 37.45756 | C35: 182.83793 | D35: 329.16352 | E35: 604.08704 | F35: 908.4196 | G35: 1265.8545 | H35: 1591.7628 | I35: 1848.6425 | J35: 1981.4713 | K35: 2117.6309
A36: ABC 2,5 kg | B36: 3.5545459 | C36: 13.870359 | D36: 31.758585 | E36: 58.481734 | F36: 84.63119 | G36: 112.3877 | H36: 138.13581 | I36: 153.83106 | J36: 166.47447 | K36: 179.31605
A37: ABC 5 kg | B37: 21.008592 | C37: 84.602649 | D37: 191.55197 | E37: 362.19982 | F37: 521.82591 | G37: 693.51095 | H37: 848.89084 | I37: 940.87698 | J37: 1015.0969 | K37: 1090.6834
A38: ABC 10 kg | B38: 1.2747337 | C38: 4.7158768 | D38: 11.04509 | E38: 21.12924 | F38: 30.668397 | G38: 41.082441 | H38: 50.290883 | I38: 55.70069 | J38: 60.100285 | K38: 64.580501
A39: Agua 10 l | B39: 1.7159877 | C39: 6.9321253 | D39: 15.887678 | E39: 29.816729 | F39: 43.027359 | G39: 57.528451 | H39: 70.513017 | I39: 78.406976 | J39: 84.736697 | K39: 91.173118
A40: AFFF 10 l | B40: 0.2451411 | C40: 1.7379858 | D40: 3.4117482 | E40: 5.6842436 | F40: 8.0179263 | G40: 10.38141 | H40: 12.885687 | I40: 14.577558 | J40: 15.938329 | K40: 17.309803
A41: AFFF 50 l s/ruedas | B41: 0.12257055 | C41: 0.89663469 | D41: 1.7722561 | E41: 3.0322865 | F41: 4.3001055 | G41: 5.5474724 | H41: 6.7835427 | I41: 7.6702478 | J41: 8.3427893 | K41: 9.0231201
A42: BC 5 kg | B42: 0.073542329 | C42: 0.50715694 | D42: 0.95787182 | E42: 1.7191131 | F42: 2.369368 | G42: 3.1468495 | H42: 3.9774398 | I42: 4.4048013 | J42: 4.8086527 | K42: 5.2161018
A43: Sales K 6 l | B43: 0.88250795 | C43: 3.6135248 | D43: 8.0453159 | E43: 14.646182 | F43: 21.14062 | G43: 28.016661 | H43: 34.477766 | I43: 38.595518 | J43: 41.753784 | K43: 44.962462
A44: CO₂ 2 kg | B44: 4.8537937 | C44: 18.285117 | D44: 42.621053 | E44: 81.49504 | F44: 117.71742 | G44: 156.49496 | H44: 191.36979 | I44: 211.57688 | J44: 228.27254 | K44: 245.27523
A45: CO₂ 5 kg | B45: 1.348276 | C45: 6.9343537 | D45: 14.823702 | E45: 26.516871 | F45: 38.217313 | G45: 50.926889 | H45: 63.125725 | I45: 71.274032 | J45: 77.512283 | K45: 83.823471
...

Sheet Parametros
A1: Parámetros del MRP
A3: Fracción de recargas con agente 100 % nuevo (equipo accionado) | B3: 1 | C3: IRAM 3517-2:2020 9.9.1.4: el polvo de un extintor accionado no se reutiliza. 100 % = cota superior. El resto de las recargas usa el caso B del BOM (recuperado + reposición de mermas). Ajustar con el dato real de la planta de recargas.
A6: Año | B6: ='Indexado Dim Técnico'!B26 | C6: ='Indexado Dim Técnico'!C26 | D6: ='Indexado Dim Técnico'!D26 | E6: ='Indexado Dim Técnico'!E26 | F6: ='Indexado Dim Técnico'!F26 | G6: ='Indexado Dim Técnico'!G26 | H6: ='Indexado Dim Técnico'!H26 | I6: ='Indexado Dim Técnico'!I26 | ... K6: ='Indexado Dim Técnico'!K26
A7: % destino CABA — unidades nuevas (zonal de revendidos, filas 79-82) | B7: ='Indexado Dim Técnico'!L79+'Indexado Dim Técnico'!L80+'Indexado Dim Técnico'!L81+'Indexado Dim Técnico'!L82 | C7: ='Indexado Dim Técnico'!M79+'Indexado Dim Técnico'!M80+'Indexado Dim Técnico'!M81+'Indexado Dim Técnico'!M82 | D7: ='Indexado Dim Técnico'!N79+'Indexado Dim Técnico'!N80+'Indexado Dim Técnico'!N81+'Indexado Dim Técnico'!N82 | E7: ='Indexado Dim Técnico'!O79+'Indexado Dim Técnico'!O80+'Indexado Dim Técnico'!O81+'Indexado Dim Técnico'!O82 | F7: ='Indexado Dim Técnico'!P79+'Indexado Dim Técnico'!P80+'Indexado Dim Técnico'!P81+'Indexado Dim Técnico'!P82 | G7: ='Indexado Dim Técnico'!Q79+'Indexado Dim Técnico'!Q80+'Indexado Dim Técnico'!Q81+'Indexado Dim Técnico'!Q82 | H7: ='Indexado Dim Técnico'!R79+'Indexado Dim Técnico'!R80+'Indexado Dim Técnico'!R81+'Indexado Dim Técnico'!R82 | I7: ='Indexado Dim Técnico'!S79+'Indexado Dim Técnico'!S80+'Indexado Dim Técnico'!S81+'Indexado Dim Técnico'!S82 | ... K7: ='Indexado Dim Técnico'!U79+'Indexado Dim Técnico'!U80+'Indexado Dim Técnico'!U81+'Indexado Dim Técnico'!U82
A8: % destino CABA — recargas (zonal de recargas, filas 61-64) | B8: ='Indexado Dim Técnico'!L61+'Indexado Dim Técnico'!L62+'Indexado Dim Técnico'!L63+'Indexado Dim Técnico'!L64 | C8: ='Indexado Dim Técnico'!M61+'Indexado Dim Técnico'!M62+'Indexado Dim Técnico'!M63+'Indexado Dim Técnico'!M64 | D8: ='Indexado Dim Técnico'!N61+'Indexado Dim Técnico'!N62+'Indexado Dim Técnico'!N63+'Indexado Dim Técnico'!N64 | E8: ='Indexado Dim Técnico'!O61+'Indexado Dim Técnico'!O62+'Indexado Dim Técnico'!O63+'Indexado Dim Técnico'!O64 | F8: ='Indexado Dim Técnico'!P61+'Indexado Dim Técnico'!P62+'Indexado Dim Técnico'!P63+'Indexado Dim Técnico'!P64 | G8: ='Indexado Dim Técnico'!Q61+'Indexado Dim Técnico'!Q62+'Indexado Dim Técnico'!Q63+'Indexado Dim Técnico'!Q64 | H8: ='Indexado Dim Técnico'!R61+'Indexado Dim Técnico'!R62+'Indexado Dim Técnico'!R63+'Indexado Dim Técnico'!R64 | I8: ='Indexado Dim Técnico'!S61+'Indexado Dim Técnico'!S62+'Indexado Dim Técnico'!S63+'Indexado Dim Técnico'!S64 | ... K8: ='Indexado Dim Técnico'!U61+'Indexado Dim Técnico'!U62+'Indexado Dim Técnico'!U63+'Indexado Dim Técnico'!U64
A9: % recargas planta COMERCIAL (zonas de Indexado V60: CABA N/E/O, PBA Norte 1°-3°) | B9: ='Indexado Dim Técnico'!L61+'Indexado Dim Técnico'!L62+'Indexado Dim Técnico'!L64+'Indexado Dim Técnico'!L68+'Indexado Dim Técnico'!L69+'Indexado Dim Técnico'!L70 | C9: ='Indexado Dim Técnico'!M61+'Indexado Dim Técnico'!M62+'Indexado Dim Técnico'!M64+'Indexado Dim Técnico'!M68+'Indexado Dim Técnico'!M69+'Indexado Dim Técnico'!M70 | D9: ='Indexado Dim Técnico'!N61+'Indexado Dim Técnico'!N62+'Indexado Dim Técnico'!N64+'Indexado Dim Técnico'!N68+'Indexado Dim Técnico'!N69+'Indexado Dim Técnico'!N70 | E9: ='Indexado Dim Técnico'!O61+'Indexado Dim Técnico'!O62+'Indexado Dim Técnico'!O64+'Indexado Dim Técnico'!O68+'Indexado Dim Técnico'!O69+'Indexado Dim Técnico'!O70 | F9: ='Indexado Dim Técnico'!P61+'Indexado Dim Técnico'!P62+'Indexado Dim Técnico'!P64+'Indexado Dim Técnico'!P68+'Indexado Dim Técnico'!P69+'Indexado Dim Técnico'!P70 | G9: ='Indexado Dim Técnico'!Q61+'Indexado Dim Técnico'!Q62+'Indexado Dim Técnico'!Q64+'Indexado Dim Técnico'!Q68+'Indexado Dim Técnico'!Q69+'Indexado Dim Técnico'!Q70 | H9: ='Indexado Dim Técnico'!R61+'Indexado Dim Técnico'!R62+'Indexado Dim Técnico'!R64+'Indexado Dim Técnico'!R68+'Indexado Dim Técnico'!R69+'Indexado Dim Técnico'!R70 | I9: ='Indexado Dim Técnico'!S61+'Indexado Dim Técnico'!S62+'Indexado Dim Técnico'!S64+'Indexado Dim Técnico'!S68+'Indexado Dim Técnico'!S69+'Indexado Dim Técnico'!S70 | ... K9: ='Indexado Dim Técnico'!U61+'Indexado Dim Técnico'!U62+'Indexado Dim Técnico'!U64+'Indexado Dim Técnico'!U68+'Indexado Dim Técnico'!U69+'Indexado Dim Técnico'!U70
A10: % recargas planta INDUSTRIAL (CABA Sur, PBA Sur 1°-3°, PBA Oeste 1°-3°, Interior) | B10: =1-B9 | C10: =1-C9 | D10: =1-D9 | E10: =1-E9 | F10: =1-F9 | G10: =1-G9 | H10: =1-H9 | I10: =1-I9 | ... K10: =1-K9
A12: Destino: lo que exige una norma de PBA (oblea Res. 522/07, tarjeta DPS Res. 349/07) se aplica a la proporción PBA; lo de CABA (tarjeta AGC, Ord. 40.473) a la proporción CABA. Para unidades nuevas se usa la distribución zonal de revendidos (única de unidades nuevas en el Indexado).

Sheet Demanda
A1: Demanda por producto (unidades/año) — fórmulas sobre las dos primeras hojas
A3: Producto | B3: ='Indexado Dim Técnico'!B26 | C3: ='Indexado Dim Técnico'!C26 | D3: ='Indexado Dim Técnico'!D26 | E3: ='Indexado Dim Técnico'!E26 | F3: ='Indexado Dim Técnico'!F26 | G3: ='Indexado Dim Técnico'!G26 | H3: ='Indexado Dim Técnico'!H26 | I3: ='Indexado Dim Técnico'!I26 | ... K3: ='Indexado Dim Técnico'!K26 | L3: Origen
A5: MATAFUEGOS FABRICADOS (unidades nuevas + venta de reserva + alta de sustitutos)
A6: FL_MAT_ABC_1kg | B6: ='Indexado Dim Técnico'!B3 | C6: ='Indexado Dim Técnico'!C3 | D6: ='Indexado Dim Técnico'!D3 | E6: ='Indexado Dim Técnico'!E3 | F6: ='Indexado Dim Técnico'!F3 | G6: ='Indexado Dim Técnico'!G3 | H6: ='Indexado Dim Técnico'!H3 | I6: ='Indexado Dim Técnico'!I3 | ... K6: ='Indexado Dim Técnico'!K3 | L6: Indexado fila 3
A7: FL_MAT_ABC_2.5kg | B7: ='Indexado Dim Técnico'!B4 | C7: ='Indexado Dim Técnico'!C4 | D7: ='Indexado Dim Técnico'!D4 | E7: ='Indexado Dim Técnico'!E4 | F7: ='Indexado Dim Técnico'!F4 | G7: ='Indexado Dim Técnico'!G4 | H7: ='Indexado Dim Técnico'!H4 | I7: ='Indexado Dim Técnico'!I4 | ... K7: ='Indexado Dim Técnico'!K4 | L7: Indexado fila 4
A8: FL_MAT_ABC_5kg | B8: ='Indexado Dim Técnico'!B5+'Reservas y Sustitutos'!B30+'Reservas y Sustitutos'!B69 | C8: ='Indexado Dim Técnico'!C5+'Reservas y Sustitutos'!C30+'Reservas y Sustitutos'!C69 | D8: ='Indexado Dim Técnico'!D5+'Reservas y Sustitutos'!D30+'Reservas y Sustitutos'!D69 | E8: ='Indexado Dim Técnico'!E5+'Reservas y Sustitutos'!E30+'Reservas y Sustitutos'!E69 | F8: ='Indexado Dim Técnico'!F5+'Reservas y Sustitutos'!F30+'Reservas y Sustitutos'!F69 | G8: ='Indexado Dim Técnico'!G5+'Reservas y Sustitutos'!G30+'Reservas y Sustitutos'!G69 | H8: ='Indexado Dim Técnico'!H5+'Reservas y Sustitutos'!H30+'Reservas y Sustitutos'!H69 | I8: ='Indexado Dim Técnico'!I5+'Reservas y Sustitutos'!I30+'Reservas y Sustitutos'!I69 | ... K8: ='Indexado Dim Técnico'!K5+'Reservas y Sustitutos'!K30+'Reservas y Sustitutos'!K69 | L8: Indexado fila 5 + Reservas fila 30 + Reservas fila 69
A9: FL_MAT_ABC_10kg | B9: ='Indexado Dim Técnico'!B6+'Reservas y Sustitutos'!B70 | C9: ='Indexado Dim Técnico'!C6+'Reservas y Sustitutos'!C70 | D9: ='Indexado Dim Técnico'!D6+'Reservas y Sustitutos'!D70 | E9: ='Indexado Dim Técnico'!E6+'Reservas y Sustitutos'!E70 | F9: ='Indexado Dim Técnico'!F6+'Reservas y Sustitutos'!F70 | G9: ='Indexado Dim Técnico'!G6+'Reservas y Sustitutos'!G70 | H9: ='Indexado Dim Técnico'!H6+'Reservas y Sustitutos'!H70 | I9: ='Indexado Dim Técnico'!I6+'Reservas y Sustitutos'!I70 | ... K9: ='Indexado Dim Técnico'!K6+'Reservas y Sustitutos'!K70 | L9: Indexado fila 6 + Reservas fila 70
A10: FL_MAT_ABC_25kg | B10: ='Indexado Dim Técnico'!B7 | C10: ='Indexado Dim Técnico'!C7 | D10: ='Indexado Dim Técnico'!D7 | E10: ='Indexado Dim Técnico'!E7 | F10: ='Indexado Dim Técnico'!F7 | G10: ='Indexado Dim Técnico'!G7 | H10: ='Indexado Dim Técnico'!H7 | I10: ='Indexado Dim Técnico'!I7 | ... K10: ='Indexado Dim Técnico'!K7 | L10: Indexado fila 7
A11: FL_MAT_ABC_50kg | B11: ='Indexado Dim Técnico'!B8+'Reservas y Sustitutos'!B79 | C11: ='Indexado Dim Técnico'!C8+'Reservas y Sustitutos'!C79 | D11: ='Indexado Dim Técnico'!D8+'Reservas y Sustitutos'!D79 | E11: ='Indexado Dim Técnico'!E8+'Reservas y Sustitutos'!E79 | F11: ='Indexado Dim Técnico'!F8+'Reservas y Sustitutos'!F79 | G11: ='Indexado Dim Técnico'!G8+'Reservas y Sustitutos'!G79 | H11: ='Indexado Dim Técnico'!H8+'Reservas y Sustitutos'!H79 | I11: ='Indexado Dim Técnico'!I8+'Reservas y Sustitutos'!I79 | ... K11: ='Indexado Dim Técnico'!K8+'Reservas y Sustitutos'!K79 | L11: Indexado fila 8 + Reservas fila 79
A12: FL_MAT_ABC_70kg | B12: ='Indexado Dim Técnico'!B9 | C12: ='Indexado Dim Técnico'!C9 | D12: ='Indexado Dim Técnico'!D9 | E12: ='Indexado Dim Técnico'!E9 | F12: ='Indexado Dim Técnico'!F9 | G12: ='Indexado Dim Técnico'!G9 | H12: ='Indexado Dim Técnico'!H9 | I12: ='Indexado Dim Técnico'!I9 | ... K12: ='Indexado Dim Técnico'!K9 | L12: Indexado fila 9
A13: FL_MAT_ABC_100kg | B13: ='Indexado Dim Técnico'!B10+'Reservas y Sustitutos'!B80 | C13: ='Indexado Dim Técnico'!C10+'Reservas y Sustitutos'!C80 | D13: ='Indexado Dim Técnico'!D10+'Reservas y Sustitutos'!D80 | E13: ='Indexado Dim Técnico'!E10+'Reservas y Sustitutos'!E80 | F13: ='Indexado Dim Técnico'!F10+'Reservas y Sustitutos'!F80 | G13: ='Indexado Dim Técnico'!G10+'Reservas y Sustitutos'!G80 | H13: ='Indexado Dim Técnico'!H10+'Reservas y Sustitutos'!H80 | I13: ='Indexado Dim Técnico'!I10+'Reservas y Sustitutos'!I80 | ... K13: ='Indexado Dim Técnico'!K10+'Reservas y Sustitutos'!K80 | L13: Indexado fila 10 + Reservas fila 80
A15: MATAFUEGOS REVENDIDOS (compra de unidades nuevas + alta de sustitutos)
A16: FL_MAT_AGUA_10l | B16: ='Indexado Dim Técnico'!B48+'Reservas y Sustitutos'!B71 | C16: ='Indexado Dim Técnico'!C48+'Reservas y Sustitutos'!C71 | D16: ='Indexado Dim Técnico'!D48+'Reservas y Sustitutos'!D71 | E16: ='Indexado Dim Técnico'!E48+'Reservas y Sustitutos'!E71 | F16: ='Indexado Dim Técnico'!F48+'Reservas y Sustitutos'!F71 | G16: ='Indexado Dim Técnico'!G48+'Reservas y Sustitutos'!G71 | H16: ='Indexado Dim Técnico'!H48+'Reservas y Sustitutos'!H71 | I16: ='Indexado Dim Técnico'!I48+'Reservas y Sustitutos'!I71 | ... K16: ='Indexado Dim Técnico'!K48+'Reservas y Sustitutos'!K71 | L16: Indexado fila 48 + Reservas fila 71
A17: FL_MAT_AFFF_10l | B17: ='Indexado Dim Técnico'!B49+'Reservas y Sustitutos'!B72 | C17: ='Indexado Dim Técnico'!C49+'Reservas y Sustitutos'!C72 | D17: ='Indexado Dim Técnico'!D49+'Reservas y Sustitutos'!D72 | E17: ='Indexado Dim Técnico'!E49+'Reservas y Sustitutos'!E72 | F17: ='Indexado Dim Técnico'!F49+'Reservas y Sustitutos'!F72 | G17: ='Indexado Dim Técnico'!G49+'Reservas y Sustitutos'!G72 | H17: ='Indexado Dim Técnico'!H49+'Reservas y Sustitutos'!H72 | I17: ='Indexado Dim Técnico'!I49+'Reservas y Sustitutos'!I72 | ... K17: ='Indexado Dim Técnico'!K49+'Reservas y Sustitutos'!K72 | L17: Indexado fila 49 + Reservas fila 72
A18: FL_MAT_AFFF_50l | B18: ='Indexado Dim Técnico'!B50+'Reservas y Sustitutos'!B73 | C18: ='Indexado Dim Técnico'!C50+'Reservas y Sustitutos'!C73 | D18: ='Indexado Dim Técnico'!D50+'Reservas y Sustitutos'!D73 | E18: ='Indexado Dim Técnico'!E50+'Reservas y Sustitutos'!E73 | F18: ='Indexado Dim Técnico'!F50+'Reservas y Sustitutos'!F73 | G18: ='Indexado Dim Técnico'!G50+'Reservas y Sustitutos'!G73 | H18: ='Indexado Dim Técnico'!H50+'Reservas y Sustitutos'!H73 | I18: ='Indexado Dim Técnico'!I50+'Reservas y Sustitutos'!I73 | ... K18: ='Indexado Dim Técnico'!K50+'Reservas y Sustitutos'!K73 | L18: Indexado fila 50 + Reservas fila 73
A19: FL_MAT_BC_5kg | B19: ='Indexado Dim Técnico'!B51+'Reservas y Sustitutos'!B74 | C19: ='Indexado Dim Técnico'!C51+'Reservas y Sustitutos'!C74 | D19: ='Indexado Dim Técnico'!D51+'Reservas y Sustitutos'!D74 | E19: ='Indexado Dim Técnico'!E51+'Reservas y Sustitutos'!E74 | F19: ='Indexado Dim Técnico'!F51+'Reservas y Sustitutos'!F74 | G19: ='Indexado Dim Técnico'!G51+'Reservas y Sustitutos'!G74 | H19: ='Indexado Dim Técnico'!H51+'Reservas y Sustitutos'!H74 | I19: ='Indexado Dim Técnico'!I51+'Reservas y Sustitutos'!I74 | ... K19: ='Indexado Dim Técnico'!K51+'Reservas y Sustitutos'!K74 | L19: Indexado fila 51 + Reservas fila 74
A20: FL_MAT_SALESK_6l | B20: ='Indexado Dim Técnico'!B52+'Reservas y Sustitutos'!B75 | C20: ='Indexado Dim Técnico'!C52+'Reservas y Sustitutos'!C75 | D20: ='Indexado Dim Técnico'!D52+'Reservas y Sustitutos'!D75 | E20: ='Indexado Dim Técnico'!E52+'Reservas y Sustitutos'!E75 | F20: ='Indexado Dim Técnico'!F52+'Reservas y Sustitutos'!F75 | G20: ='Indexado Dim Técnico'!G52+'Reservas y Sustitutos'!G75 | H20: ='Indexado Dim Técnico'!H52+'Reservas y Sustitutos'!H75 | I20: ='Indexado Dim Técnico'!I52+'Reservas y Sustitutos'!I75 | ... K20: ='Indexado Dim Técnico'!K52+'Reservas y Sustitutos'!K75 | L20: Indexado fila 52 + Reservas fila 75
A21: FL_MAT_CO2_2kg | B21: ='Indexado Dim Técnico'!B53 | C21: ='Indexado Dim Técnico'!C53 | D21: ='Indexado Dim Técnico'!D53 | E21: ='Indexado Dim Técnico'!E53 | F21: ='Indexado Dim Técnico'!F53 | G21: ='Indexado Dim Técnico'!G53 | H21: ='Indexado Dim Técnico'!H53 | I21: ='Indexado Dim Técnico'!I53 | ... K21: ='Indexado Dim Técnico'!K53 | L21: Indexado fila 53
A22: FL_MAT_CO2_5kg | B22: ='Indexado Dim Técnico'!B54+'Reservas y Sustitutos'!B76 | C22: ='Indexado Dim Técnico'!C54+'Reservas y Sustitutos'!C76 | D22: ='Indexado Dim Técnico'!D54+'Reservas y Sustitutos'!D76 | E22: ='Indexado Dim Técnico'!E54+'Reservas y Sustitutos'!E76 | F22: ='Indexado Dim Técnico'!F54+'Reservas y Sustitutos'!F76 | G22: ='Indexado Dim Técnico'!G54+'Reservas y Sustitutos'!G76 | H22: ='Indexado Dim Técnico'!H54+'Reservas y Sustitutos'!H76 | I22: ='Indexado Dim Técnico'!I54+'Reservas y Sustitutos'!I76 | ... K22: ='Indexado Dim Técnico'!K54+'Reservas y Sustitutos'!K76 | L22: Indexado fila 54 + Reservas fila 76
A23: FL_MAT_HCFC-HFC_5kg | B23: ='Indexado Dim Técnico'!B55+'Reservas y Sustitutos'!B77 | C23: ='Indexado Dim Técnico'!C55+'Reservas y Sustitutos'!C77 | D23: ='Indexado Dim Técnico'!D55+'Reservas y Sustitutos'!D77 | E23: ='Indexado Dim Técnico'!E55+'Reservas y Sustitutos'!E77 | F23: ='Indexado Dim Técnico'!F55+'Reservas y Sustitutos'!F77 | G23: ='Indexado Dim Técnico'!G55+'Reservas y Sustitutos'!G77 | H23: ='Indexado Dim Técnico'!H55+'Reservas y Sustitutos'!H77 | I23: ='Indexado Dim Técnico'!I55+'Reservas y Sustitutos'!I77 | ... K23: ='Indexado Dim Técnico'!K55+'Reservas y Sustitutos'!K77 | L23: Indexado fila 55 + Reservas fila 77
A24: FL_MAT_CLASED_9l | B24: ='Indexado Dim Técnico'!B56+'Reservas y Sustitutos'!B78 | C24: ='Indexado Dim Técnico'!C56+'Reservas y Sustitutos'!C78 | D24: ='Indexado Dim Técnico'!D56+'Reservas y Sustitutos'!D78 | E24: ='Indexado Dim Técnico'!E56+'Reservas y Sustitutos'!E78 | F24: ='Indexado Dim Técnico'!F56+'Reservas y Sustitutos'!F78 | G24: ='Indexado Dim Técnico'!G56+'Reservas y Sustitutos'!G78 | H24: ='Indexado Dim Técnico'!H56+'Reservas y Sustitutos'!H78 | I24: ='Indexado Dim Técnico'!I56+'Reservas y Sustitutos'!I78 | ... K24: ='Indexado Dim Técnico'!K56+'Reservas y Sustitutos'!K78 | L24: Indexado fila 56 + Reservas fila 78
A26: CILINDROS SUELTOS (venta)
A27: FL_REC_ABC_1kg | B27: ='Indexado Dim Técnico'!B15 | C27: ='Indexado Dim Técnico'!C15 | D27: ='Indexado Dim Técnico'!D15 | E27: ='Indexado Dim Técnico'!E15 | F27: ='Indexado Dim Técnico'!F15 | G27: ='Indexado Dim Técnico'!G15 | H27: ='Indexado Dim Técnico'!H15 | I27: ='Indexado Dim Técnico'!I15 | ... K27: ='Indexado Dim Técnico'!K15 | L27: Indexado fila 15
A28: FL_REC_ABC_2.5kg | B28: ='Indexado Dim Técnico'!B16 | C28: ='Indexado Dim Técnico'!C16 | D28: ='Indexado Dim Técnico'!D16 | E28: ='Indexado Dim Técnico'!E16 | F28: ='Indexado Dim Técnico'!F16 | G28: ='Indexado Dim Técnico'!G16 | H28: ='Indexado Dim Técnico'!H16 | I28: ='Indexado Dim Técnico'!I16 | ... K28: ='Indexado Dim Técnico'!K16 | L28: Indexado fila 16
A29: FL_REC_ABC_5kg | B29: ='Indexado Dim Técnico'!B17 | C29: ='Indexado Dim Técnico'!C17 | D29: ='Indexado Dim Técnico'!D17 | E29: ='Indexado Dim Técnico'!E17 | F29: ='Indexado Dim Técnico'!F17 | G29: ='Indexado Dim Técnico'!G17 | H29: ='Indexado Dim Técnico'!H17 | I29: ='Indexado Dim Técnico'!I17 | ... K29: ='Indexado Dim Técnico'!K17 | L29: Indexado fila 17
A30: FL_REC_ABC_10kg | B30: ='Indexado Dim Técnico'!B18 | C30: ='Indexado Dim Técnico'!C18 | D30: ='Indexado Dim Técnico'!D18 | E30: ='Indexado Dim Técnico'!E18 | F30: ='Indexado Dim Técnico'!F18 | G30: ='Indexado Dim Técnico'!G18 | H30: ='Indexado Dim Técnico'!H18 | I30: ='Indexado Dim Técnico'!I18 | ... K30: ='Indexado Dim Técnico'!K18 | L30: Indexado fila 18
A31: FL_REC_ABC_25kg | B31: ='Indexado Dim Técnico'!B19 | C31: ='Indexado Dim Técnico'!C19 | D31: ='Indexado Dim Técnico'!D19 | E31: ='Indexado Dim Técnico'!E19 | F31: ='Indexado Dim Técnico'!F19 | G31: ='Indexado Dim Técnico'!G19 | H31: ='Indexado Dim Técnico'!H19 | I31: ='Indexado Dim Técnico'!I19 | ... K31: ='Indexado Dim Técnico'!K19 | L31: Indexado fila 19
A32: FL_REC_ABC_50kg | B32: ='Indexado Dim Técnico'!B20 | C32: ='Indexado Dim Técnico'!C20 | D32: ='Indexado Dim Técnico'!D20 | E32: ='Indexado Dim Técnico'!E20 | F32: ='Indexado Dim Técnico'!F20 | G32: ='Indexado Dim Técnico'!G20 | H32: ='Indexado Dim Técnico'!H20 | I32: ='Indexado Dim Técnico'!I20 | ... K32: ='Indexado Dim Técnico'!K20 | L32: Indexado fila 20
A33: FL_REC_ABC_70kg | B33: ='Indexado Dim Técnico'!B21 | C33: ='Indexado Dim Técnico'!C21 | D33: ='Indexado Dim Técnico'!D21 | E33: ='Indexado Dim Técnico'!E21 | F33: ='Indexado Dim Técnico'!F21 | G33: ='Indexado Dim Técnico'!G21 | H33: ='Indexado Dim Técnico'!H21 | I33: ='Indexado Dim Técnico'!I21 | ... K33: ='Indexado Dim Técnico'!K21 | L33: Indexado fila 21
A34: FL_REC_ABC_100kg | B34: ='Indexado Dim Técnico'!B22 | C34: ='Indexado Dim Técnico'!C22 | D34: ='Indexado Dim Técnico'!D22 | E34: ='Indexado Dim Técnico'!E22 | F34: ='Indexado Dim Técnico'!F22 | G34: ='Indexado Dim Técnico'!G22 | H34: ='Indexado Dim Técnico'!H22 | I34: ='Indexado Dim Técnico'!I22 | ... K34: ='Indexado Dim Técnico'!K22 | L34: Indexado fila 22
A36: KITS DE SUSTITUTO (alta anual de sustitutos por pool)
A37: FL_SUS_ABC_5kg | B37: ='Reservas y Sustitutos'!B69 | C37: ='Reservas y Sustitutos'!C69 | D37: ='Reservas y Sustitutos'!D69 | E37: ='Reservas y Sustitutos'!E69 | F37: ='Reservas y Sustitutos'!F69 | G37: ='Reservas y Sustitutos'!G69 | H37: ='Reservas y Sustitutos'!H69 | I37: ='Reservas y Sustitutos'!I69 | ... K37: ='Reservas y Sustitutos'!K69 | L37: Reservas fila 69
A38: FL_SUS_ABC_10kg | B38: ='Reservas y Sustitutos'!B70 | C38: ='Reservas y Sustitutos'!C70 | D38: ='Reservas y Sustitutos'!D70 | E38: ='Reservas y Sustitutos'!E70 | F38: ='Reservas y Sustitutos'!F70 | G38: ='Reservas y Sustitutos'!G70 | H38: ='Reservas y Sustitutos'!H70 | I38: ='Reservas y Sustitutos'!I70 | ... K38: ='Reservas y Sustitutos'!K70 | L38: Reservas fila 70
A39: FL_SUS_AGUA_10l | B39: ='Reservas y Sustitutos'!B71 | C39: ='Reservas y Sustitutos'!C71 | D39: ='Reservas y Sustitutos'!D71 | E39: ='Reservas y Sustitutos'!E71 | F39: ='Reservas y Sustitutos'!F71 | G39: ='Reservas y Sustitutos'!G71 | H39: ='Reservas y Sustitutos'!H71 | I39: ='Reservas y Sustitutos'!I71 | ... K39: ='Reservas y Sustitutos'!K71 | L39: Reservas fila 71
A40: FL_SUS_AFFF_10l | B40: ='Reservas y Sustitutos'!B72 | C40: ='Reservas y Sustitutos'!C72 | D40: ='Reservas y Sustitutos'!D72 | E40: ='Reservas y Sustitutos'!E72 | F40: ='Reservas y Sustitutos'!F72 | G40: ='Reservas y Sustitutos'!G72 | H40: ='Reservas y Sustitutos'!H72 | I40: ='Reservas y Sustitutos'!I72 | ... K40: ='Reservas y Sustitutos'!K72 | L40: Reservas fila 72
A41: FL_SUS_AFFF_50l | B41: ='Reservas y Sustitutos'!B73 | C41: ='Reservas y Sustitutos'!C73 | D41: ='Reservas y Sustitutos'!D73 | E41: ='Reservas y Sustitutos'!E73 | F41: ='Reservas y Sustitutos'!F73 | G41: ='Reservas y Sustitutos'!G73 | H41: ='Reservas y Sustitutos'!H73 | I41: ='Reservas y Sustitutos'!I73 | ... K41: ='Reservas y Sustitutos'!K73 | L41: Reservas fila 73
A42: FL_SUS_BC_5kg | B42: ='Reservas y Sustitutos'!B74 | C42: ='Reservas y Sustitutos'!C74 | D42: ='Reservas y Sustitutos'!D74 | E42: ='Reservas y Sustitutos'!E74 | F42: ='Reservas y Sustitutos'!F74 | G42: ='Reservas y Sustitutos'!G74 | H42: ='Reservas y Sustitutos'!H74 | I42: ='Reservas y Sustitutos'!I74 | ... K42: ='Reservas y Sustitutos'!K74 | L42: Reservas fila 74
A43: FL_SUS_SALESK_6l | B43: ='Reservas y Sustitutos'!B75 | C43: ='Reservas y Sustitutos'!C75 | D43: ='Reservas y Sustitutos'!D75 | E43: ='Reservas y Sustitutos'!E75 | F43: ='Reservas y Sustitutos'!F75 | G43: ='Reservas y Sustitutos'!G75 | H43: ='Reservas y Sustitutos'!H75 | I43: ='Reservas y Sustitutos'!I75 | ... K43: ='Reservas y Sustitutos'!K75 | L43: Reservas fila 75
A44: FL_SUS_CO2_5kg | B44: ='Reservas y Sustitutos'!B76 | C44: ='Reservas y Sustitutos'!C76 | D44: ='Reservas y Sustitutos'!D76 | E44: ='Reservas y Sustitutos'!E76 | F44: ='Reservas y Sustitutos'!F76 | G44: ='Reservas y Sustitutos'!G76 | H44: ='Reservas y Sustitutos'!H76 | I44: ='Reservas y Sustitutos'!I76 | ... K44: ='Reservas y Sustitutos'!K76 | L44: Reservas fila 76
A45: FL_SUS_HCFC-HFC_5kg | B45: ='Reservas y Sustitutos'!B77 | C45: ='Reservas y Sustitutos'!C77 | D45: ='Reservas y Sustitutos'!D77 | E45: ='Reservas y Sustitutos'!E77 | F45: ='Reservas y Sustitutos'!F77 | G45: ='Reservas y Sustitutos'!G77 | H45: ='Reservas y Sustitutos'!H77 | I45: ='Reservas y Sustitutos'!I77 | ... K45: ='Reservas y Sustitutos'!K77 | L45: Reservas fila 77
...

Sheet MP_MATAFUEGOS_FABRICADOS
A1: Requerimiento de MP — matafuegos fabricados (ABC 1 a 100 kg)
A2: Demanda = unidades nuevas + venta de reserva ABC 5 kg + alta de sustitutos. Coeficientes del BOM (azul). Destino CABA/PBA según % zonal (Parametros fila 7).
AJ4: Demanda (u) → | AK4: ABC_1kg | AL4: ABC_2.5kg | AM4: ABC_5kg | AN4: ABC_10kg | AO4: ABC_25kg | AP4: ABC_50kg | AQ4: ABC_70kg | AR4: ABC_100kg
AJ5: ='Demanda'!B3 | AK5: ='Demanda'!B6 | AL5: ='Demanda'!B7 | AM5: ='Demanda'!B8 | AN5: ='Demanda'!B9 | AO5: ='Demanda'!B10 | AP5: ='Demanda'!B11 | AQ5: ='Demanda'!B12 | AR5: ='Demanda'!B13
AJ6: ='Demanda'!C3 | AK6: ='Demanda'!C6 | AL6: ='Demanda'!C7 | AM6: ='Demanda'!C8 | AN6: ='Demanda'!C9 | AO6: ='Demanda'!C10 | AP6: ='Demanda'!C11 | AQ6: ='Demanda'!C12 | AR6: ='Demanda'!C13
AJ7: ='Demanda'!D3 | AK7: ='Demanda'!D6 | AL7: ='Demanda'!D7 | AM7: ='Demanda'!D8 | AN7: ='Demanda'!D9 | AO7: ='Demanda'!D10 | AP7: ='Demanda'!D11 | AQ7: ='Demanda'!D12 | AR7: ='Demanda'!D13
AJ8: ='Demanda'!E3 | AK8: ='Demanda'!E6 | AL8: ='Demanda'!E7 | AM8: ='Demanda'!E8 | AN8: ='Demanda'!E9 | AO8: ='Demanda'!E10 | AP8: ='Demanda'!E11 | AQ8: ='Demanda'!E12 | AR8: ='Demanda'!E13
AJ9: ='Demanda'!F3 | AK9: ='Demanda'!F6 | AL9: ='Demanda'!F7 | AM9: ='Demanda'!F8 | AN9: ='Demanda'!F9 | AO9: ='Demanda'!F10 | AP9: ='Demanda'!F11 | AQ9: ='Demanda'!F12 | AR9: ='Demanda'!F13
AJ10: ='Demanda'!G3 | AK10: ='Demanda'!G6 | AL10: ='Demanda'!G7 | AM10: ='Demanda'!G8 | AN10: ='Demanda'!G9 | AO10: ='Demanda'!G10 | AP10: ='Demanda'!G11 | AQ10: ='Demanda'!G12 | AR10: ='Demanda'!G13
AJ11: ='Demanda'!H3 | AK11: ='Demanda'!H6 | AL11: ='Demanda'!H7 | AM11: ='Demanda'!H8 | AN11: ='Demanda'!H9 | AO11: ='Demanda'!H10 | AP11: ='Demanda'!H11 | AQ11: ='Demanda'!H12 | AR11: ='Demanda'!H13
AJ12: ='Demanda'!I3 | AK12: ='Demanda'!I6 | AL12: ='Demanda'!I7 | AM12: ='Demanda'!I8 | AN12: ='Demanda'!I9 | AO12: ='Demanda'!I10 | AP12: ='Demanda'!I11 | AQ12: ='Demanda'!I12 | AR12: ='Demanda'!I13
AJ13: ='Demanda'!J3 | AK13: ='Demanda'!J6 | AL13: ='Demanda'!J7 | AM13: ='Demanda'!J8 | AN13: ='Demanda'!J9 | AO13: ='Demanda'!J10 | AP13: ='Demanda'!J11 | AQ13: ='Demanda'!J12 | AR13: ='Demanda'!J13
AJ14: ='Demanda'!K3 | AK14: ='Demanda'!K6 | AL14: ='Demanda'!K7 | AM14: ='Demanda'!K8 | AN14: ='Demanda'!K9 | AO14: ='Demanda'!K10 | AP14: ='Demanda'!K11 | AQ14: ='Demanda'!K12 | AR14: ='Demanda'!K13
A16: Ítem | B16: UM | C16: Rubro | D16: Proveedor principal | E16: Destino | F16: ='Demanda'!B3 | G16: ='Demanda'!C3 | H16: ='Demanda'!D3 | I16: ='Demanda'!E3 | J16: ='Demanda'!F3 | K16: ='Demanda'!G3 | L16: ='Demanda'!H3 | M16: ='Demanda'!I3 | ... O16: ='Demanda'!K3 | AK16: coef. ABC_1kg | AL16: coef. ABC_2.5kg | AM16: coef. ABC_5kg | AN16: coef. ABC_10kg | AO16: coef. ABC_25kg | AP16: coef. ABC_50kg | AQ16: coef. ABC_70kg | AR16: coef. ABC_100kg
A17: Caño SAE 1010 Ø25,4 × 1,6 | B17: barra 6 m | C17: Materia prima | D17: Metalpri / Prilux | E17: Todos | F17: =SUMPRODUCT($AK17:$AR17,$AK$5:$AR$5)*IF($E17="CABA",'Parametros'!B$7,IF($E17="PBA",1-'Parametros'!B$7,1)) | G17: =SUMPRODUCT($AK17:$AR17,$AK$6:$AR$6)*IF($E17="CABA",'Parametros'!C$7,IF($E17="PBA",1-'Parametros'!C$7,1)) | H17: =SUMPRODUCT($AK17:$AR17,$AK$7:$AR$7)*IF($E17="CABA",'Parametros'!D$7,IF($E17="PBA",1-'Parametros'!D$7,1)) | I17: =SUMPRODUCT($AK17:$AR17,$AK$8:$AR$8)*IF($E17="CABA",'Parametros'!E$7,IF($E17="PBA",1-'Parametros'!E$7,1)) | J17: =SUMPRODUCT($AK17:$AR17,$AK$9:$AR$9)*IF($E17="CABA",'Parametros'!F$7,IF($E17="PBA",1-'Parametros'!F$7,1)) | K17: =SUMPRODUCT($AK17:$AR17,$AK$10:$AR$10)*IF($E17="CABA",'Parametros'!G$7,IF($E17="PBA",1-'Parametros'!G$7,1)) | L17: =SUMPRODUCT($AK17:$AR17,$AK$11:$AR$11)*IF($E17="CABA",'Parametros'!H$7,IF($E17="PBA",1-'Parametros'!H$7,1)) | M17: =SUMPRODUCT($AK17:$AR17,$AK$12:$AR$12)*IF($E17="CABA",'Parametros'!I$7,IF($E17="PBA",1-'Parametros'!I$7,1)) | N17: =SUMPRODUCT($AK17:$AR17,$AK$13:$AR$13)*IF($E17="CABA",'Parametros'!J$7,IF($E17="PBA",1-'Parametros'!J$7,1)) | O17: =SUMPRODUCT($AK17:$AR17,$AK$14:$AR$14)*IF($E17="CABA",'Parametros'!K$7,IF($E17="PBA",1-'Parametros'!K$7,1)) | AO17: 0.2774 | AP17: 0.2767 | AQ17: 0.3162 | AR17: 0.2998
A18: Caño Ø76,2 × 1,25 | B18: barra 6 m | C18: Materia prima | D18: Metalpri / Prilux | E18: Todos | F18: =SUMPRODUCT($AK18:$AR18,$AK$5:$AR$5)*IF($E18="CABA",'Parametros'!B$7,IF($E18="PBA",1-'Parametros'!B$7,1)) | G18: =SUMPRODUCT($AK18:$AR18,$AK$6:$AR$6)*IF($E18="CABA",'Parametros'!C$7,IF($E18="PBA",1-'Parametros'!C$7,1)) | H18: =SUMPRODUCT($AK18:$AR18,$AK$7:$AR$7)*IF($E18="CABA",'Parametros'!D$7,IF($E18="PBA",1-'Parametros'!D$7,1)) | I18: =SUMPRODUCT($AK18:$AR18,$AK$8:$AR$8)*IF($E18="CABA",'Parametros'!E$7,IF($E18="PBA",1-'Parametros'!E$7,1)) | J18: =SUMPRODUCT($AK18:$AR18,$AK$9:$AR$9)*IF($E18="CABA",'Parametros'!F$7,IF($E18="PBA",1-'Parametros'!F$7,1)) | K18: =SUMPRODUCT($AK18:$AR18,$AK$10:$AR$10)*IF($E18="CABA",'Parametros'!G$7,IF($E18="PBA",1-'Parametros'!G$7,1)) | L18: =SUMPRODUCT($AK18:$AR18,$AK$11:$AR$11)*IF($E18="CABA",'Parametros'!H$7,IF($E18="PBA",1-'Parametros'!H$7,1)) | M18: =SUMPRODUCT($AK18:$AR18,$AK$12:$AR$12)*IF($E18="CABA",'Parametros'!I$7,IF($E18="PBA",1-'Parametros'!I$7,1)) | N18: =SUMPRODUCT($AK18:$AR18,$AK$13:$AR$13)*IF($E18="CABA",'Parametros'!J$7,IF($E18="PBA",1-'Parametros'!J$7,1)) | O18: =SUMPRODUCT($AK18:$AR18,$AK$14:$AR$14)*IF($E18="CABA",'Parametros'!K$7,IF($E18="PBA",1-'Parametros'!K$7,1)) | AK18: 0.0435
A19: Chapa LAC 1500 × 3000 e=3,2 | B19: kg | C19: Materia prima | D19: Pradecon S.A. | E19: Todos | F19: =SUMPRODUCT($AK19:$AR19,$AK$5:$AR$5)*IF($E19="CABA",'Parametros'!B$7,IF($E19="PBA",1-'Parametros'!B$7,1)) | G19: =SUMPRODUCT($AK19:$AR19,$AK$6:$AR$6)*IF($E19="CABA",'Parametros'!C$7,IF($E19="PBA",1-'Parametros'!C$7,1)) | H19: =SUMPRODUCT($AK19:$AR19,$AK$7:$AR$7)*IF($E19="CABA",'Parametros'!D$7,IF($E19="PBA",1-'Parametros'!D$7,1)) | I19: =SUMPRODUCT($AK19:$AR19,$AK$8:$AR$8)*IF($E19="CABA",'Parametros'!E$7,IF($E19="PBA",1-'Parametros'!E$7,1)) | J19: =SUMPRODUCT($AK19:$AR19,$AK$9:$AR$9)*IF($E19="CABA",'Parametros'!F$7,IF($E19="PBA",1-'Parametros'!F$7,1)) | K19: =SUMPRODUCT($AK19:$AR19,$AK$10:$AR$10)*IF($E19="CABA",'Parametros'!G$7,IF($E19="PBA",1-'Parametros'!G$7,1)) | L19: =SUMPRODUCT($AK19:$AR19,$AK$11:$AR$11)*IF($E19="CABA",'Parametros'!H$7,IF($E19="PBA",1-'Parametros'!H$7,1)) | M19: =SUMPRODUCT($AK19:$AR19,$AK$12:$AR$12)*IF($E19="CABA",'Parametros'!I$7,IF($E19="PBA",1-'Parametros'!I$7,1)) | N19: =SUMPRODUCT($AK19:$AR19,$AK$13:$AR$13)*IF($E19="CABA",'Parametros'!J$7,IF($E19="PBA",1-'Parametros'!J$7,1)) | O19: =SUMPRODUCT($AK19:$AR19,$AK$14:$AR$14)*IF($E19="CABA",'Parametros'!K$7,IF($E19="PBA",1-'Parametros'!K$7,1)) | AO19: 12.558 | AP19: 18.845
A20: Chapa LAC 1500 × 3000 e=4,75 | B20: kg | C20: Materia prima | D20: Pradecon S.A. | E20: Todos | F20: =SUMPRODUCT($AK20:$AR20,$AK$5:$AR$5)*IF($E20="CABA",'Parametros'!B$7,IF($E20="PBA",1-'Parametros'!B$7,1)) | G20: =SUMPRODUCT($AK20:$AR20,$AK$6:$AR$6)*IF($E20="CABA",'Parametros'!C$7,IF($E20="PBA",1-'Parametros'!C$7,1)) | H20: =SUMPRODUCT($AK20:$AR20,$AK$7:$AR$7)*IF($E20="CABA",'Parametros'!D$7,IF($E20="PBA",1-'Parametros'!D$7,1)) | I20: =SUMPRODUCT($AK20:$AR20,$AK$8:$AR$8)*IF($E20="CABA",'Parametros'!E$7,IF($E20="PBA",1-'Parametros'!E$7,1)) | J20: =SUMPRODUCT($AK20:$AR20,$AK$9:$AR$9)*IF($E20="CABA",'Parametros'!F$7,IF($E20="PBA",1-'Parametros'!F$7,1)) | K20: =SUMPRODUCT($AK20:$AR20,$AK$10:$AR$10)*IF($E20="CABA",'Parametros'!G$7,IF($E20="PBA",1-'Parametros'!G$7,1)) | L20: =SUMPRODUCT($AK20:$AR20,$AK$11:$AR$11)*IF($E20="CABA",'Parametros'!H$7,IF($E20="PBA",1-'Parametros'!H$7,1)) | M20: =SUMPRODUCT($AK20:$AR20,$AK$12:$AR$12)*IF($E20="CABA",'Parametros'!I$7,IF($E20="PBA",1-'Parametros'!I$7,1)) | N20: =SUMPRODUCT($AK20:$AR20,$AK$13:$AR$13)*IF($E20="CABA",'Parametros'!J$7,IF($E20="PBA",1-'Parametros'!J$7,1)) | O20: =SUMPRODUCT($AK20:$AR20,$AK$14:$AR$14)*IF($E20="CABA",'Parametros'!K$7,IF($E20="PBA",1-'Parametros'!K$7,1)) | AQ20: 38.802 | AR20: 51.355
A21: Chapa LAF 1000 × 2000 e=1,6 | B21: kg | C21: Materia prima | D21: Pradecon S.A. | E21: Todos | F21: =SUMPRODUCT($AK21:$AR21,$AK$5:$AR$5)*IF($E21="CABA",'Parametros'!B$7,IF($E21="PBA",1-'Parametros'!B$7,1)) | G21: =SUMPRODUCT($AK21:$AR21,$AK$6:$AR$6)*IF($E21="CABA",'Parametros'!C$7,IF($E21="PBA",1-'Parametros'!C$7,1)) | H21: =SUMPRODUCT($AK21:$AR21,$AK$7:$AR$7)*IF($E21="CABA",'Parametros'!D$7,IF($E21="PBA",1-'Parametros'!D$7,1)) | I21: =SUMPRODUCT($AK21:$AR21,$AK$8:$AR$8)*IF($E21="CABA",'Parametros'!E$7,IF($E21="PBA",1-'Parametros'!E$7,1)) | J21: =SUMPRODUCT($AK21:$AR21,$AK$9:$AR$9)*IF($E21="CABA",'Parametros'!F$7,IF($E21="PBA",1-'Parametros'!F$7,1)) | K21: =SUMPRODUCT($AK21:$AR21,$AK$10:$AR$10)*IF($E21="CABA",'Parametros'!G$7,IF($E21="PBA",1-'Parametros'!G$7,1)) | L21: =SUMPRODUCT($AK21:$AR21,$AK$11:$AR$11)*IF($E21="CABA",'Parametros'!H$7,IF($E21="PBA",1-'Parametros'!H$7,1)) | M21: =SUMPRODUCT($AK21:$AR21,$AK$12:$AR$12)*IF($E21="CABA",'Parametros'!I$7,IF($E21="PBA",1-'Parametros'!I$7,1)) | N21: =SUMPRODUCT($AK21:$AR21,$AK$13:$AR$13)*IF($E21="CABA",'Parametros'!J$7,IF($E21="PBA",1-'Parametros'!J$7,1)) | O21: =SUMPRODUCT($AK21:$AR21,$AK$14:$AR$14)*IF($E21="CABA",'Parametros'!K$7,IF($E21="PBA",1-'Parametros'!K$7,1)) | AM21: 2.092
A22: Chapa LAF 1220 × 2440 e=1,25 | B22: kg | C22: Materia prima | D22: Pradecon S.A. | E22: Todos | F22: =SUMPRODUCT($AK22:$AR22,$AK$5:$AR$5)*IF($E22="CABA",'Parametros'!B$7,IF($E22="PBA",1-'Parametros'!B$7,1)) | G22: =SUMPRODUCT($AK22:$AR22,$AK$6:$AR$6)*IF($E22="CABA",'Parametros'!C$7,IF($E22="PBA",1-'Parametros'!C$7,1)) | H22: =SUMPRODUCT($AK22:$AR22,$AK$7:$AR$7)*IF($E22="CABA",'Parametros'!D$7,IF($E22="PBA",1-'Parametros'!D$7,1)) | I22: =SUMPRODUCT($AK22:$AR22,$AK$8:$AR$8)*IF($E22="CABA",'Parametros'!E$7,IF($E22="PBA",1-'Parametros'!E$7,1)) | J22: =SUMPRODUCT($AK22:$AR22,$AK$9:$AR$9)*IF($E22="CABA",'Parametros'!F$7,IF($E22="PBA",1-'Parametros'!F$7,1)) | K22: =SUMPRODUCT($AK22:$AR22,$AK$10:$AR$10)*IF($E22="CABA",'Parametros'!G$7,IF($E22="PBA",1-'Parametros'!G$7,1)) | L22: =SUMPRODUCT($AK22:$AR22,$AK$11:$AR$11)*IF($E22="CABA",'Parametros'!H$7,IF($E22="PBA",1-'Parametros'!H$7,1)) | M22: =SUMPRODUCT($AK22:$AR22,$AK$12:$AR$12)*IF($E22="CABA",'Parametros'!I$7,IF($E22="PBA",1-'Parametros'!I$7,1)) | N22: =SUMPRODUCT($AK22:$AR22,$AK$13:$AR$13)*IF($E22="CABA",'Parametros'!J$7,IF($E22="PBA",1-'Parametros'!J$7,1)) | O22: =SUMPRODUCT($AK22:$AR22,$AK$14:$AR$14)*IF($E22="CABA",'Parametros'!K$7,IF($E22="PBA",1-'Parametros'!K$7,1)) | AL22: 1.082
A23: Chapa LAF 1500 × 3000 e=2 | B23: kg | C23: Materia prima | D23: Pradecon S.A. | E23: Todos | F23: =SUMPRODUCT($AK23:$AR23,$AK$5:$AR$5)*IF($E23="CABA",'Parametros'!B$7,IF($E23="PBA",1-'Parametros'!B$7,1)) | G23: =SUMPRODUCT($AK23:$AR23,$AK$6:$AR$6)*IF($E23="CABA",'Parametros'!C$7,IF($E23="PBA",1-'Parametros'!C$7,1)) | H23: =SUMPRODUCT($AK23:$AR23,$AK$7:$AR$7)*IF($E23="CABA",'Parametros'!D$7,IF($E23="PBA",1-'Parametros'!D$7,1)) | I23: =SUMPRODUCT($AK23:$AR23,$AK$8:$AR$8)*IF($E23="CABA",'Parametros'!E$7,IF($E23="PBA",1-'Parametros'!E$7,1)) | J23: =SUMPRODUCT($AK23:$AR23,$AK$9:$AR$9)*IF($E23="CABA",'Parametros'!F$7,IF($E23="PBA",1-'Parametros'!F$7,1)) | K23: =SUMPRODUCT($AK23:$AR23,$AK$10:$AR$10)*IF($E23="CABA",'Parametros'!G$7,IF($E23="PBA",1-'Parametros'!G$7,1)) | L23: =SUMPRODUCT($AK23:$AR23,$AK$11:$AR$11)*IF($E23="CABA",'Parametros'!H$7,IF($E23="PBA",1-'Parametros'!H$7,1)) | M23: =SUMPRODUCT($AK23:$AR23,$AK$12:$AR$12)*IF($E23="CABA",'Parametros'!I$7,IF($E23="PBA",1-'Parametros'!I$7,1)) | N23: =SUMPRODUCT($AK23:$AR23,$AK$13:$AR$13)*IF($E23="CABA",'Parametros'!J$7,IF($E23="PBA",1-'Parametros'!J$7,1)) | O23: =SUMPRODUCT($AK23:$AR23,$AK$14:$AR$14)*IF($E23="CABA",'Parametros'!K$7,IF($E23="PBA",1-'Parametros'!K$7,1)) | AN23: 4.71
A24: Fleje e=0,9 × 114 | B24: m | C24: Materia prima | D24: Pacheco Chapas | E24: Todos | F24: =SUMPRODUCT($AK24:$AR24,$AK$5:$AR$5)*IF($E24="CABA",'Parametros'!B$7,IF($E24="PBA",1-'Parametros'!B$7,1)) | G24: =SUMPRODUCT($AK24:$AR24,$AK$6:$AR$6)*IF($E24="CABA",'Parametros'!C$7,IF($E24="PBA",1-'Parametros'!C$7,1)) | H24: =SUMPRODUCT($AK24:$AR24,$AK$7:$AR$7)*IF($E24="CABA",'Parametros'!D$7,IF($E24="PBA",1-'Parametros'!D$7,1)) | I24: =SUMPRODUCT($AK24:$AR24,$AK$8:$AR$8)*IF($E24="CABA",'Parametros'!E$7,IF($E24="PBA",1-'Parametros'!E$7,1)) | J24: =SUMPRODUCT($AK24:$AR24,$AK$9:$AR$9)*IF($E24="CABA",'Parametros'!F$7,IF($E24="PBA",1-'Parametros'!F$7,1)) | K24: =SUMPRODUCT($AK24:$AR24,$AK$10:$AR$10)*IF($E24="CABA",'Parametros'!G$7,IF($E24="PBA",1-'Parametros'!G$7,1)) | L24: =SUMPRODUCT($AK24:$AR24,$AK$11:$AR$11)*IF($E24="CABA",'Parametros'!H$7,IF($E24="PBA",1-'Parametros'!H$7,1)) | M24: =SUMPRODUCT($AK24:$AR24,$AK$12:$AR$12)*IF($E24="CABA",'Parametros'!I$7,IF($E24="PBA",1-'Parametros'!I$7,1)) | N24: =SUMPRODUCT($AK24:$AR24,$AK$13:$AR$13)*IF($E24="CABA",'Parametros'!J$7,IF($E24="PBA",1-'Parametros'!J$7,1)) | O24: =SUMPRODUCT($AK24:$AR24,$AK$14:$AR$14)*IF($E24="CABA",'Parametros'!K$7,IF($E24="PBA",1-'Parametros'!K$7,1)) | AK24: 0.111
A25: Fleje e=1,25 × 106 | B25: m | C25: Materia prima | D25: Pacheco Chapas | E25: Todos | F25: =SUMPRODUCT($AK25:$AR25,$AK$5:$AR$5)*IF($E25="CABA",'Parametros'!B$7,IF($E25="PBA",1-'Parametros'!B$7,1)) | G25: =SUMPRODUCT($AK25:$AR25,$AK$6:$AR$6)*IF($E25="CABA",'Parametros'!C$7,IF($E25="PBA",1-'Parametros'!C$7,1)) | H25: =SUMPRODUCT($AK25:$AR25,$AK$7:$AR$7)*IF($E25="CABA",'Parametros'!D$7,IF($E25="PBA",1-'Parametros'!D$7,1)) | I25: =SUMPRODUCT($AK25:$AR25,$AK$8:$AR$8)*IF($E25="CABA",'Parametros'!E$7,IF($E25="PBA",1-'Parametros'!E$7,1)) | J25: =SUMPRODUCT($AK25:$AR25,$AK$9:$AR$9)*IF($E25="CABA",'Parametros'!F$7,IF($E25="PBA",1-'Parametros'!F$7,1)) | K25: =SUMPRODUCT($AK25:$AR25,$AK$10:$AR$10)*IF($E25="CABA",'Parametros'!G$7,IF($E25="PBA",1-'Parametros'!G$7,1)) | L25: =SUMPRODUCT($AK25:$AR25,$AK$11:$AR$11)*IF($E25="CABA",'Parametros'!H$7,IF($E25="PBA",1-'Parametros'!H$7,1)) | M25: =SUMPRODUCT($AK25:$AR25,$AK$12:$AR$12)*IF($E25="CABA",'Parametros'!I$7,IF($E25="PBA",1-'Parametros'!I$7,1)) | N25: =SUMPRODUCT($AK25:$AR25,$AK$13:$AR$13)*IF($E25="CABA",'Parametros'!J$7,IF($E25="PBA",1-'Parametros'!J$7,1)) | O25: =SUMPRODUCT($AK25:$AR25,$AK$14:$AR$14)*IF($E25="CABA",'Parametros'!K$7,IF($E25="PBA",1-'Parametros'!K$7,1)) | AK25: 0.103
A26: Fleje e=1,25 × 200 | B26: m | C26: Materia prima | D26: Pacheco Chapas | E26: Todos | F26: =SUMPRODUCT($AK26:$AR26,$AK$5:$AR$5)*IF($E26="CABA",'Parametros'!B$7,IF($E26="PBA",1-'Parametros'!B$7,1)) | G26: =SUMPRODUCT($AK26:$AR26,$AK$6:$AR$6)*IF($E26="CABA",'Parametros'!C$7,IF($E26="PBA",1-'Parametros'!C$7,1)) | H26: =SUMPRODUCT($AK26:$AR26,$AK$7:$AR$7)*IF($E26="CABA",'Parametros'!D$7,IF($E26="PBA",1-'Parametros'!D$7,1)) | I26: =SUMPRODUCT($AK26:$AR26,$AK$8:$AR$8)*IF($E26="CABA",'Parametros'!E$7,IF($E26="PBA",1-'Parametros'!E$7,1)) | J26: =SUMPRODUCT($AK26:$AR26,$AK$9:$AR$9)*IF($E26="CABA",'Parametros'!F$7,IF($E26="PBA",1-'Parametros'!F$7,1)) | K26: =SUMPRODUCT($AK26:$AR26,$AK$10:$AR$10)*IF($E26="CABA",'Parametros'!G$7,IF($E26="PBA",1-'Parametros'!G$7,1)) | L26: =SUMPRODUCT($AK26:$AR26,$AK$11:$AR$11)*IF($E26="CABA",'Parametros'!H$7,IF($E26="PBA",1-'Parametros'!H$7,1)) | M26: =SUMPRODUCT($AK26:$AR26,$AK$12:$AR$12)*IF($E26="CABA",'Parametros'!I$7,IF($E26="PBA",1-'Parametros'!I$7,1)) | N26: =SUMPRODUCT($AK26:$AR26,$AK$13:$AR$13)*IF($E26="CABA",'Parametros'!J$7,IF($E26="PBA",1-'Parametros'!J$7,1)) | O26: =SUMPRODUCT($AK26:$AR26,$AK$14:$AR$14)*IF($E26="CABA",'Parametros'!K$7,IF($E26="PBA",1-'Parametros'!K$7,1)) | AL26: 0.333
A27: Fleje e=1,6 × 200 | B27: m | C27: Materia prima | D27: Pacheco Chapas | E27: Todos | F27: =SUMPRODUCT($AK27:$AR27,$AK$5:$AR$5)*IF($E27="CABA",'Parametros'!B$7,IF($E27="PBA",1-'Parametros'!B$7,1)) | G27: =SUMPRODUCT($AK27:$AR27,$AK$6:$AR$6)*IF($E27="CABA",'Parametros'!C$7,IF($E27="PBA",1-'Parametros'!C$7,1)) | H27: =SUMPRODUCT($AK27:$AR27,$AK$7:$AR$7)*IF($E27="CABA",'Parametros'!D$7,IF($E27="PBA",1-'Parametros'!D$7,1)) | I27: =SUMPRODUCT($AK27:$AR27,$AK$8:$AR$8)*IF($E27="CABA",'Parametros'!E$7,IF($E27="PBA",1-'Parametros'!E$7,1)) | J27: =SUMPRODUCT($AK27:$AR27,$AK$9:$AR$9)*IF($E27="CABA",'Parametros'!F$7,IF($E27="PBA",1-'Parametros'!F$7,1)) | K27: =SUMPRODUCT($AK27:$AR27,$AK$10:$AR$10)*IF($E27="CABA",'Parametros'!G$7,IF($E27="PBA",1-'Parametros'!G$7,1)) | L27: =SUMPRODUCT($AK27:$AR27,$AK$11:$AR$11)*IF($E27="CABA",'Parametros'!H$7,IF($E27="PBA",1-'Parametros'!H$7,1)) | M27: =SUMPRODUCT($AK27:$AR27,$AK$12:$AR$12)*IF($E27="CABA",'Parametros'!I$7,IF($E27="PBA",1-'Parametros'!I$7,1)) | N27: =SUMPRODUCT($AK27:$AR27,$AK$13:$AR$13)*IF($E27="CABA",'Parametros'!J$7,IF($E27="PBA",1-'Parametros'!J$7,1)) | O27: =SUMPRODUCT($AK27:$AR27,$AK$14:$AR$14)*IF($E27="CABA",'Parametros'!K$7,IF($E27="PBA",1-'Parametros'!K$7,1)) | AM27: 0.18
A28: Fleje e=1,6 × 250 | B28: m | C28: Materia prima | D28: Pacheco Chapas | E28: Todos | F28: =SUMPRODUCT($AK28:$AR28,$AK$5:$AR$5)*IF($E28="CABA",'Parametros'!B$7,IF($E28="PBA",1-'Parametros'!B$7,1)) | G28: =SUMPRODUCT($AK28:$AR28,$AK$6:$AR$6)*IF($E28="CABA",'Parametros'!C$7,IF($E28="PBA",1-'Parametros'!C$7,1)) | H28: =SUMPRODUCT($AK28:$AR28,$AK$7:$AR$7)*IF($E28="CABA",'Parametros'!D$7,IF($E28="PBA",1-'Parametros'!D$7,1)) | I28: =SUMPRODUCT($AK28:$AR28,$AK$8:$AR$8)*IF($E28="CABA",'Parametros'!E$7,IF($E28="PBA",1-'Parametros'!E$7,1)) | J28: =SUMPRODUCT($AK28:$AR28,$AK$9:$AR$9)*IF($E28="CABA",'Parametros'!F$7,IF($E28="PBA",1-'Parametros'!F$7,1)) | K28: =SUMPRODUCT($AK28:$AR28,$AK$10:$AR$10)*IF($E28="CABA",'Parametros'!G$7,IF($E28="PBA",1-'Parametros'!G$7,1)) | L28: =SUMPRODUCT($AK28:$AR28,$AK$11:$AR$11)*IF($E28="CABA",'Parametros'!H$7,IF($E28="PBA",1-'Parametros'!H$7,1)) | M28: =SUMPRODUCT($AK28:$AR28,$AK$12:$AR$12)*IF($E28="CABA",'Parametros'!I$7,IF($E28="PBA",1-'Parametros'!I$7,1)) | N28: =SUMPRODUCT($AK28:$AR28,$AK$13:$AR$13)*IF($E28="CABA",'Parametros'!J$7,IF($E28="PBA",1-'Parametros'!J$7,1)) | O28: =SUMPRODUCT($AK28:$AR28,$AK$14:$AR$14)*IF($E28="CABA",'Parametros'!K$7,IF($E28="PBA",1-'Parametros'!K$7,1)) | AM28: 0.224
A29: Fleje e=1,6 × 300 | B29: m | C29: Materia prima | D29: Pacheco Chapas | E29: Todos | F29: =SUMPRODUCT($AK29:$AR29,$AK$5:$AR$5)*IF($E29="CABA",'Parametros'!B$7,IF($E29="PBA",1-'Parametros'!B$7,1)) | G29: =SUMPRODUCT($AK29:$AR29,$AK$6:$AR$6)*IF($E29="CABA",'Parametros'!C$7,IF($E29="PBA",1-'Parametros'!C$7,1)) | H29: =SUMPRODUCT($AK29:$AR29,$AK$7:$AR$7)*IF($E29="CABA",'Parametros'!D$7,IF($E29="PBA",1-'Parametros'!D$7,1)) | I29: =SUMPRODUCT($AK29:$AR29,$AK$8:$AR$8)*IF($E29="CABA",'Parametros'!E$7,IF($E29="PBA",1-'Parametros'!E$7,1)) | J29: =SUMPRODUCT($AK29:$AR29,$AK$9:$AR$9)*IF($E29="CABA",'Parametros'!F$7,IF($E29="PBA",1-'Parametros'!F$7,1)) | K29: =SUMPRODUCT($AK29:$AR29,$AK$10:$AR$10)*IF($E29="CABA",'Parametros'!G$7,IF($E29="PBA",1-'Parametros'!G$7,1)) | L29: =SUMPRODUCT($AK29:$AR29,$AK$11:$AR$11)*IF($E29="CABA",'Parametros'!H$7,IF($E29="PBA",1-'Parametros'!H$7,1)) | M29: =SUMPRODUCT($AK29:$AR29,$AK$12:$AR$12)*IF($E29="CABA",'Parametros'!I$7,IF($E29="PBA",1-'Parametros'!I$7,1)) | N29: =SUMPRODUCT($AK29:$AR29,$AK$13:$AR$13)*IF($E29="CABA",'Parametros'!J$7,IF($E29="PBA",1-'Parametros'!J$7,1)) | O29: =SUMPRODUCT($AK29:$AR29,$AK$14:$AR$14)*IF($E29="CABA",'Parametros'!K$7,IF($E29="PBA",1-'Parametros'!K$7,1)) | AN29: 0.261
A30: Fleje e=2 × 249 | B30: m | C30: Materia prima | D30: Pacheco Chapas | E30: Todos | F30: =SUMPRODUCT($AK30:$AR30,$AK$5:$AR$5)*IF($E30="CABA",'Parametros'!B$7,IF($E30="PBA",1-'Parametros'!B$7,1)) | G30: =SUMPRODUCT($AK30:$AR30,$AK$6:$AR$6)*IF($E30="CABA",'Parametros'!C$7,IF($E30="PBA",1-'Parametros'!C$7,1)) | H30: =SUMPRODUCT($AK30:$AR30,$AK$7:$AR$7)*IF($E30="CABA",'Parametros'!D$7,IF($E30="PBA",1-'Parametros'!D$7,1)) | I30: =SUMPRODUCT($AK30:$AR30,$AK$8:$AR$8)*IF($E30="CABA",'Parametros'!E$7,IF($E30="PBA",1-'Parametros'!E$7,1)) | J30: =SUMPRODUCT($AK30:$AR30,$AK$9:$AR$9)*IF($E30="CABA",'Parametros'!F$7,IF($E30="PBA",1-'Parametros'!F$7,1)) | K30: =SUMPRODUCT($AK30:$AR30,$AK$10:$AR$10)*IF($E30="CABA",'Parametros'!G$7,IF($E30="PBA",1-'Parametros'!G$7,1)) | L30: =SUMPRODUCT($AK30:$AR30,$AK$11:$AR$11)*IF($E30="CABA",'Parametros'!H$7,IF($E30="PBA",1-'Parametros'!H$7,1)) | M30: =SUMPRODUCT($AK30:$AR30,$AK$12:$AR$12)*IF($E30="CABA",'Parametros'!I$7,IF($E30="PBA",1-'Parametros'!I$7,1)) | N30: =SUMPRODUCT($AK30:$AR30,$AK$13:$AR$13)*IF($E30="CABA",'Parametros'!J$7,IF($E30="PBA",1-'Parametros'!J$7,1)) | O30: =SUMPRODUCT($AK30:$AR30,$AK$14:$AR$14)*IF($E30="CABA",'Parametros'!K$7,IF($E30="PBA",1-'Parametros'!K$7,1)) | AN30: 0.208
A31: Redondo SAE 1045 Ø25 | B31: barra 6 m | C31: Materia prima | D31: Hierros Parrotta | E31: Todos | F31: =SUMPRODUCT($AK31:$AR31,$AK$5:$AR$5)*IF($E31="CABA",'Parametros'!B$7,IF($E31="PBA",1-'Parametros'!B$7,1)) | G31: =SUMPRODUCT($AK31:$AR31,$AK$6:$AR$6)*IF($E31="CABA",'Parametros'!C$7,IF($E31="PBA",1-'Parametros'!C$7,1)) | H31: =SUMPRODUCT($AK31:$AR31,$AK$7:$AR$7)*IF($E31="CABA",'Parametros'!D$7,IF($E31="PBA",1-'Parametros'!D$7,1)) | I31: =SUMPRODUCT($AK31:$AR31,$AK$8:$AR$8)*IF($E31="CABA",'Parametros'!E$7,IF($E31="PBA",1-'Parametros'!E$7,1)) | J31: =SUMPRODUCT($AK31:$AR31,$AK$9:$AR$9)*IF($E31="CABA",'Parametros'!F$7,IF($E31="PBA",1-'Parametros'!F$7,1)) | K31: =SUMPRODUCT($AK31:$AR31,$AK$10:$AR$10)*IF($E31="CABA",'Parametros'!G$7,IF($E31="PBA",1-'Parametros'!G$7,1)) | L31: =SUMPRODUCT($AK31:$AR31,$AK$11:$AR$11)*IF($E31="CABA",'Parametros'!H$7,IF($E31="PBA",1-'Parametros'!H$7,1)) | M31: =SUMPRODUCT($AK31:$AR31,$AK$12:$AR$12)*IF($E31="CABA",'Parametros'!I$7,IF($E31="PBA",1-'Parametros'!I$7,1)) | N31: =SUMPRODUCT($AK31:$AR31,$AK$13:$AR$13)*IF($E31="CABA",'Parametros'!J$7,IF($E31="PBA",1-'Parametros'!J$7,1)) | O31: =SUMPRODUCT($AK31:$AR31,$AK$14:$AR$14)*IF($E31="CABA",'Parametros'!K$7,IF($E31="PBA",1-'Parametros'!K$7,1)) | AO31: 0.0758 | AP31: 0.0777 | AQ31: 0.0958 | AR31: 0.105
A32: Cuello roscado — Ø29 × 12,5 de alto, rosca M22x1,5, asiento Ø26 | B32: u | C32: Semielaborado comprado | D32: Eli-Met | E32: Todos | F32: =SUMPRODUCT($AK32:$AR32,$AK$5:$AR$5)*IF($E32="CABA",'Parametros'!B$7,IF($E32="PBA",1-'Parametros'!B$7,1)) | G32: =SUMPRODUCT($AK32:$AR32,$AK$6:$AR$6)*IF($E32="CABA",'Parametros'!C$7,IF($E32="PBA",1-'Parametros'!C$7,1)) | H32: =SUMPRODUCT($AK32:$AR32,$AK$7:$AR$7)*IF($E32="CABA",'Parametros'!D$7,IF($E32="PBA",1-'Parametros'!D$7,1)) | I32: =SUMPRODUCT($AK32:$AR32,$AK$8:$AR$8)*IF($E32="CABA",'Parametros'!E$7,IF($E32="PBA",1-'Parametros'!E$7,1)) | J32: =SUMPRODUCT($AK32:$AR32,$AK$9:$AR$9)*IF($E32="CABA",'Parametros'!F$7,IF($E32="PBA",1-'Parametros'!F$7,1)) | K32: =SUMPRODUCT($AK32:$AR32,$AK$10:$AR$10)*IF($E32="CABA",'Parametros'!G$7,IF($E32="PBA",1-'Parametros'!G$7,1)) | L32: =SUMPRODUCT($AK32:$AR32,$AK$11:$AR$11)*IF($E32="CABA",'Parametros'!H$7,IF($E32="PBA",1-'Parametros'!H$7,1)) | M32: =SUMPRODUCT($AK32:$AR32,$AK$12:$AR$12)*IF($E32="CABA",'Parametros'!I$7,IF($E32="PBA",1-'Parametros'!I$7,1)) | N32: =SUMPRODUCT($AK32:$AR32,$AK$13:$AR$13)*IF($E32="CABA",'Parametros'!J$7,IF($E32="PBA",1-'Parametros'!J$7,1)) | O32: =SUMPRODUCT($AK32:$AR32,$AK$14:$AR$14)*IF($E32="CABA",'Parametros'!K$7,IF($E32="PBA",1-'Parametros'!K$7,1)) | AK32: 1
A33: Cuello roscado — Ø36,8 × 14 de alto, rosca M30x1,5, asiento Ø35 | B33: u | C33: Semielaborado comprado | D33: Eli-Met | E33: Todos | F33: =SUMPRODUCT($AK33:$AR33,$AK$5:$AR$5)*IF($E33="CABA",'Parametros'!B$7,IF($E33="PBA",1-'Parametros'!B$7,1)) | G33: =SUMPRODUCT($AK33:$AR33,$AK$6:$AR$6)*IF($E33="CABA",'Parametros'!C$7,IF($E33="PBA",1-'Parametros'!C$7,1)) | H33: =SUMPRODUCT($AK33:$AR33,$AK$7:$AR$7)*IF($E33="CABA",'Parametros'!D$7,IF($E33="PBA",1-'Parametros'!D$7,1)) | I33: =SUMPRODUCT($AK33:$AR33,$AK$8:$AR$8)*IF($E33="CABA",'Parametros'!E$7,IF($E33="PBA",1-'Parametros'!E$7,1)) | J33: =SUMPRODUCT($AK33:$AR33,$AK$9:$AR$9)*IF($E33="CABA",'Parametros'!F$7,IF($E33="PBA",1-'Parametros'!F$7,1)) | K33: =SUMPRODUCT($AK33:$AR33,$AK$10:$AR$10)*IF($E33="CABA",'Parametros'!G$7,IF($E33="PBA",1-'Parametros'!G$7,1)) | L33: =SUMPRODUCT($AK33:$AR33,$AK$11:$AR$11)*IF($E33="CABA",'Parametros'!H$7,IF($E33="PBA",1-'Parametros'!H$7,1)) | M33: =SUMPRODUCT($AK33:$AR33,$AK$12:$AR$12)*IF($E33="CABA",'Parametros'!I$7,IF($E33="PBA",1-'Parametros'!I$7,1)) | N33: =SUMPRODUCT($AK33:$AR33,$AK$13:$AR$13)*IF($E33="CABA",'Parametros'!J$7,IF($E33="PBA",1-'Parametros'!J$7,1)) | O33: =SUMPRODUCT($AK33:$AR33,$AK$14:$AR$14)*IF($E33="CABA",'Parametros'!K$7,IF($E33="PBA",1-'Parametros'!K$7,1)) | AN33: 1
