Workbook

Sheet 01_Indice
A1: FLAMA S.A. - Lista de materiales (BOM) de matafuegos, cilindros, sustitutos y recargas
A3: Origen | B3: Generado por código (python generar.py --bom) a partir del mismo modelo 3D que los planos FL_MAT, FL_REC, FL_DES y FL_SUS: código, posición, denominación y material de cada pieza son los del plano; medida y peso se miden sobre el sólido.
A4: Alcance | B4: 17 matafuegos FL_MAT (8 de fabricación propia ABC y 9 revendidos), 8 cilindros sueltos FL_REC, 17 extintores sustitutos FL_SUS y los kits de recarga RK por extintor y caso.
A5: Niveles | B5: 0 producto (= plano) · 1 subconjunto · 2 pieza o insumo · 3 materia prima de la pieza fabricada (cursiva; no suma al peso porque ya está en la pieza).
A6: Subconjuntos | B6: S1 Recipiente (cilindro) · S2 Conjunto de válvula · S3 Dispositivo de descarga · S4 Carro (tren rodante soldado y ruedas) · S5 Carga: agente extintor y gas impulsor · S6 Identificación y precinto · S7 Embalaje · S8 Soporte (accesorio de montaje) · S0 Equipo terminado comprado (revendidos). En los ABC el S1 es el plano FL_REC (el mismo recipiente que se vende suelto).
A7: Entra MRP | B7: Sí = se compra (materia prima, componente, consumible, servicio, agente, gas, identificación, embalaje). No = se fabrica (se explota en su materia prima), viene dentro de un conjunto comprado o es un proceso. Revendidos: sólo S0 (y la tarjeta AGC si va a CABA). Cilindros: materia prima del recipiente, tapón, etiqueta y embalaje. Sustitutos: sólo el kit de identificación. Recargas: todo lo que se repone.
A8: Códigos | B8: ABC10-01… pieza del plano (posición 01) · ABC10-S1…S8 subconjuntos · K2 válvula HZ armada · C consumible del recipiente · V interno de válvula · A carga · I soporte · E embalaje · T cilindro suelto · MP-* materia prima · SUS-* sustituto · RK-*-A/B/C kits de recarga.
A9: Peso | B9: kg por unidad de medida. Peso total = Cant. × Peso unit. (fórmula). Subconjunto = suma de sus piezas. Componentes comprados sin ficha quedan sin peso (fila naranja).
A10: Fuente P | B10: Plano / modelo 3D (misma geometría que el plano FL_MAT / FL_REC)
A11: Fuente C | B11: Cálculo declarado con datos del plano, de la norma o de una fuente técnica (fórmula en Medida u Observaciones)
A12: Fuente N | B12: Norma IRAM o resolución (se cita el apartado; texto no transcripto por licencia)
A13: Fuente L | B13: Layout de planta FLAMA (FL_PI_04) cruzado con la cotización de chapa (Pacheco / Pradecon)
A14: Fuente Q | B14: Cotización o ficha técnica recibida del proveedor (ver 11_Validacion_MP)
... A17: Normas | B17: IRAM 3517-2:2020 y las IRAM de producto citadas; resoluciones PBA y CABA. Los PDF de las normas tienen licencia monousuario: se citan apartados, no se transcribe texto.
A19: Colores de estado
A20: Sin color | B20: Validado: especificación respaldada por plano, norma, cotización o proveedor nacional con el producto exacto (la falta de precio no cambia el color: ver 10_Proveedores)
A21: Amarillo | B21: Estimado: valor justificado con norma o fuente técnica citada, sin medición ni cotización propia (corregir con dato real)
A22: Naranja | B22: A validar: falta el dato, la cotización o la confirmación del proveedor
A23: Rojo | B23: No cumple o decisión pendiente: contradicción con la norma, con el plano o sin proveedor nacional
A25: Hojas
A26: 02_Decisiones | B26: Decisiones de diseño y abastecimiento con su fundamento
A27: 03_Resumen_Productos | B27: Una fila por matafuego: agente, carga, gas, pesos, desvío contra catálogo, ítems en MRP
A28: 04_BOM_Matafuegos | B28: BOM de los 17 matafuegos en tabla plana filtrable
A29: 05_BOM_Cilindros | B29: BOM de los 8 cilindros sueltos FL_REC
A30: 06_BOM_Sustitutos | B30: BOM unitario de los extintores sustitutos FL_SUS
A31: 07_BOM_Recargas | B31: Kits de recarga por extintor y por caso (IRAM 3517-2:2020)
A32: 08_Quimica_Agentes | B32: Química y densidades de los agentes (entrada de 09_Carga_N2)
A33: 09_Carga_N2 | B33: Volumen libre, gas impulsor y control de llenado por modelo
A34: 10_Proveedores | B34: Proveedores nacionales por ítem (principal y alternativa) y directorio
A35: 11_Validacion_MP | B35: Respaldo documental y estado de cada materia prima y componente
A36: 12_Maestro_Consolidado_MP | B36: Maestro consolidado: todo lo que lleva cada matafuego, cilindro, sustituto y kit de recarga, por unidad, más los insumos de cada proceso (base del archivo MRP_MATERIA_PRIMA)
A37: 13_Fuentes | B37: Documentos y fuentes técnicas citadas
... A40: BOM_FL_MAT_* / BOM_FL_REC_* | B40: Una hoja por plano con el BOM multinivel plegable (links en 03_Resumen_Productos y 15_Indice_Planos)

Sheet 02_Decisiones
A1: Decisiones de diseño y abastecimiento que estructuran el BOM
A2: Colores: | B2: Validado | D2: Estimado | F2: A validar | H2: No cumple o decisión pendiente
A4: N° | B4: Tema | C4: Decisión adoptada | D4: Fundamento (norma / fuente) | E4: Impacto en el BOM
A5: 1 | B5: Fabricación propia | C5: Se fabrican sólo los ABC (1 a 100 kg). BC, clase D, agua, AFFF, sales K, CO₂ y HCFC se compran terminados y se revenden. | D5: Decisión FLAMA | E5: Revendidos: BOM completo de referencia; en MRP sólo la fila S0 «Equipo terminado comprado» (más la tarjeta AGC si el destino es CABA).
A6: 2 | B6: Alcance del MRP | C6: El BOM se arma completo; la columna «Entra MRP» marca lo que se compra. Lo fabricado se explota en su materia prima; lo que viene dentro de un conjunto comprado (válvula HZ, rueda) no se pide aparte. | D6: Decisión FLAMA | E6: 12_Maestro_Consolidado_MP trae todo por producto con la marca Entra MRP. El MRP por año (MRP_MATERIA_PRIMA) va en otro archivo.
A7: 3 | B7: Polvo ABC | C7: DEMSA principal (DEM-60 / DEM-90 según modelo). Polvex / Sancibrao alternativa. | D7: IRAM 3569 (composición declarada por el fabricante del polvo); licencia IRAM 3523 Drago: potencial de referencia con DEM-60/90; Polvex: sello IRAM 3569 no confirmado | E7: Con la alternativa el potencial sale del ensayo de tipo de FLAMA (IRAM 3542 / 3543).
A8: 4 | B8: Densidad del polvo | C8: Volumen libre con densidad empacada mínima 1,10 kg/dm³; llenado controlado con aparente mínima. | D8: NOM-104-STPS-2001 (IRAM 3569 no fija densidad); criterio de aceptación: descarga ≥ 85 % (IRAM 3523 4.9.1) | E8: 09_Carga_N2 y fila A2 (N₂) en amarillo hasta el ensayo de descarga.
A9: 5 | B9: Soldadura | C9: MAG 135 con Arcal 21 / ARCAL Speed (Ar + 8 % CO₂, M20) y alambre ER70S-6. | D9: Decisión FLAMA. IRAM 3523 3.2.4.2 y 3550 3.2.2.2 nombran «atmósfera inerte»: acreditar con el certificador en el ensayo de tipo (probetas IRAM 609 y PH) | E9: Consumos C1 y C2 calculados por longitud de cordón; planos con símbolo 135.
A10: 6 | B10: Placas de refuerzo | C10: 70 y 100 kg: dos placas 200 × 100 × 4,75 curvadas a Ø380, por dentro sobre la costura longitudinal, una en cada extremo a 100 mm de la boca; salen de las orillas de 4,75. | D10: Proceso FLAMA de carros (corte, cilindrado y punteo) | E10: Pieza en S1 (planos FL_MAT, FL_REC y FL_DES 70/100).
A11: 7 | B11: Carro de rodantes | C11: Accesorios soldados al recipiente antes de la PH: dos triángulos con V (chapa 4,75) con el caño del eje 1" / 1¼" × 2,0 apoyado, manija de caño 1" × 2,0 con lengüetas aplastadas 40 × 60, dos flejes del soporte de manga y pata delantera; eje, ruedas, arandelas y pasadores al montaje final. | D11: Proceso FLAMA de carros v2 (puesto 8 y kit del 8.1, tabla de posiciones); IRAM 3550 6.1.1, 3.8.2, 3.12.3 y 4.8.2 | E11: Medidas y posiciones del proceso; kit 2,8-3,7 kg (proceso: 2,9-3,8).
A12: 8 | B12: Tapas de rodantes | C12: Casquetes de 25, 50, 70 y 100 kg embutidos por Gockel Ingeniería (Wilde, Avellaneda). | D12: IRAM 3550 3.2.1 / 4.1.3; proveedor de FLAMA | E12: Ítem comprado (semielaborado); cotizar con certificado de material.
A13: 9 | B13: Pintura | C13: Tercerizada (Prymax manuales, pintor de carros rodantes). | D13: Res. 349/07 art. 18: la cabina de pintura figura en el equipamiento del fabricante; la tercerización queda sujeta a la aceptación del Ministerio | E13: C4 servicio por unidad.
A14: 10 | B14: Granallado | C14: Manuales en Airblast G-100 (Ø80-200). | D14: Ficha del equipo | E14: 1 kg (Ø76,2) fuera de rango: fila C3 en rojo hasta definir soporte o equipo.
A15: 11 | B15: Proveedores | C15: Sólo nacionales y cercanos o razonables para Avellaneda; principal + alternativa. | D15: Decisión FLAMA | E15: Columnas Proveedor principal / Alternativa y hoja 10_Proveedores.
A16: 12 | B16: Inoxidables revendidos | C16: Agua, AFFF 10 L y sales K: recipiente inoxidable soldado (no sin costura), TIG con Ar puro. | D16: IRAM 3525 3.2.1 b) y 3.2.2 (≤ 1 longitudinal + 2 transversales, proceso automático, atmósfera inerte); IRAM 3517-2 9.4.21 (sales K en inoxidable); mercado: «recipiente inoxidable soldado, PH 100 %» | E16: Referencia (revendidos). Proceso exacto (TIG / plasma / láser) no publicado por los fabricantes.
... A18: 14 | B18: Sustitutos | C18: Extintor del stock + faja amarilla ≤ 40 mm + tarjeta DPS «sustituto habilitado» + tarjeta AGC «Es sustituto». | D18: IRAM 3517-2:2020 9.4.5; Res. 349/07 art. 32; Res. AGC 32/15 | E18: 06_BOM_Sustitutos (unitario; el tamaño del parque se dimensiona aparte).

Sheet 03_Resumen_Productos
A1: Plano | B1: Producto | C1: Familia | D1: Fabricación | E1: Norma IRAM | F1: Agente | G1: Carga | H1: UM | I1: Gas impulsor | J1: Gas (kg) | K1: Peso vacío S1-S4 (kg) | L1: Peso cargado (kg) | M1: Peso de referencia (kg) | N1: Desvío | O1: Piezas del plano | P1: Ítems BOM | Q1: Ítems que entran en MRP | R1: Recipiente suelto | S1: Hoja BOM | T1: Tara de referencia (kg) = referencia - carga - gas | U1: Desvío de tara (modelo vs referencia) | V1: Fuente del peso de referencia
A2: FL_MAT_ABC_1kg | B2: Extintor ABC 1 kg | C2: manual | D2: Propia | E2: 3523 | F2: Polvo químico seco ABC (fosfato monoamónico) | G2: 1.05 | H2: kg | I2: N₂ | J2: 0.0047 | K2: ='BOM_FL_MAT_ABC_1kg'!G3 | L2: ='BOM_FL_MAT_ABC_1kg'!G4 | M2: 1.84 | N2: =L2/M2-1 | O2: 23 | P2: 51 | Q2: 28 | R2: FL_REC_ABC_1kg | S2: ir » | T2: =M2-1.05-J2 | U2: =(L2-1.05-J2)/T2-1 | V2: Plano Fadesa «Extintor 1 kg Ø76 (válvula HZ) R1»
A3: FL_MAT_ABC_2.5kg | B3: Extintor ABC 2,5 kg | C3: manual | D3: Propia | E3: 3523 | F3: Polvo químico seco ABC (fosfato monoamónico) | G3: 2.55 | H3: kg | I3: N₂ | J3: 0.0212 | K3: ='BOM_FL_MAT_ABC_2.5kg'!G3 | L3: ='BOM_FL_MAT_ABC_2.5kg'!G4 | M3: 4.62 | N3: =L3/M3-1 | O3: 27 | P3: 57 | Q3: 34 | R3: FL_REC_ABC_2.5kg | S3: ir » | T3: =M3-2.55-J3 | U3: =(L3-2.55-J3)/T3-1 | V3: Plano Fadesa «Extintor 2,5 kg válvula HZ R1»
A4: FL_MAT_ABC_5kg | B4: Extintor ABC 5 kg | C4: manual | D4: Propia | E4: 3523 | F4: Polvo químico seco ABC (fosfato monoamónico) | G4: 5.15 | H4: kg | I4: N₂ | J4: 0.0251 | K4: ='BOM_FL_MAT_ABC_5kg'!G3 | L4: ='BOM_FL_MAT_ABC_5kg'!G4 | M4: 8.4 | N4: =L4/M4-1 | O4: 27 | P4: 57 | Q4: 34 | R4: FL_REC_ABC_5kg | S4: ir » | T4: =M4-5.15-J4 | U4: =(L4-5.15-J4)/T4-1 | V4: Plano Fadesa «Extintor 5 kg válvula HZ R1»
A5: FL_MAT_ABC_10kg | B5: Extintor ABC 10 kg | C5: manual | D5: Propia | E5: 3523 | F5: Polvo químico seco ABC (fosfato monoamónico) | G5: 10.15 | H5: kg | I5: N₂ | J5: 0.0588 | K5: ='BOM_FL_MAT_ABC_10kg'!G3 | L5: ='BOM_FL_MAT_ABC_10kg'!G4 | M5: 16.4 | N5: =L5/M5-1 | O5: 27 | P5: 57 | Q5: 34 | R5: FL_REC_ABC_10kg | S5: ir » | T5: =M5-10.15-J5 | U5: =(L5-10.15-J5)/T5-1 | V5: Plano Fadesa «Extintor 10 kg HZ R1»
A6: FL_MAT_AGUA_10l | B6: Extintor Agua 10 l | C6: inox | D6: Revendido | E6: 3525 | F6: Agua | G6: 10 | H6: L | I6: Aire comprimido | J6: 0.0427 | K6: ='BOM_FL_MAT_AGUA_10l'!G3 | L6: ='BOM_FL_MAT_AGUA_10l'!G4 | M6: 12.55 | N6: =L6/M6-1 | O6: 28 | P6: 50 | Q6: 2 | R6: - | S6: ir » | T6: =M6-10.0-J6 | U6: =(L6-10.0-J6)/T6-1 | V6: Catálogo Fadesa 3 (repite pesos entre tablas: sólo orientativo)
A7: FL_MAT_AFFF_10l | B7: Extintor AFFF 10 l | C7: inox | D7: Revendido | E7: 3527 | F7: Agua + espumígeno AFFF 3 % (DEMSA 203 MN, IRAM 3515) | G7: 10 | H7: L | I7: Aire comprimido | J7: 0.0427 | K7: ='BOM_FL_MAT_AFFF_10l'!G3 | L7: ='BOM_FL_MAT_AFFF_10l'!G4 | M7: 12.6 | N7: =L7/M7-1 | O7: 28 | P7: 51 | Q7: 2 | R7: - | S7: ir » | T7: =M7-10.0-J7 | U7: =(L7-10.0-J7)/T7-1 | V7: Catálogo Fadesa 3 (repite pesos entre tablas: sólo orientativo)
A8: FL_MAT_AFFF_50l | B8: Extintor AFFF 50 l sobre ruedas | C8: rodante | D8: Revendido | E8: 3541 | F8: Agua + espumígeno AFFF 3 % (DEMSA 203 MN, IRAM 3515) | G8: 50 | H8: L | I8: Aire comprimido | J8: 0.1265 | K8: ='BOM_FL_MAT_AFFF_50l'!G3 | L8: ='BOM_FL_MAT_AFFF_50l'!G4 | M8: 100 | N8: =L8/M8-1 | O8: 37 | P8: 55 | Q8: 2 | R8: - | S8: ir » | T8: =M8-50.0-J8 | U8: =(L8-50.0-J8)/T8-1 | V8: Catálogo Fadesa 3 (repite pesos entre tablas: sólo orientativo)
A9: FL_MAT_BC_5kg | B9: Extintor BC 5 kg | C9: manual | D9: Revendido | E9: 3523 | F9: Polvo químico seco BC (bicarbonato) | G9: 5.15 | H9: kg | I9: N₂ | J9: 0.0077 | K9: ='BOM_FL_MAT_BC_5kg'!G3 | L9: ='BOM_FL_MAT_BC_5kg'!G4 | M9: 8.5 | N9: =L9/M9-1 | O9: 27 | P9: 50 | Q9: 2 | R9: - | S9: ir » | T9: =M9-5.15-J9 | U9: =(L9-5.15-J9)/T9-1 | V9: Catálogo Fadesa 3 (repite pesos entre tablas: sólo orientativo)
A10: FL_MAT_SALESK_6l | B10: Extintor Sales K 6 l | C10: inox | D10: Revendido | E10: 3694 | F10: Acetato de potasio - DEMSA Kitchen (IRAM 3697) | G10: 6.09 | H10: L | I10: N₂ | J10: 0.0306 | K10: ='BOM_FL_MAT_SALESK_6l'!G3 | L10: ='BOM_FL_MAT_SALESK_6l'!G4 | M10: 9.5 | N10: =L10/M10-1 | O10: 28 | P10: 50 | Q10: 2 | R10: - | S10: ir » | T10: =M10-7.8-J10 | U10: =(L10-7.8-J10)/T10-1 | V10: Ficha técnica Melisam acetato 6 L
A11: FL_MAT_CO2_2kg | B11: Extintor CO₂ 2 kg | C11: co2 | D11: Revendido | E11: 3509 | F11: Dióxido de carbono (IRAM 41170) | G11: 2 | H11: kg | I11: - (autopresurizado) | K11: ='BOM_FL_MAT_CO2_2kg'!G3 | L11: ='BOM_FL_MAT_CO2_2kg'!G4 | M11: 9 | N11: =L11/M11-1 | O11: 24 | P11: 44 | Q11: 2 | R11: - | S11: ir » | T11: =M11-2.0 | U11: =(L11-2.0)/T11-1 | V11: Catálogo Fadesa 3 (repite pesos entre tablas: sólo orientativo)
A12: FL_MAT_CO2_5kg | B12: Extintor CO₂ 5 kg | C12: co2 | D12: Revendido | E12: 3509 | F12: Dióxido de carbono (IRAM 41170) | G12: 5 | H12: kg | I12: - (autopresurizado) | K12: ='BOM_FL_MAT_CO2_5kg'!G3 | L12: ='BOM_FL_MAT_CO2_5kg'!G4 | M12: 20 | N12: =L12/M12-1 | O12: 26 | P12: 46 | Q12: 2 | R12: - | S12: ir » | T12: =M12-5.0 | U12: =(L12-5.0)/T12-1 | V12: Catálogo Fadesa 3 (repite pesos entre tablas: sólo orientativo)
A13: FL_MAT_HCFC-HFC_5kg | B13: Extintor HCFC/HFC 5 kg | C13: manual | D13: Revendido | E13: 3504 | F13: HCFC 123 / HFC 236fa (agente limpio) | G13: 5 | H13: kg | I13: Argón | J13: 0.0388 | K13: ='BOM_FL_MAT_HCFC-HFC_5kg'!G3 | L13: ='BOM_FL_MAT_HCFC-HFC_5kg'!G4 | M13: 8.5 | N13: =L13/M13-1 | O13: 27 | P13: 50 | Q13: 2 | R13: - | S13: ir » | T13: =M13-5.0-J13 | U13: =(L13-5.0-J13)/T13-1 | V13: Catálogo Fadesa 3 (repite pesos entre tablas: sólo orientativo)
A14: FL_MAT_CLASED_9l | B14: Extintor Clase D 9 l | C14: manual | D14: Revendido | E14: 3523 | F14: Polvo para metales combustibles clase D | G14: 9.15 | H14: kg | I14: N₂ | J14: 0.0604 | K14: ='BOM_FL_MAT_CLASED_9l'!G3 | L14: ='BOM_FL_MAT_CLASED_9l'!G4 | M14: 16.5 | N14: =L14/M14-1 | O14: 28 | P14: 50 | Q14: 2 | R14: - | S14: ir » | T14: =M14-9.15-J14 | U14: =(L14-9.15-J14)/T14-1 | V14: Catálogo Fadesa 3 (repite pesos entre tablas: sólo orientativo)
A15: FL_MAT_ABC_25kg | B15: Extintor ABC 25 kg sobre ruedas | C15: rodante | D15: Propia | E15: 3550 | F15: Polvo químico seco ABC (fosfato monoamónico) | G15: 25 | H15: kg | I15: N₂ | J15: 0.2013 | K15: ='BOM_FL_MAT_ABC_25kg'!G3 | L15: ='BOM_FL_MAT_ABC_25kg'!G4 | M15: 53.2 | N15: =L15/M15-1 | O15: 38 | P15: 62 | Q15: 34 | R15: FL_REC_ABC_25kg | S15: ir » | T15: =M15-25.0-J15 | U15: =(L15-25.0-J15)/T15-1 | V15: Plano Fadesa «Extintor rodante 25 kg R1»
A16: FL_MAT_ABC_50kg | B16: Extintor ABC 50 kg sobre ruedas | C16: rodante | D16: Propia | E16: 3550 | F16: Polvo químico seco ABC (fosfato monoamónico) | G16: 50 | H16: kg | I16: N₂ | J16: 0.2819 | K16: ='BOM_FL_MAT_ABC_50kg'!G3 | L16: ='BOM_FL_MAT_ABC_50kg'!G4 | M16: 94 | N16: =L16/M16-1 | O16: 37 | P16: 61 | Q16: 34 | R16: FL_REC_ABC_50kg | S16: ir » | T16: =M16-50.0-J16 | U16: =(L16-50.0-J16)/T16-1 | V16: Plano Fadesa «Extintor rodante 50 kg R1»
A17: FL_MAT_ABC_70kg | B17: Extintor ABC 70 kg sobre ruedas | C17: rodante | D17: Propia | E17: 3550 | F17: Polvo químico seco ABC (fosfato monoamónico) | G17: 70 | H17: kg | I17: N₂ | J17: 0.5581 | K17: ='BOM_FL_MAT_ABC_70kg'!G3 | L17: ='BOM_FL_MAT_ABC_70kg'!G4 | M17: 140 | N17: =L17/M17-1 | O17: 38 | P17: 62 | Q17: 34 | R17: FL_REC_ABC_70kg | S17: ir » | T17: =M17-70.0-J17 | U17: =(L17-70.0-J17)/T17-1 | V17: Ficha técnica Georgia ABC 90 70 kg
A18: FL_MAT_ABC_100kg | B18: Extintor ABC 100 kg sobre ruedas | C18: rodante | D18: Propia | E18: 3550 | F18: Polvo químico seco ABC (fosfato monoamónico) | G18: 100 | H18: kg | I18: N₂ | J18: 0.5189 | K18: ='BOM_FL_MAT_ABC_100kg'!G3 | L18: ='BOM_FL_MAT_ABC_100kg'!G4 | M18: 187.6 | N18: =L18/M18-1 | O18: 38 | P18: 62 | Q18: 34 | R18: FL_REC_ABC_100kg | S18: ir » | T18: =M18-100.0-J18 | U18: =(L18-100.0-J18)/T18-1 | V18: Plano Fadesa «Extintor rodante 100 kg R1»

Sheet 04_BOM_Matafuegos
A1: BOM de matafuegos terminados FL_MAT (tabla plana filtrable)
A2: Colores: | B2: Validado | D2: Estimado | F2: A validar | H2: No cumple o decisión pendiente
A4: Producto | B4: Nivel | C4: Código | D4: Descripción | E4: Cant. | F4: UM | G4: Peso unit. (kg/UM) | H4: Peso total (kg) | I4: Material | J4: Medida (mm) | K4: Origen | L4: Entra MRP | M4: Proveedor principal | N4: Alternativa | O4: Operación / puesto (layout FLAMA) | P4: Norma / referencia | Q4: Fte. | R4: Plano | S4: Observaciones
A5: FL_MAT_ABC_1kg | B5: 0 | C5: FL_MAT_ABC_1kg | D5: Extintor ABC 1 kg | E5: 1 | F5: u | P5: IRAM 3523 | Q5: P | R5: FL_MAT_ABC_1kg | S5: Fabricación propia
A6: FL_MAT_ABC_1kg | B6: 1 | C6: FL_REC_ABC_1kg | D6: Recipiente (cilindro) | E6: 1 | F6: u | H6: =H7+H9+H11+H13+H14 | K6: Fabricación | P6: IRAM 3523 / 3550 (recipiente) | Q6: P | R6: FL_REC_ABC_1kg
A7: FL_MAT_ABC_1kg | B7: 2 | C7: ABC1-01 | D7: Cuerpo (virola) | E7: 1 | F7: u | G7: 0.6072 | H7: =E7*G7 | I7: Caño c-c LF Ø76,2 e=1,25 (SAE 1010) | J7: Ø76,2 × e1,25 × 263,4 de alto; desarrollo 235,5 × 263,4 | K7: Fabricación | L7: No | O7: 5 Corte láser de caño (M15/M16) -> 9 encastre -> 10 bordoneado (los dos extremos) | Q7: P | R7: FL_DES_ABC_1kg | S7: costura long. MAG
A8: FL_MAT_ABC_1kg | B8: 3 | C8: MP-CANO | D8: Caño Ø76,2 × 1,25 (tramo de barra de 6 m) | E8: 0.0435 | F8: barra | G8: 14.288 | H8: =E8*G8 | I8: Caño acero SAE 1010 con costura | J8: 255 mm por cuerpo; 23 cuerpos por barra (kg por barra) | K8: Compra | L8: Sí | M8: Metalpri / Prilux | N8: Comercial MID | O8: AL-1T cantiléver | Q8: L | R8: FL_PI_04 h2
A9: FL_MAT_ABC_1kg | B9: 2 | C9: ABC1-02 | D9: Cúpula | E9: 1 | F9: u | G9: 0.0335 | H9: =E9*G9 | I9: Chapa LAF IRAM-IAS U 500-05 e=0,9 | J9: Ø76,2 × e0,9 × 12,1 de alto; disco Ø108 | K9: Fabricación | L9: No | O9: 6 Desbobinado + embutido (M06-M08) -> numerado de cúpula (micropercusión, en arco junto al cuello) -> 8 soldadura de cuello | Q9: P | R9: FL_DES_ABC_1kg | S9: embutida
A10: FL_MAT_ABC_1kg | B10: 3 | C10: MP-FLEJE | D10: Fleje e=0,9 × 114 (paso 111) | E10: 0.111 | F10: m | G10: 0.805 | H10: =E10*G10 | I10: Fleje SAE 1010 | J10: disco Ø108 (kg por m de fleje) | K10: Compra | L10: Sí | M10: Pacheco Chapas | N10: Pradecon S.A. | O10: AL-1F porta-flejes | Q10: L | R10: FL_PI_04 h2
A11: FL_MAT_ABC_1kg | B11: 2 | C11: ABC1-03 | D11: Fondo | E11: 1 | F11: u | G11: 0.0662 | H11: =E11*G11 | I11: Chapa LAF IRAM-IAS U 500-05 e=1,25 | J11: Ø76,2 × e1,25 × 22 de alto; disco Ø100 | K11: Fabricación | L11: No | O11: 6 Desbobinado + embutido (M06-M08) | Q11: P | R11: FL_DES_ABC_1kg | S11: embutido
A12: FL_MAT_ABC_1kg | B12: 3 | C12: MP-FLEJE | D12: Fleje e=1,25 × 106 (paso 103) | E12: 0.103 | F12: m | G12: 1.04 | H12: =E12*G12 | I12: Fleje SAE 1010 | J12: disco Ø100 (kg por m de fleje) | K12: Compra | L12: Sí | M12: Pacheco Chapas | N12: Pradecon S.A. | O12: AL-1F porta-flejes | Q12: L | R12: FL_PI_04 h2
A13: FL_MAT_ABC_1kg | B13: 2 | C13: ABC1-04 | D13: Cuello roscado | E13: 1 | F13: u | G13: 0.0358 | H13: =E13*G13 | I13: Acero SAE 1010 | J13: Ø29 × 12,5 de alto, rosca M22x1,5, asiento Ø26 | K13: Compra (mecanizado, Eli-Met) | L13: Sí | M13: Eli-Met | N13: - | O13: Compra -> 8 soldadura de cuello | Q13: P | R13: FL_DES_ABC_1kg | S13: M22x1,5
A14: FL_MAT_ABC_1kg | B14: 2 | C14: ABC1-C1 | D14: Alambre MAG ER70S-6 Ø0,9 (AWS A5.18) | E14: 0.0146 | F14: kg | G14: 0.95 | H14: =E14*G14 | I14: ER70S-6 | J14: metal depositado de los cordones del plano 14 g / rendimiento 0,95 | K14: Compra | L14: Sí | M14: Conarco (ESAB Argentina) | N14: - | O14: 4 sold. long. / 8 cuello / 11 circunferencial | P14: IRAM 3523 3.2.4.2 · IRAM 3550 4.1.2 | Q14: C | S14: Peso unit. = fracción que queda en la pieza (el resto es salpicadura). Depositado = volumen de los cordones del modelo × 7,85. Rendimiento de deposición del alambre macizo MAG 90-97 % (ESAB): se adopta 0,95. Medir en la prueba de soldadura del equipo (Getweld)
A15: FL_MAT_ABC_1kg | B15: 2 | C15: ABC1-C2 | D15: Gas de protección MAG Arcal 21 / ARCAL Speed (Ar + 8 % CO₂, M20) | E15: 13.3 | F15: L | I15: EN ISO 14175 M20-ArC-8 | J15: 14 L/min × 0,95 min de arco (cordones 570 mm: long. 0 + circ. 479 + cuello 91, a 600 mm/min) | K15: Compra | L15: Sí | M15: Air Liquide Argentina - sucursal Piñeyro | N15: Gogniat | O15: Colector SC | P15: IRAM 3523 3.2.4.2 · IRAM 3550 3.2.2.2 | Q15: C | S15: Caudal 12-16 L/min para alambre 0,9-1,2 (Air Liquide; Ingemecánica): se adopta 14. Velocidad: Getweld 0-1500 mm/min; se adopta 600. Decisión FLAMA: MAG 135 con Arcal 21; la norma nombra «atmósfera inerte»: acreditar con el certificador en el ensayo de tipo. No incluye la soldadura del carro
A16: FL_MAT_ABC_1kg | B16: 2 | C16: ABC1-C3 | D16: Granalla de acero S330 / S390 (ISO 11124-3, SAE J444) | E16: 0.08 | F16: kg | I16: Granalla esférica alto C | J16: 0,073 m² a Sa 2½ (ISO 8501-1); 3,4 kg/h ÷ 42,5 u/h | K16: Compra | L16: Sí | M16: CyM Materiales | N16: Roca Ingeniería | O16: 14 Granallado (B08) | P16: DOC-01 | Q16: C | S16: Consumo (desgaste) por turbina ≈ HP / 2 lb/h (The Fabricator, «aspectos básicos del granallado por turbina»): G-100 con 2 × 7,5 HP = 7,5 lb/h = 3,4 kg/h; ritmo 340 u por turno (Getweld) = 42,5 u/h. OJO: Ø76,2 fuera del rango de la Airblast G-100 (Ø80-200): definir soporte o equipo
A17: FL_MAT_ABC_1kg | B17: 2 | C17: ABC1-C4 | D17: Servicio de pintura en polvo al horno, rojo 03-1-050 | E17: 1 | F17: u | I17: Servicio tercerizado | J17: superficie exterior 0,073 m² | K17: Compra (servicio) | L17: Sí | M17: Prymax | N17: Pintor de carros (cotización por mensaje) | O17: 17 Pintura tercerizada | P17: IRAM 3523 5.3 / IRAM 3550 3.11 · IRAM 121 | Q17: Q | S17: Q-PRYMAX (precio por cilindro); exigir informe de niebla salina del sistema de pintura; tercerización aceptada por el Ministerio (Res. 349/07 art. 18)
A18: FL_MAT_ABC_1kg | B18: 1 | C18: ABC1-S2 | D18: Conjunto de válvula | E18: 1 | F18: u | H18: =H19+H20+H21+H23+H24+H25+H26+H27+H28+H29+H30 | K18: Compra / armado | P18: Manómetro IRAM 3533 | Q18: P | R18: FL_DES_ABC_1kg
A19: FL_MAT_ABC_1kg | B19: 2 | C19: ABC1-05 | D19: Espiga roscada | E19: 1 | F19: u | G19: 0.0117 | H19: =E19*G19 | I19: Latón forjado | J19: 21 × 21 × 8,6 | K19: Incluido en válvula HZ | L19: No | O19: 19 Ensamblaje de válvula (T03/T04) | Q19: P | R19: FL_DES_ABC_1kg
A20: FL_MAT_ABC_1kg | B20: 2 | C20: ABC1-06 | D20: Collarín de válvula | E20: 1 | F20: u | G20: 0.0025 | H20: =E20*G20 | I20: Latón forjado | J20: 19 × 19 × 3 | K20: Incluido en válvula HZ | L20: No | O20: 19 Ensamblaje de válvula (T03/T04) | Q20: P | R20: FL_DES_ABC_1kg
A21: FL_MAT_ABC_1kg | B21: 2 | C21: ABC1-07 | D21: Cuerpo de válvula | E21: 1 | F21: u | G21: 0.0935 | H21: =E21*G21 | I21: Latón forjado | J21: 32,3 × 28 × 22,9 | K21: Incluido en válvula HZ | L21: No | O21: 19 Ensamblaje de válvula (T03/T04) | Q21: P | R21: FL_DES_ABC_1kg
A22: FL_MAT_ABC_1kg | B22: 2 | C22: ABC1-08 | D22: Manómetro | E22: 1 | F22: u | I22: Comercial | J22: Ø36 esfera, rango 0-3,5 MPa, sector verde en 1,4 | K22: Compra | L22: Sí | M22: Yukon / MatafuegosYa S.R.L. | N22: Matafuegos Iglesias | O22: 19 Ensamblaje de válvula (T03/T04) | P22: IRAM 3533 | Q22: P | R22: FL_DES_ABC_1kg | S22: Pieza comercial; sello IRAM 3533; peso: completar con la ficha del proveedor (no afecta el MRP)
A23: FL_MAT_ABC_1kg | B23: 2 | C23: ABC1-09 | D23: Vástago | E23: 1 | F23: u | G23: 0.0044 | H23: =E23*G23 | I23: Latón | J23: 22,8 × 9 × 9 | K23: Incluido en válvula HZ | L23: No | O23: 19 Ensamblaje de válvula (T03/T04) | Q23: P | R23: FL_DES_ABC_1kg | S23: con junta tórica
A24: FL_MAT_ABC_1kg | B24: 2 | C24: ABC1-10 | D24: Resorte de válvula | E24: 1 | F24: u | G24: 0.0018 | H24: =E24*G24 | I24: Alambre acero inox. AISI 302 | J24: 19,9 × 9,8 × 9,8 | K24: Incluido en válvula HZ | L24: No | O24: 19 Ensamblaje de válvula (T03/T04) | Q24: P | R24: FL_DES_ABC_1kg | S24: cierre del vástago
A25: FL_MAT_ABC_1kg | B25: 2 | C25: ABC1-11 | D25: Eje de palanca | E25: 1 | F25: u | G25: 0.0023 | H25: =E25*G25 | I25: Acero inox. AISI 304 | J25: 29 × 3,6 × 3,6 | K25: Incluido en válvula HZ | L25: No | O25: 19 Ensamblaje de válvula (T03/T04) | Q25: P | R25: FL_DES_ABC_1kg
A26: FL_MAT_ABC_1kg | B26: 2 | C26: ABC1-12 | D26: Pasador de seguridad | E26: 1 | F26: u | G26: 0.0053 | H26: =E26*G26 | I26: Alambre acero inox. AISI 304 | J26: 41,9 × 21 × 20,8 | K26: Incluido en válvula HZ | L26: No | O26: 19 Ensamblaje de válvula (T03/T04) | Q26: P | R26: FL_DES_ABC_1kg | S26: con precinto
A27: FL_MAT_ABC_1kg | B27: 2 | C27: ABC1-13 | D27: Manija de accionamiento | E27: 1 | F27: u | G27: 0.025 | H27: =E27*G27 | I27: Chapa acero SAE 1010 pintada | J27: 67,1 × 27 × 11 | K27: Incluido en válvula HZ | L27: No | O27: 19 Ensamblaje de válvula (T03/T04) | Q27: P | R27: FL_DES_ABC_1kg
A28: FL_MAT_ABC_1kg | B28: 2 | C28: ABC1-14 | D28: Manija de transporte | E28: 1 | F28: u | G28: 0.0501 | H28: =E28*G28 | I28: Chapa acero SAE 1010 pintada | J28: 91,7 × 60 × 31 | K28: Incluido en válvula HZ | L28: No | O28: 19 Ensamblaje de válvula (T03/T04) | Q28: P | R28: FL_DES_ABC_1kg
A29: FL_MAT_ABC_1kg | B29: 2 | C29: ABC1-15 | D29: Caño de pesca (sifón) | E29: 1 | F29: u | G29: 0.023 | H29: =E29*G29 | I29: Tubo PVC rígido | J29: Ø14,4 × 270,1 de largo | K29: Incluido en válvula HZ | L29: No | O29: 19 Ensamblaje de válvula (T03/T04) | Q29: P | R29: FL_DES_ABC_1kg
A30: FL_MAT_ABC_1kg | B30: 2 | C30: ABC1-21 | D30: Junta tórica de asiento | E30: 1 | F30: u | G30: 0.0007 | H30: =E30*G30 | I30: NBR 70 Shore A | J30: Ø24 ext. × cordón 3 | K30: Compra | L30: Sí | M30: Argensold | N30: Matafuegos Iglesias | O30: 19 Ensamblaje de válvula (T03/T04) | Q30: P | R30: FL_DES_ABC_1kg | S30: cambio c/recarga
A31: FL_MAT_ABC_1kg | B31: 2 | C31: ABC1-K2 | D31: Válvula HZ armada M-22 1 kg c/tubo de pesca plástico | E31: 1 | F31: u | I31: Latón forjado (HZ) | J31: rosca M22x1,5 | K31: Compra | L31: Sí | M31: Polvex S.R.L. / Sancibrao | N31: Mozart S.R.L. | O31: 19 Ensamblaje de válvula | P31: IRAM 3523 3.3 | Q31: Q | R31: FL_DES_ABC_1kg | S31: Lista de precios HZ (Q-AGENTES); plano Fadesa usa válvula HZ (R-FADESA). Trae las piezas marcadas «Incluido en válvula HZ»
A32: FL_MAT_ABC_1kg | B32: 2 | C32: ABC1-V2 | D32: Resorte de retorno del vástago | E32: 1 | F32: u | I32: Acero para resortes | J32: incluido en la válvula | K32: Incluido en válvula HZ | L32: No | O32: 19 Ensamblaje | Q32: Q | S32: Lista de precios HZ: válvula «c/resorte» (Q-AGENTES)
A33: FL_MAT_ABC_1kg | B33: 2 | C33: ABC1-V3 | D33: Junta tórica del vástago | E33: 1 | F33: u | I33: NBR 70 Shore A | J33: incluida en la válvula | K33: Incluido en válvula HZ | L33: No | O33: 19 Ensamblaje | Q33: P | S33: Figura en el plano como «vástago con junta tórica»
A34: FL_MAT_ABC_1kg | B34: 1 | C34: ABC1-S3 | D34: Dispositivo de descarga | E34: 1 | F34: u | H34: =H35 | K34: Compra / armado | Q34: P | R34: FL_DES_ABC_1kg
A35: FL_MAT_ABC_1kg | B35: 2 | C35: ABC1-16 | D35: Tobera | E35: 1 | F35: u | G35: 0.0006 | H35: =E35*G35 | I35: Polipropileno | J35: 12 × 12 × 10 | K35: Compra | L35: Sí | M35: Yukon / MatafuegosYa S.R.L. | N35: Matafuegos Iglesias | O35: 19 Ensamblaje (T03/T04) | Q35: P | R35: FL_DES_ABC_1kg
A36: FL_MAT_ABC_1kg | B36: 1 | C36: ABC1-S5 | D36: Carga: agente extintor y gas impulsor | E36: 1 | F36: u | H36: =H37+H38 | K36: Carga en planta | O36: 18 Carga de polvo (T01) / C8 (T02)
A37: FL_MAT_ABC_1kg | B37: 2 | C37: ABC1-A1 | D37: Polvo químico seco ABC 60 (Sello IRAM 3569) | E37: 1.05 | F37: kg | G37: 1 | H37: =E37*G37 | I37: Polvo químico seco ABC 60 (Sello IRAM 3569) | J37: nominal 1 kg; tolerancia 0 / +100 g (IRAM 3517-2:2020 tabla 3 · IRAM 3523 tabla II) | K37: Compra | L37: Sí | M37: DEM S.A. (DEMSA) | N37: Polvex S.R.L. / Sancibrao | O37: SP-1 almacén previo a la carga | P37: IRAM 3569 | Q37: N | S37: Composición declarada del polvo ABC 60: MAP 60 % (IRAM 3569: 57-63 %) = 0,63 kg MAP + 0,389 kg sulfato de amonio + 0,032 kg aditivos · potencial de referencia 1A-5B:C (licencia Drago con DEM-60/90, L-DRAGO) · Decisión: DEMSA principal (sello IRAM 3569 y potencial de referencia); Polvex/Sancibrao alternativa sujeta a sello IRAM 3569 y ensayo de tipo de FLAMA (IRAM 3542/3543) · Lote único por extintor; prohibido mezclar ABC con BC (3517-2 9.9.1.6)
A38: FL_MAT_ABC_1kg | B38: 2 | C38: ABC1-A2 | D38: Gas impulsor: N₂ | E38: 0.0047 | F38: kg | G38: 1 | H38: =E38*G38 | I38: N₂ | J38: 3,7 L normales para 1,4 MPa a 20 °C en 0,27 dm³ libres | K38: Compra | L38: Sí | M38: Air Liquide Argentina - sucursal Piñeyro | N38: Gogniat | O38: 20 Presurización (T05) / C10 | P38: IRAM 3517-2 9.4.9 (tabla 2) · IRAM 3523 2.3 y 3.10 | Q38: C | S38: N₂ ≥ 99,8 %, H₂O ≤ 40 ppm (Q-N2, Air Liquide) · volumen libre con ρ empacada mínima 1,1 kg/dm³ (NOM-104-STPS-2001); confirmar con descarga ≥ 85 % (IRAM 3523 4.9.1)
A39: FL_MAT_ABC_1kg | B39: 1 | C39: ABC1-S6 | D39: Identificación y precinto | E39: 1 | F39: u | H39: =H40+H41+H42+H43+H44+H45 | K39: Compra | O39: 22 Etiquetado (T07)
A40: FL_MAT_ABC_1kg | B40: 2 | C40: ABC1-17 | D40: Etiqueta / placa de características | E40: 1 | F40: u | G40: 0.0097 | H40: =E40*G40 | I40: Vinilo autoadhesivo laminado | J40: 168 × 137 (desarrollo × alto: panel central 108° + 2 alas laterales), e ≈ 0,3, laminado UV | K40: Compra | L40: Sí | M40: Astuprint | N40: Multilabel Argentina S.A. | O40: 22 Etiquetado (T07) | P40: IRAM 3534 · IRAM 3523 cap. 5 · relevamiento de mercado | Q40: P | R40: FL_DES_ABC_1kg | S40: IRAM 3534
A41: FL_MAT_ABC_1kg | B41: 2 | C41: ABC1-18 | D41: Oblea de fabricación (PBA) | E41: 1 | F41: u | G41: 0.0009 | H41: =E41*G41 | I41: Papel de seguridad autodestructible | J41: Ø46 (Res. OPDS 522/07), numerada, autodestructible | K41: Compra | L41: Sí | M41: Ministerio de Ambiente PBA (ex OPDS) | N41: - | O41: 22 Etiquetado (T07) | P41: Res. OPDS 522/07 anexos 1, 2 y 6 | Q41: P | R41: FL_DES_ABC_1kg | S41: Res. 522/07
...

Sheet 05_BOM_Cilindros
A1: BOM de cilindros sueltos FL_REC
A2: Colores: | B2: Validado | D2: Estimado | F2: A validar | H2: No cumple o decisión pendiente
A4: Producto | B4: Nivel | C4: Código | D4: Descripción | E4: Cant. | F4: UM | G4: Peso unit. (kg/UM) | H4: Peso total (kg) | I4: Material | J4: Medida (mm) | K4: Origen | L4: Entra MRP | M4: Proveedor principal | N4: Alternativa | O4: Operación / puesto (layout FLAMA) | P4: Norma / referencia | Q4: Fte. | R4: Plano | S4: Observaciones
A5: FL_REC_ABC_1kg | B5: 0 | C5: FL_REC_ABC_1kg | D5: Cilindro (recipiente) ABC 1 kg - repuesto vacío sin válvula | E5: 1 | F5: u | P5: IRAM 3523 | Q5: P | R5: FL_REC_ABC_1kg | S5: Fabricación propia
A6: FL_REC_ABC_1kg | B6: 1 | C6: ABC1-S1 | D6: Recipiente (cilindro) | E6: 1 | F6: u | H6: =H7+H9+H11+H13+H14+H21 | K6: Fabricación | P6: IRAM 3523 / 3550 (recipiente) | Q6: P | R6: FL_DES_ABC_1kg
A7: FL_REC_ABC_1kg | B7: 2 | C7: ABC1-01 | D7: Cuerpo (virola) | E7: 1 | F7: u | G7: 0.6072 | H7: =E7*G7 | I7: Caño c-c LF Ø76,2 e=1,25 (SAE 1010) | J7: Ø76,2 × e1,25 × 263,4 de alto; desarrollo 235,5 × 263,4 | K7: Fabricación | L7: No | O7: 5 Corte láser de caño (M15/M16) -> 9 encastre -> 10 bordoneado (los dos extremos) | Q7: P | R7: FL_DES_ABC_1kg | S7: costura long. MAG
A8: FL_REC_ABC_1kg | B8: 3 | C8: MP-CANO | D8: Caño Ø76,2 × 1,25 (tramo de barra de 6 m) | E8: 0.0435 | F8: barra | G8: 14.288 | H8: =E8*G8 | I8: Caño acero SAE 1010 con costura | J8: 255 mm por cuerpo; 23 cuerpos por barra (kg por barra) | K8: Compra | L8: Sí | M8: Metalpri / Prilux | N8: Comercial MID | O8: AL-1T cantiléver | Q8: L | R8: FL_PI_04 h2
A9: FL_REC_ABC_1kg | B9: 2 | C9: ABC1-02 | D9: Cúpula | E9: 1 | F9: u | G9: 0.0335 | H9: =E9*G9 | I9: Chapa LAF IRAM-IAS U 500-05 e=0,9 | J9: Ø76,2 × e0,9 × 12,1 de alto; disco Ø108 | K9: Fabricación | L9: No | O9: 6 Desbobinado + embutido (M06-M08) -> numerado de cúpula (micropercusión, en arco junto al cuello) -> 8 soldadura de cuello | Q9: P | R9: FL_DES_ABC_1kg | S9: embutida
A10: FL_REC_ABC_1kg | B10: 3 | C10: MP-FLEJE | D10: Fleje e=0,9 × 114 (paso 111) | E10: 0.111 | F10: m | G10: 0.805 | H10: =E10*G10 | I10: Fleje SAE 1010 | J10: disco Ø108 (kg por m de fleje) | K10: Compra | L10: Sí | M10: Pacheco Chapas | N10: Pradecon S.A. | O10: AL-1F porta-flejes | Q10: L | R10: FL_PI_04 h2
A11: FL_REC_ABC_1kg | B11: 2 | C11: ABC1-03 | D11: Fondo | E11: 1 | F11: u | G11: 0.0662 | H11: =E11*G11 | I11: Chapa LAF IRAM-IAS U 500-05 e=1,25 | J11: Ø76,2 × e1,25 × 22 de alto; disco Ø100 | K11: Fabricación | L11: No | O11: 6 Desbobinado + embutido (M06-M08) | Q11: P | R11: FL_DES_ABC_1kg | S11: embutido
A12: FL_REC_ABC_1kg | B12: 3 | C12: MP-FLEJE | D12: Fleje e=1,25 × 106 (paso 103) | E12: 0.103 | F12: m | G12: 1.04 | H12: =E12*G12 | I12: Fleje SAE 1010 | J12: disco Ø100 (kg por m de fleje) | K12: Compra | L12: Sí | M12: Pacheco Chapas | N12: Pradecon S.A. | O12: AL-1F porta-flejes | Q12: L | R12: FL_PI_04 h2
A13: FL_REC_ABC_1kg | B13: 2 | C13: ABC1-04 | D13: Cuello roscado | E13: 1 | F13: u | G13: 0.0358 | H13: =E13*G13 | I13: Acero SAE 1010 | J13: Ø29 × 12,5 de alto, rosca M22x1,5, asiento Ø26 | K13: Compra (mecanizado, Eli-Met) | L13: Sí | M13: Eli-Met | N13: - | O13: Compra -> 8 soldadura de cuello | Q13: P | R13: FL_DES_ABC_1kg | S13: M22x1,5
A14: FL_REC_ABC_1kg | B14: 2 | C14: ABC1-C1 | D14: Alambre MAG ER70S-6 Ø0,9 (AWS A5.18) | E14: 0.0146 | F14: kg | G14: 0.95 | H14: =E14*G14 | I14: ER70S-6 | J14: metal depositado de los cordones del plano 14 g / rendimiento 0,95 | K14: Compra | L14: Sí | M14: Conarco (ESAB Argentina) | N14: - | O14: 4 sold. long. / 8 cuello / 11 circunferencial | P14: IRAM 3523 3.2.4.2 · IRAM 3550 4.1.2 | Q14: C | S14: Peso unit. = fracción que queda en la pieza (el resto es salpicadura). Depositado = volumen de los cordones del modelo × 7,85. Rendimiento de deposición del alambre macizo MAG 90-97 % (ESAB): se adopta 0,95. Medir en la prueba de soldadura del equipo (Getweld)
A15: FL_REC_ABC_1kg | B15: 2 | C15: ABC1-C2 | D15: Gas de protección MAG Arcal 21 / ARCAL Speed (Ar + 8 % CO₂, M20) | E15: 13.3 | F15: L | I15: EN ISO 14175 M20-ArC-8 | J15: 14 L/min × 0,95 min de arco (cordones 570 mm: long. 0 + circ. 479 + cuello 91, a 600 mm/min) | K15: Compra | L15: Sí | M15: Air Liquide Argentina - sucursal Piñeyro | N15: Gogniat | O15: Colector SC | P15: IRAM 3523 3.2.4.2 · IRAM 3550 3.2.2.2 | Q15: C | S15: Caudal 12-16 L/min para alambre 0,9-1,2 (Air Liquide; Ingemecánica): se adopta 14. Velocidad: Getweld 0-1500 mm/min; se adopta 600. Decisión FLAMA: MAG 135 con Arcal 21; la norma nombra «atmósfera inerte»: acreditar con el certificador en el ensayo de tipo. No incluye la soldadura del carro
A16: FL_REC_ABC_1kg | B16: 2 | C16: ABC1-C3 | D16: Granalla de acero S330 / S390 (ISO 11124-3, SAE J444) | E16: 0.08 | F16: kg | I16: Granalla esférica alto C | J16: 0,073 m² a Sa 2½ (ISO 8501-1); 3,4 kg/h ÷ 42,5 u/h | K16: Compra | L16: Sí | M16: CyM Materiales | N16: Roca Ingeniería | O16: 14 Granallado (B08) | P16: DOC-01 | Q16: C | S16: Consumo (desgaste) por turbina ≈ HP / 2 lb/h (The Fabricator, «aspectos básicos del granallado por turbina»): G-100 con 2 × 7,5 HP = 7,5 lb/h = 3,4 kg/h; ritmo 340 u por turno (Getweld) = 42,5 u/h. OJO: Ø76,2 fuera del rango de la Airblast G-100 (Ø80-200): definir soporte o equipo
A17: FL_REC_ABC_1kg | B17: 2 | C17: ABC1-C4 | D17: Servicio de pintura en polvo al horno, rojo 03-1-050 | E17: 1 | F17: u | I17: Servicio tercerizado | J17: superficie exterior 0,073 m² | K17: Compra (servicio) | L17: Sí | M17: Prymax | N17: Pintor de carros (cotización por mensaje) | O17: 17 Pintura tercerizada | P17: IRAM 3523 5.3 / IRAM 3550 3.11 · IRAM 121 | Q17: Q | S17: Q-PRYMAX (precio por cilindro); exigir informe de niebla salina del sistema de pintura; tercerización aceptada por el Ministerio (Res. 349/07 art. 18)
A18: FL_REC_ABC_1kg | B18: 2 | C18: ABC1-T1 | D18: Tapón protector de rosca del cuello | E18: 1 | F18: u | I18: Polietileno | J18: para rosca M22x1,5 (plano FL_REC_ABC_1kg hoja 3, R4) | K18: Compra | L18: Sí | M18: - | N18: - | O18: Embalaje | Q18: P
A19: FL_REC_ABC_1kg | B19: 2 | C19: ABC1-T2 | D19: Marcado del recipiente: estampado en la cúpula, en arco junto al cuello (puesto de numerado de cúpula) | E19: 1 | F19: u | I19: - | J19: Fabricante, n° de serie, año; en arco junto al cuello, letra 5 mm; cuño DPS 15 × 7 junto al n° | K19: Proceso | L19: No | O19: Marcado | P19: IRAM 3523 5.1 · Res. 349/07 anexo IV | Q19: N
A20: FL_REC_ABC_1kg | B20: 2 | C20: ABC1-T3 | D20: Etiqueta de identificación del cilindro suelto | E20: 1 | F20: u | I20: Poliéster autoadhesivo removible | J20: 100 × 60, impresión térmica, QR GS1 | K20: Compra | L20: Sí | M20: Astuprint | N20: GS1 Argentina | O20: Etiquetado | Q20: P | R20: FL_REC_ABC_1kg hoja 3
A21: FL_REC_ABC_1kg | B21: 2 | C21: ABC1-T4 | D21: Protocolo de ensayo hidrostático (certificado que acompaña) | E21: 1 | F21: u | G21: 0.005 | H21: =E21*G21 | I21: Papel | J21: A5 | K21: Proceso | L21: No | O21: Control de calidad | P21: IRAM 3523 4.1 y cap. 6 · IRAM 2587 | Q21: N | R21: FL_REC_ABC_1kg hoja 3
A22: FL_REC_ABC_1kg | B22: 1 | C22: ABC1-S7 | D22: Embalaje | E22: 1 | F22: u | H22: =H25 | K22: Compra | O22: 23 Embalaje -> 24 envolvedora (T11)
A23: FL_REC_ABC_1kg | B23: 2 | C23: ABC1-E1 | D23: Caja de cartón corrugado simple | E23: 1 | F23: u | I23: Cartón corrugado | J23: 106 × 106 × 318 interior (envolvente del plano + 15 por lado) | K23: Compra | L23: Sí | M23: Maxipack | N23: Cartocan | O23: 23 Embalaje | Q23: P | S23: Medida del plano
A24: FL_REC_ABC_1kg | B24: 2 | C24: ABC1-E3 | D24: Pallet 1200 × 1000 (fracción) | E24: 0.0025 | F24: u | I24: Madera | J24: 396 u por pallet | K24: Compra | L24: Sí | M24: IndusPallets | N24: - | O24: 23 Embalaje | Q24: C | S24: u por pallet = acomodo de la caja (plano) en 1200 × 1000 × 1450 de alto
A25: FL_REC_ABC_1kg | B25: 2 | C25: ABC1-E4 | D25: Film stretch (fracción del pallet) | E25: 0.0003 | F25: kg | G25: 1 | H25: =E25*G25 | I25: PE lineal 23 µm | J25: 0,12 kg por pallet / 396 u | K25: Compra | L25: Sí | M25: MV Embalajes | N25: Embalpack | O25: 24 Envolvedora (T11) | Q25: C | S25: Perímetro del pallet 4,4 m × 9 vueltas = 40 m aplicados; con pre-estirado 250 % (1 m de bobina = 3,5 m aplicados) = 11,4 m de bobina × 0,5 m × 23 µm × 0,92 g/cm³ = 0,12 kg. Fuentes: fichas de film 23 µm × 500 mm (MV Embalajes / Embalpack) y pre-estirado de la envolvedora. Medir en la puesta en marcha
A26: FL_REC_ABC_1kg | B26: 2 | C26: ABC1-E5 | D26: Etiqueta de pallet (lote y destino, fracción) | E26: 0.0025 | F26: u | I26: Papel térmico | J26: 100 × 150 | K26: Compra | L26: Sí | M26: Astuprint | N26: Multilabel Argentina S.A. | O26: 24 Envolvedora | Q26: C
A27: FL_REC_ABC_1kg | B27: 2 | C27: ABC1-E6 | D27: Cinta de embalaje PP 48 mm (cierre de la caja) | E27: 0.492 | F27: m | I27: Polipropileno con adhesivo acrílico | J27: cierre en I arriba y abajo: 2 × (106 + 2 × 70 de solapa) | K27: Compra | L27: Sí | M27: MV Embalajes | N27: Embalpack | O27: 23 Embalaje | Q27: C | S27: Solapa de 70 mm por lado: práctica de cierre de cajas (medir en la línea)
A28: FL_REC_ABC_1kg | B28: 2 | C28: ABC1-E7 | D28: Esquineros de cartón 50 × 50 × 1200 (fracción del pallet) | E28: 0.0101 | F28: u | I28: Cartón | J28: 4 por pallet / 396 u | K28: Compra | L28: Sí | M28: Maxipack | N28: Cartocan | O28: 24 Envolvedora (T11) | Q28: C | S28: Planilla MP-64
A29: FL_REC_ABC_1kg | B29: 2 | C29: ABC1-E8 | D29: Separador de capa de cartón 1200 × 1000 (fracción del pallet) | E29: 0.0076 | F29: u | I29: Cartón | J29: 4 capas → 3 separadores por pallet / 396 u | K29: Compra | L29: Sí | M29: Maxipack | N29: Cartocan | O29: 23 Embalaje | Q29: C | S29: Planilla MP-61
A30: FL_REC_ABC_2.5kg | B30: 0 | C30: FL_REC_ABC_2.5kg | D30: Cilindro (recipiente) ABC 2,5 kg - repuesto vacío sin válvula | E30: 1 | F30: u | P30: IRAM 3523 | Q30: P | R30: FL_REC_ABC_2.5kg | S30: Fabricación propia
A31: FL_REC_ABC_2.5kg | B31: 1 | C31: ABC2.5-S1 | D31: Recipiente (cilindro) | E31: 1 | F31: u | H31: =H32+H34+H36+H38+H39+H46 | K31: Fabricación | P31: IRAM 3523 / 3550 (recipiente) | Q31: P | R31: FL_DES_ABC_2.5kg
A32: FL_REC_ABC_2.5kg | B32: 2 | C32: ABC2.5-01 | D32: Cuerpo (virola) | E32: 1 | F32: u | G32: 1.011 | H32: =E32*G32 | I32: Chapa LAF IRAM-IAS U 500-05 e=1,25 | J32: Ø124 × e1,25 × 267,4 de alto; desarrollo 385,6 × 267,4 | K32: Fabricación | L32: No | O32: 1 Guillotina -> 3 cilindrado -> 4 soldadura longitudinal -> 9 encastre del fondo -> 10 bordoneado | Q32: P | R32: FL_DES_ABC_2.5kg | S32: costura long. MAG
A33: FL_REC_ABC_2.5kg | B33: 3 | C33: MP-HOJA | D33: Recorte de hoja LAF 1220 × 2440 e=1,25 | E33: 1 | F33: u | G33: 1.082 | H33: =E33*G33 | I33: Chapa LAF IRAM-IAS U 500-05 LAF | J33: 385,5 × 269,5 (aprovech. 94,2 %) | K33: Compra | L33: Sí | M33: Pradecon S.A. | N33: Pacheco Chapas | O33: AL-1H paquetes de hojas | Q33: L | R33: FL_PI_04 h2
A34: FL_REC_ABC_2.5kg | B34: 2 | C34: ABC2.5-02 | D34: Cúpula | E34: 1 | F34: u | G34: 0.1734 | H34: =E34*G34 | I34: Chapa LAF IRAM-IAS U 500-05 e=1,25 | J34: Ø124 × e1,25 × 38,1 de alto; disco Ø179 | K34: Fabricación | L34: No | O34: 6 Desbobinado + embutido (M06-M08) -> numerado de cúpula (micropercusión, en arco junto al cuello) -> 8 soldadura de cuello | Q34: P | R34: FL_DES_ABC_2.5kg | S34: embutida
A35: FL_REC_ABC_2.5kg | B35: 3 | C35: MP-FLEJE | D35: Fleje e=1,25 × 200 (paso 182) | E35: 0.182 | F35: m | G35: 1.962 | H35: =E35*G35 | I35: Fleje SAE 1010 | J35: disco Ø179 (kg por m de fleje) | K35: Compra | L35: Sí | M35: Pacheco Chapas | N35: Pradecon S.A. | O35: AL-1F porta-flejes | Q35: L | R35: FL_PI_04 h2
A36: FL_REC_ABC_2.5kg | B36: 2 | C36: ABC2.5-03 | D36: Fondo | E36: 1 | F36: u | G36: 0.1657 | H36: =E36*G36 | I36: Chapa LAF IRAM-IAS U 500-05 e=1,25 | J36: Ø124 × e1,25 × 20,5 de alto; disco Ø148 | K36: Fabricación | L36: No | O36: 6 Desbobinado + embutido (M06-M08) | Q36: P | R36: FL_DES_ABC_2.5kg | S36: embutido
A37: FL_REC_ABC_2.5kg | B37: 3 | C37: MP-FLEJE | D37: Fleje e=1,25 × 200 (paso 151) | E37: 0.151 | F37: m | G37: 1.962 | H37: =E37*G37 | I37: Fleje SAE 1010 | J37: disco Ø148 (kg por m de fleje) | K37: Compra | L37: Sí | M37: Pacheco Chapas | N37: Pradecon S.A. | O37: AL-1F porta-flejes | Q37: L | R37: FL_PI_04 h2
A38: FL_REC_ABC_2.5kg | B38: 2 | C38: ABC2.5-04 | D38: Cuello roscado | E38: 1 | F38: u | G38: 0.0545 | H38: =E38*G38 | I38: Acero SAE 1010 | J38: Ø37 × 14 de alto, rosca M30x1,5, asiento Ø35 | K38: Compra (mecanizado, Eli-Met) | L38: Sí | M38: Eli-Met | N38: - | O38: Compra -> 8 soldadura de cuello | Q38: P | R38: FL_DES_ABC_2.5kg | S38: M30x1,5
A39: FL_REC_ABC_2.5kg | B39: 2 | C39: ABC2.5-C1 | D39: Alambre MAG ER70S-6 Ø0,9 (AWS A5.18) | E39: 0.0292 | F39: kg | G39: 0.95 | H39: =E39*G39 | I39: ER70S-6 | J39: metal depositado de los cordones del plano 28 g / rendimiento 0,95 | K39: Compra | L39: Sí | M39: Conarco (ESAB Argentina) | N39: - | O39: 4 sold. long. / 8 cuello / 11 circunferencial | P39: IRAM 3523 3.2.4.2 · IRAM 3550 4.1.2 | Q39: C | S39: Peso unit. = fracción que queda en la pieza (el resto es salpicadura). Depositado = volumen de los cordones del modelo × 7,85. Rendimiento de deposición del alambre macizo MAG 90-97 % (ESAB): se adopta 0,95. Medir en la prueba de soldadura del equipo (Getweld)
A40: FL_REC_ABC_2.5kg | B40: 2 | C40: ABC2.5-C2 | D40: Gas de protección MAG Arcal 21 / ARCAL Speed (Ar + 8 % CO₂, M20) | E40: 27.1 | F40: L | I40: EN ISO 14175 M20-ArC-8 | J40: 14 L/min × 1,94 min de arco (cordones 1.163 mm: long. 267 + circ. 779 + cuello 116, a 600 mm/min) | K40: Compra | L40: Sí | M40: Air Liquide Argentina - sucursal Piñeyro | N40: Gogniat | O40: Colector SC | P40: IRAM 3523 3.2.4.2 · IRAM 3550 3.2.2.2 | Q40: C | S40: Caudal 12-16 L/min para alambre 0,9-1,2 (Air Liquide; Ingemecánica): se adopta 14. Velocidad: Getweld 0-1500 mm/min; se adopta 600. Decisión FLAMA: MAG 135 con Arcal 21; la norma nombra «atmósfera inerte»: acreditar con el certificador en el ensayo de tipo. No incluye la soldadura del carro
A41: FL_REC_ABC_2.5kg | B41: 2 | C41: ABC2.5-C3 | D41: Granalla de acero S330 / S390 (ISO 11124-3, SAE J444) | E41: 0.08 | F41: kg | I41: Granalla esférica alto C | J41: 0,138 m² a Sa 2½ (ISO 8501-1); 3,4 kg/h ÷ 42,5 u/h | K41: Compra | L41: Sí | M41: CyM Materiales | N41: Roca Ingeniería | O41: 14 Granallado (B08) | P41: DOC-01 | Q41: C | S41: Consumo (desgaste) por turbina ≈ HP / 2 lb/h (The Fabricator, «aspectos básicos del granallado por turbina»): G-100 con 2 × 7,5 HP = 7,5 lb/h = 3,4 kg/h; ritmo 340 u por turno (Getweld) = 42,5 u/h.
...

Sheet 06_BOM_Sustitutos
A1: BOM unitario de extintores sustitutos FL_SUS (IRAM 3517-2:2020 9.4.5)
A2: Colores: | B2: Validado | D2: Estimado | F2: A validar | H2: No cumple o decisión pendiente
A4: Producto | B4: Nivel | C4: Código | D4: Descripción | E4: Cant. | F4: UM | G4: Peso unit. (kg/UM) | H4: Peso total (kg) | I4: Material | J4: Medida (mm) | K4: Origen | L4: Entra MRP | M4: Proveedor principal | N4: Alternativa | O4: Operación / puesto (layout FLAMA) | P4: Norma / referencia | Q4: Fte. | R4: Plano | S4: Observaciones
A5: FL_SUS_ABC_1kg | B5: 0 | C5: FL_SUS_ABC_1kg | D5: Extintor sustituto para Extintor ABC 1 kg | E5: 1 | F5: u | P5: IRAM 3517-2:2020 9.4.5 | Q5: N | R5: FL_SUS_ABC_1kg | S5: Unitario: el tamaño del parque de sustitutos se dimensiona aparte
A6: FL_SUS_ABC_1kg | B6: 1 | C6: FL_MAT_ABC_1kg | D6: Extintor base: Extintor ABC 1 kg (mismo modelo) | E6: 1 | F6: u | K6: Stock FLAMA (fabricación propia) | L6: No | P6: IRAM 3517-2:2020 9.4.5 | Q6: N | R6: FL_SUS_ABC_1kg | S6: Igual clasificación y capacidad; mantenimiento vigente. BOM: hoja FL_MAT_ABC_1kg · No entra en MRP del kit: es demanda del producto FL_MAT (stock)
A7: FL_SUS_ABC_1kg | B7: 1 | C7: SUS-ABC_1kg-K | D7: Identificación de extintor sustituto | E7: 1 | F7: u | K7: Compra | Q7: N | R7: FL_SUS_ABC_1kg
A8: FL_SUS_ABC_1kg | B8: 2 | C8: SUS-ABC_1kg-01 | D8: Faja amarilla de sustituto en la pollera (3 leyendas) | E8: 1 | F8: u | I8: Cinta vinílica autoadhesiva amarilla | J8: 36 × 259 (alto ≤ 40; perímetro + 20 de solape) | K8: Compra | L8: Sí | M8: Astuprint | N8: Multilabel Argentina S.A. | P8: IRAM 3517-2:2020 9.4.5 b) | Q8: N | R8: FL_SUS_ABC_1kg | S8: Leyendas: extintor sustituto / reemplaza al equipo de este puesto en mantenimiento o recarga / FLAMA S.A. (datos y logo). Proveedor a cotizar
A9: FL_SUS_ABC_1kg | B9: 2 | C9: SUS-ABC_1kg-02 | D9: Tarjeta de identificación DPS con sello «SUSTITUTO HABILITADO» | E9: 1 | F9: u | I9: Tarjeta oficial DPS (PBA) | J9: formato oficial | K9: Compra (organismo) | L9: Sí | M9: Ministerio de Ambiente PBA (ex OPDS) | N9: - | P9: Res. 349/07 art. 32 | Q9: N | R9: FL_SUS_ABC_1kg | S9: Sólo PBA; reutilizable en cada revisión de carga; n° del extintor asentado en el libro de actas
A10: FL_SUS_ABC_1kg | B10: 2 | C10: SUS-ABC_1kg-03 | D10: Tarjeta AGC con «Es sustituto» (sin domicilio de instalación) | E10: 1 | F10: u | I10: Etiqueta autoadhesiva AGC | J10: formato oficial | K10: Compra (organismo) | L10: Sí | M10: Agencia Gubernamental de Control (CABA) | N10: - | P10: Res. AGC 32/15 anexo II | Q10: N | R10: FL_SUS_ABC_1kg | S10: Sólo CABA
A11: FL_SUS_ABC_1kg | B11: 2 | C11: SUS-ABC_1kg-04 | D11: Remito de préstamo con membrete (n° de extintor, puesto, equipo retirado, fechas) | E11: 1 | F11: u/préstamo | I11: Papel | J11: A5 duplicado | K11: Compra | L11: Sí | M11: Astuprint | N11: - | Q11: I | R11: FL_SUS_ABC_1kg | S11: Práctica de mercado relevada (Fullmat, Rodo, Eversafe)
A12: FL_SUS_ABC_2.5kg | B12: 0 | C12: FL_SUS_ABC_2.5kg | D12: Extintor sustituto para Extintor ABC 2,5 kg | E12: 1 | F12: u | P12: IRAM 3517-2:2020 9.4.5 | Q12: N | R12: FL_SUS_ABC_2.5kg | S12: Unitario: el tamaño del parque de sustitutos se dimensiona aparte
A13: FL_SUS_ABC_2.5kg | B13: 1 | C13: FL_MAT_ABC_2.5kg | D13: Extintor base: Extintor ABC 2,5 kg (mismo modelo) | E13: 1 | F13: u | K13: Stock FLAMA (fabricación propia) | L13: No | P13: IRAM 3517-2:2020 9.4.5 | Q13: N | R13: FL_SUS_ABC_2.5kg | S13: Igual clasificación y capacidad; mantenimiento vigente. BOM: hoja FL_MAT_ABC_2.5kg · No entra en MRP del kit: es demanda del producto FL_MAT (stock)
A14: FL_SUS_ABC_2.5kg | B14: 1 | C14: SUS-ABC_2.5kg-K | D14: Identificación de extintor sustituto | E14: 1 | F14: u | K14: Compra | Q14: N | R14: FL_SUS_ABC_2.5kg
A15: FL_SUS_ABC_2.5kg | B15: 2 | C15: SUS-ABC_2.5kg-01 | D15: Faja amarilla de sustituto en la pollera (3 leyendas) | E15: 1 | F15: u | I15: Cinta vinílica autoadhesiva amarilla | J15: 30 × 410 (alto ≤ 40; perímetro + 20 de solape) | K15: Compra | L15: Sí | M15: Astuprint | N15: Multilabel Argentina S.A. | P15: IRAM 3517-2:2020 9.4.5 b) | Q15: N | R15: FL_SUS_ABC_2.5kg | S15: Leyendas: extintor sustituto / reemplaza al equipo de este puesto en mantenimiento o recarga / FLAMA S.A. (datos y logo). Proveedor a cotizar
A16: FL_SUS_ABC_2.5kg | B16: 2 | C16: SUS-ABC_2.5kg-02 | D16: Tarjeta de identificación DPS con sello «SUSTITUTO HABILITADO» | E16: 1 | F16: u | I16: Tarjeta oficial DPS (PBA) | J16: formato oficial | K16: Compra (organismo) | L16: Sí | M16: Ministerio de Ambiente PBA (ex OPDS) | N16: - | P16: Res. 349/07 art. 32 | Q16: N | R16: FL_SUS_ABC_2.5kg | S16: Sólo PBA; reutilizable en cada revisión de carga; n° del extintor asentado en el libro de actas
A17: FL_SUS_ABC_2.5kg | B17: 2 | C17: SUS-ABC_2.5kg-03 | D17: Tarjeta AGC con «Es sustituto» (sin domicilio de instalación) | E17: 1 | F17: u | I17: Etiqueta autoadhesiva AGC | J17: formato oficial | K17: Compra (organismo) | L17: Sí | M17: Agencia Gubernamental de Control (CABA) | N17: - | P17: Res. AGC 32/15 anexo II | Q17: N | R17: FL_SUS_ABC_2.5kg | S17: Sólo CABA
A18: FL_SUS_ABC_2.5kg | B18: 2 | C18: SUS-ABC_2.5kg-04 | D18: Remito de préstamo con membrete (n° de extintor, puesto, equipo retirado, fechas) | E18: 1 | F18: u/préstamo | I18: Papel | J18: A5 duplicado | K18: Compra | L18: Sí | M18: Astuprint | N18: - | Q18: I | R18: FL_SUS_ABC_2.5kg | S18: Práctica de mercado relevada (Fullmat, Rodo, Eversafe)
A19: FL_SUS_ABC_5kg | B19: 0 | C19: FL_SUS_ABC_5kg | D19: Extintor sustituto para Extintor ABC 5 kg | E19: 1 | F19: u | P19: IRAM 3517-2:2020 9.4.5 | Q19: N | R19: FL_SUS_ABC_5kg | S19: Unitario: el tamaño del parque de sustitutos se dimensiona aparte
A20: FL_SUS_ABC_5kg | B20: 1 | C20: FL_MAT_ABC_5kg | D20: Extintor base: Extintor ABC 5 kg (mismo modelo) | E20: 1 | F20: u | K20: Stock FLAMA (fabricación propia) | L20: No | P20: IRAM 3517-2:2020 9.4.5 | Q20: N | R20: FL_SUS_ABC_5kg | S20: Igual clasificación y capacidad; mantenimiento vigente. BOM: hoja FL_MAT_ABC_5kg · No entra en MRP del kit: es demanda del producto FL_MAT (stock)
A21: FL_SUS_ABC_5kg | B21: 1 | C21: SUS-ABC_5kg-K | D21: Identificación de extintor sustituto | E21: 1 | F21: u | K21: Compra | Q21: N | R21: FL_SUS_ABC_5kg
A22: FL_SUS_ABC_5kg | B22: 2 | C22: SUS-ABC_5kg-01 | D22: Faja amarilla de sustituto en la pollera (3 leyendas) | E22: 1 | F22: u | I22: Cinta vinílica autoadhesiva amarilla | J22: 40 × 501 (alto ≤ 40; perímetro + 20 de solape) | K22: Compra | L22: Sí | M22: Astuprint | N22: Multilabel Argentina S.A. | P22: IRAM 3517-2:2020 9.4.5 b) | Q22: N | R22: FL_SUS_ABC_5kg | S22: Leyendas: extintor sustituto / reemplaza al equipo de este puesto en mantenimiento o recarga / FLAMA S.A. (datos y logo). Proveedor a cotizar
A23: FL_SUS_ABC_5kg | B23: 2 | C23: SUS-ABC_5kg-02 | D23: Tarjeta de identificación DPS con sello «SUSTITUTO HABILITADO» | E23: 1 | F23: u | I23: Tarjeta oficial DPS (PBA) | J23: formato oficial | K23: Compra (organismo) | L23: Sí | M23: Ministerio de Ambiente PBA (ex OPDS) | N23: - | P23: Res. 349/07 art. 32 | Q23: N | R23: FL_SUS_ABC_5kg | S23: Sólo PBA; reutilizable en cada revisión de carga; n° del extintor asentado en el libro de actas
A24: FL_SUS_ABC_5kg | B24: 2 | C24: SUS-ABC_5kg-03 | D24: Tarjeta AGC con «Es sustituto» (sin domicilio de instalación) | E24: 1 | F24: u | I24: Etiqueta autoadhesiva AGC | J24: formato oficial | K24: Compra (organismo) | L24: Sí | M24: Agencia Gubernamental de Control (CABA) | N24: - | P24: Res. AGC 32/15 anexo II | Q24: N | R24: FL_SUS_ABC_5kg | S24: Sólo CABA
A25: FL_SUS_ABC_5kg | B25: 2 | C25: SUS-ABC_5kg-04 | D25: Remito de préstamo con membrete (n° de extintor, puesto, equipo retirado, fechas) | E25: 1 | F25: u/préstamo | I25: Papel | J25: A5 duplicado | K25: Compra | L25: Sí | M25: Astuprint | N25: - | Q25: I | R25: FL_SUS_ABC_5kg | S25: Práctica de mercado relevada (Fullmat, Rodo, Eversafe)
A26: FL_SUS_ABC_10kg | B26: 0 | C26: FL_SUS_ABC_10kg | D26: Extintor sustituto para Extintor ABC 10 kg | E26: 1 | F26: u | P26: IRAM 3517-2:2020 9.4.5 | Q26: N | R26: FL_SUS_ABC_10kg | S26: Unitario: el tamaño del parque de sustitutos se dimensiona aparte
A27: FL_SUS_ABC_10kg | B27: 1 | C27: FL_MAT_ABC_10kg | D27: Extintor base: Extintor ABC 10 kg (mismo modelo) | E27: 1 | F27: u | K27: Stock FLAMA (fabricación propia) | L27: No | P27: IRAM 3517-2:2020 9.4.5 | Q27: N | R27: FL_SUS_ABC_10kg | S27: Igual clasificación y capacidad; mantenimiento vigente. BOM: hoja FL_MAT_ABC_10kg · No entra en MRP del kit: es demanda del producto FL_MAT (stock)
A28: FL_SUS_ABC_10kg | B28: 1 | C28: SUS-ABC_10kg-K | D28: Identificación de extintor sustituto | E28: 1 | F28: u | K28: Compra | Q28: N | R28: FL_SUS_ABC_10kg
A29: FL_SUS_ABC_10kg | B29: 2 | C29: SUS-ABC_10kg-01 | D29: Faja amarilla de sustituto en la pollera (3 leyendas) | E29: 1 | F29: u | I29: Cinta vinílica autoadhesiva amarilla | J29: 40 × 590 (alto ≤ 40; perímetro + 20 de solape) | K29: Compra | L29: Sí | M29: Astuprint | N29: Multilabel Argentina S.A. | P29: IRAM 3517-2:2020 9.4.5 b) | Q29: N | R29: FL_SUS_ABC_10kg | S29: Leyendas: extintor sustituto / reemplaza al equipo de este puesto en mantenimiento o recarga / FLAMA S.A. (datos y logo). Proveedor a cotizar
A30: FL_SUS_ABC_10kg | B30: 2 | C30: SUS-ABC_10kg-02 | D30: Tarjeta de identificación DPS con sello «SUSTITUTO HABILITADO» | E30: 1 | F30: u | I30: Tarjeta oficial DPS (PBA) | J30: formato oficial | K30: Compra (organismo) | L30: Sí | M30: Ministerio de Ambiente PBA (ex OPDS) | N30: - | P30: Res. 349/07 art. 32 | Q30: N | R30: FL_SUS_ABC_10kg | S30: Sólo PBA; reutilizable en cada revisión de carga; n° del extintor asentado en el libro de actas
A31: FL_SUS_ABC_10kg | B31: 2 | C31: SUS-ABC_10kg-03 | D31: Tarjeta AGC con «Es sustituto» (sin domicilio de instalación) | E31: 1 | F31: u | I31: Etiqueta autoadhesiva AGC | J31: formato oficial | K31: Compra (organismo) | L31: Sí | M31: Agencia Gubernamental de Control (CABA) | N31: - | P31: Res. AGC 32/15 anexo II | Q31: N | R31: FL_SUS_ABC_10kg | S31: Sólo CABA
A32: FL_SUS_ABC_10kg | B32: 2 | C32: SUS-ABC_10kg-04 | D32: Remito de préstamo con membrete (n° de extintor, puesto, equipo retirado, fechas) | E32: 1 | F32: u/préstamo | I32: Papel | J32: A5 duplicado | K32: Compra | L32: Sí | M32: Astuprint | N32: - | Q32: I | R32: FL_SUS_ABC_10kg | S32: Práctica de mercado relevada (Fullmat, Rodo, Eversafe)
A33: FL_SUS_AGUA_10l | B33: 0 | C33: FL_SUS_AGUA_10l | D33: Extintor sustituto para Extintor Agua 10 l | E33: 1 | F33: u | P33: IRAM 3517-2:2020 9.4.5 | Q33: N | R33: FL_SUS_AGUA_10l | S33: Unitario: el tamaño del parque de sustitutos se dimensiona aparte
A34: FL_SUS_AGUA_10l | B34: 1 | C34: FL_MAT_AGUA_10l | D34: Extintor base: Extintor Agua 10 l (mismo modelo) | E34: 1 | F34: u | K34: Stock FLAMA (comprado terminado) | L34: No | P34: IRAM 3517-2:2020 9.4.5 | Q34: N | R34: FL_SUS_AGUA_10l | S34: Igual clasificación y capacidad; mantenimiento vigente. BOM: hoja FL_MAT_AGUA_10l · No entra en MRP del kit: es demanda del producto FL_MAT (stock)
A35: FL_SUS_AGUA_10l | B35: 1 | C35: SUS-AGUA_10l-K | D35: Identificación de extintor sustituto | E35: 1 | F35: u | K35: Compra | Q35: N | R35: FL_SUS_AGUA_10l
A36: FL_SUS_AGUA_10l | B36: 2 | C36: SUS-AGUA_10l-01 | D36: Faja amarilla de sustituto en la pollera (3 leyendas) | E36: 1 | F36: u | I36: Cinta vinílica autoadhesiva amarilla | J36: 40 × 617 (alto ≤ 40; perímetro + 20 de solape) | K36: Compra | L36: Sí | M36: Astuprint | N36: Multilabel Argentina S.A. | P36: IRAM 3517-2:2020 9.4.5 b) | Q36: N | R36: FL_SUS_AGUA_10l | S36: Leyendas: extintor sustituto / reemplaza al equipo de este puesto en mantenimiento o recarga / FLAMA S.A. (datos y logo). Proveedor a cotizar
A37: FL_SUS_AGUA_10l | B37: 2 | C37: SUS-AGUA_10l-02 | D37: Tarjeta de identificación DPS con sello «SUSTITUTO HABILITADO» | E37: 1 | F37: u | I37: Tarjeta oficial DPS (PBA) | J37: formato oficial | K37: Compra (organismo) | L37: Sí | M37: Ministerio de Ambiente PBA (ex OPDS) | N37: - | P37: Res. 349/07 art. 32 | Q37: N | R37: FL_SUS_AGUA_10l | S37: Sólo PBA; reutilizable en cada revisión de carga; n° del extintor asentado en el libro de actas
A38: FL_SUS_AGUA_10l | B38: 2 | C38: SUS-AGUA_10l-03 | D38: Tarjeta AGC con «Es sustituto» (sin domicilio de instalación) | E38: 1 | F38: u | I38: Etiqueta autoadhesiva AGC | J38: formato oficial | K38: Compra (organismo) | L38: Sí | M38: Agencia Gubernamental de Control (CABA) | N38: - | P38: Res. AGC 32/15 anexo II | Q38: N | R38: FL_SUS_AGUA_10l | S38: Sólo CABA
A39: FL_SUS_AGUA_10l | B39: 2 | C39: SUS-AGUA_10l-04 | D39: Remito de préstamo con membrete (n° de extintor, puesto, equipo retirado, fechas) | E39: 1 | F39: u/préstamo | I39: Papel | J39: A5 duplicado | K39: Compra | L39: Sí | M39: Astuprint | N39: - | Q39: I | R39: FL_SUS_AGUA_10l | S39: Práctica de mercado relevada (Fullmat, Rodo, Eversafe)
A40: FL_SUS_AFFF_10l | B40: 0 | C40: FL_SUS_AFFF_10l | D40: Extintor sustituto para Extintor AFFF 10 l | E40: 1 | F40: u | P40: IRAM 3517-2:2020 9.4.5 | Q40: N | R40: FL_SUS_AFFF_10l | S40: Unitario: el tamaño del parque de sustitutos se dimensiona aparte
A41: FL_SUS_AFFF_10l | B41: 1 | C41: FL_MAT_AFFF_10l | D41: Extintor base: Extintor AFFF 10 l (mismo modelo) | E41: 1 | F41: u | K41: Stock FLAMA (comprado terminado) | L41: No | P41: IRAM 3517-2:2020 9.4.5 | Q41: N | R41: FL_SUS_AFFF_10l | S41: Igual clasificación y capacidad; mantenimiento vigente. BOM: hoja FL_MAT_AFFF_10l · No entra en MRP del kit: es demanda del producto FL_MAT (stock)
...

Sheet 07_BOM_Recargas
A1: BOM de servicio de recarga y mantenimiento por extintor y por caso (IRAM 3517-2:2020)
A2: • Polvo: un extintor ACCIONADO (aunque sea parcialmente) se recarga con polvo NUEVO; el polvo de ese extintor no se reutiliza (9.9.1.4). El polvo de un extintor que se abre SIN haber sido accionado (control interior, prueba hidráulica) puede volver al mismo equipo si se trata en el sistema cerrado de recuperación del recinto y pasa el control de 9.9.3 (4.4.1 y). Nunca se mezcla ABC con BC (9.9.1.6).
A3: • Polvo de la versión anterior de la IRAM 3569 → reemplazo total obligatorio (9.9.4); el retirado es residuo.
A4: • HCFC / gases limpios: el agente se trasvasa y RECUPERA en circuito cerrado, nunca se ventea (4.4.1 z). Se repone sólo la pérdida. El recuperado fuera de especificación va a regeneración por gestor habilitado.
A5: • CO₂: carga por trasvase (4.4.1 l); recuperación recomendada en vaciados (9.4.18).
